Workbook
Name RiskPct: 'הגדרות'!$B$4
Name MaxHeat: 'הגדרות'!$B$5
Name NearStop: 'הגדרות'!$B$6
Name PartialR: 'הגדרות'!$B$7
Name MaxPos: 'הגדרות'!$B$8
Name EntryZone: 'הגדרות'!$B$9
Name FxManual: 'הגדרות'!$B$10
Name Fx: 'הגדרות'!$B$11
Name DivYear: 'הגדרות'!$B$12
Name PerfStart: 'הגדרות'!$B$13
Name SectorList: 'הגדרות'!$A$16:$A$28
Name Cash: 'דשבורד'!$C$8
Name Equity: 'דשבורד'!$C$5

Sheet הוראות
A1: Pearl Portfolio Tracker · מערכת ניהול תיק השקעות
A2: ניהול תיק, סיכונים, דיבידנדים וביצועים — בעברית, עם מחירים חיים ב-Google Sheets
B4: איך מתחילים
B5: 1. הגדרות | C5: קבע % סיכון לעסקה, תקרת סיכון כוללת לתיק, ושער דולר. מכאן נגזרים גודל פוזיציה והתראות.
B6: 2. עסקאות | C6: כל תנועה בשורה אחת: הפקדה, קנייה, מכירה, דיבידנד, משיכה, עמלה. זה המקור היחיד לאמת — כל השאר מחושב מכאן.
B7: 3. תיק | C7: רשום כל טיקר פעם אחת (עמודה A), סקטור, סטופ התחלתי וסטופ נוכחי. כמות, עלות ממוצעת, רווח ו-R מחושבים לבד.
B8: 4. מעקב | C8: מניות שאתה שוקל: אזור כניסה, סטופ ויעדים. המערכת מחשבת כמה מניות לקנות לפי מדיניות הסיכון ומסמנת כשהמחיר באזור הכניסה.
B9: 5. ביצועים | C9: בסוף כל חודש הזן את שווי התיק (או השאר — החודש הנוכחי מתמלא לבד). מקבלים תשואה חודשית ומצטברת מנוטרלת הפקדות.
B10: 6. דשבורד | C10: תמונת מצב: שווי, רווח, דיבידנדים, חום התיק (סיכון כולל), התראות פעילות, פיזור סקטורים וגרפים.
B12: מקרא צבעים
B13: תא צהוב / טקסט כחול | C13: שדה קלט — כאן מקלידים.
B14: טקסט שחור | C14: נוסחה — לא לגעת.
B15: כותרת זהובה | C15: עמודת קלט בטבלה.
B17: מחירים חיים
B18: Google Sheets | C18: קובץ ← ייבוא ← העלה את הקובץ. עמודת "מחיר" משתמשת ב-GOOGLEFINANCE ומתעדכנת אוטומטית (עיכוב של עד 20 דק').
B19: Excel | C19: GOOGLEFINANCE לא קיים באקסל, ולכן נלקח המחיר מעמודת "מחיר ידני". עדכן אותה כשתרצה.
B20: טיקרים | C20: מניות ארה"ב: AAPL. ת"א: TLV:TEVA. אם GOOGLEFINANCE לא מזהה טיקר — נלקח המחיר הידני.
B22: התראות בטבלת התיק
B23: 🔴 סטופ נפגע | C23: המחיר מתחת לסטופ — לצאת.
B24: 🟠 אין סטופ | C24: לפוזיציה לא הוגדר סטופ.
B25: 🟠 קרוב לסטופ | C25: נותרו פחות מסף הקרבה (ברירת מחדל 2%) עד הסטופ.
B26: 🟡 הזז לאיזון | C26: הרווח עבר 1R והסטופ עדיין מתחת לעלות — אפשר להעלות אותו לנקודת הכניסה ולהסיר סיכון.
B27: 🟢 מימוש חלקי | C27: הרווח עבר את סף ה-R למימוש (ברירת מחדל 3R).
B28: ⚠️ סיכון חורג | C28: ההפסד האפשרי בפוזיציה גדול מ-% הסיכון לעסקה.
B29: ✅ תקין | C29: אין מה לעשות.
B31: הערות
B32: עלות ממוצעת | C32: שיטת ממוצע משוקלל של כל הקניות עד אותה עסקה. רווח ממומש מחושב מול העלות הזו.
B33: נתוני דוגמה | C33: השורות המסומנות "דוגמה" בעסקאות ובתיק — מחק אותן לפני שאתה מזין את התיק האמיתי.

Sheet דשבורד
A1: 🎯 Pearl Portfolio · דשבורד
A2: תמונת מצב של התיק — מתעדכן אוטומטית.
B4: שווי | E4: רווח | H4: הכנסות ועלויות | K4: סיכון
B5: שווי תיק כולל $ | C5: =C6+C8 | E5: הון שהופקד נטו $ | F5: =SUMIFS('עסקאות'!$F$5:$F$1004,'עסקאות'!$B$5:$B$1004,"הפקדה")-SUMIFS('עסקאות'!$F$5:$F$1004,'עסקאות'!$B$5:$B$1004,"משיכה") | H5: רווח ממומש $ | I5: =SUM('עסקאות'!$J$5:$J$1004) | K5: חום התיק (סיכון כולל) | L5: =IF(C5=0,"",SUM('תיק'!$S$5:$S$54)/C5)
B6: שווי מניות $ | C6: =SUM('תיק'!$H$5:$H$54) | E6: רווח כולל $ | F6: =C5-F5 | H6: דיבידנדים מצטברים $ | I6: =SUMIFS('עסקאות'!$F$5:$F$1004,'עסקאות'!$B$5:$B$1004,"דיבידנד") | K6: תקרת חום | L6: =MaxHeat
B7: שווי כולל ₪ | C7: =C5*Fx | E7: תשואה כוללת | F7: =IF(F5=0,"",F6/F5) | H7: דיבידנד שנתי צפוי $ | I7: =IFERROR(IF(TODAY()-MIN('עסקאות'!$A$5:$A$1004)<30,I6,I6*365/(TODAY()-MIN('עסקאות'!$A$5:$A$1004))),0) | K7: פוזיציות פתוחות | L7: =COUNTIF('תיק'!$D$5:$D$54,">0")
B8: מזומן $ | C8: =SUM('עסקאות'!$H$5:$H$1004) | E8: רווח לא ממומש $ | F8: =SUM('תיק'!$J$5:$J$54) | H8: עמלות ששולמו $ | I8: =SUM('עסקאות'!$G$5:$G$1004) | K8: התראות פעילות | L8: =COUNTIF('תיק'!$W$5:$W$54,"🔴*")+COUNTIF('תיק'!$W$5:$W$54,"🟠*")+COUNTIF('תיק'!$W$5:$W$54,"🟡*")+COUNTIF('תיק'!$W$5:$W$54,"🟢*")+COUNTIF('תיק'!$W$5:$W$54,"⚠️*")
B10: פיזור לפי סקטור | H10: התראות לפי פוזיציה
B11: סקטור | C11: שווי $ | E11: משקל | H11: טיקר | I11: פעולה
B12: ='הגדרות'!A16 | C12: =SUMIFS('תיק'!$H$5:$H$54,'תיק'!$C$5:$C$54,B12) | E12: =IF($C$6=0,"",C12/$C$6) | H12: =IFERROR(INDEX('תיק'!$A$5:$A$54,MATCH(1,'תיק'!$X$5:$X$54,0)),"") | I12: =IF(H12="","",INDEX('תיק'!$W$5:$W$54,MATCH(H12,'תיק'!$A$5:$A$54,0)))
B13: ='הגדרות'!A17 | C13: =SUMIFS('תיק'!$H$5:$H$54,'תיק'!$C$5:$C$54,B13) | E13: =IF($C$6=0,"",C13/$C$6) | H13: =IFERROR(INDEX('תיק'!$A$5:$A$54,MATCH(2,'תיק'!$X$5:$X$54,0)),"") | I13: =IF(H13="","",INDEX('תיק'!$W$5:$W$54,MATCH(H13,'תיק'!$A$5:$A$54,0)))
B14: ='הגדרות'!A18 | C14: =SUMIFS('תיק'!$H$5:$H$54,'תיק'!$C$5:$C$54,B14) | E14: =IF($C$6=0,"",C14/$C$6) | H14: =IFERROR(INDEX('תיק'!$A$5:$A$54,MATCH(3,'תיק'!$X$5:$X$54,0)),"") | I14: =IF(H14="","",INDEX('תיק'!$W$5:$W$54,MATCH(H14,'תיק'!$A$5:$A$54,0)))
B15: ='הגדרות'!A19 | C15: =SUMIFS('תיק'!$H$5:$H$54,'תיק'!$C$5:$C$54,B15) | E15: =IF($C$6=0,"",C15/$C$6) | H15: =IFERROR(INDEX('תיק'!$A$5:$A$54,MATCH(4,'תיק'!$X$5:$X$54,0)),"") | I15: =IF(H15="","",INDEX('תיק'!$W$5:$W$54,MATCH(H15,'תיק'!$A$5:$A$54,0)))
B16: ='הגדרות'!A20 | C16: =SUMIFS('תיק'!$H$5:$H$54,'תיק'!$C$5:$C$54,B16) | E16: =IF($C$6=0,"",C16/$C$6) | H16: =IFERROR(INDEX('תיק'!$A$5:$A$54,MATCH(5,'תיק'!$X$5:$X$54,0)),"") | I16: =IF(H16="","",INDEX('תיק'!$W$5:$W$54,MATCH(H16,'תיק'!$A$5:$A$54,0)))
B17: ='הגדרות'!A21 | C17: =SUMIFS('תיק'!$H$5:$H$54,'תיק'!$C$5:$C$54,B17) | E17: =IF($C$6=0,"",C17/$C$6) | H17: =IFERROR(INDEX('תיק'!$A$5:$A$54,MATCH(6,'תיק'!$X$5:$X$54,0)),"") | I17: =IF(H17="","",INDEX('תיק'!$W$5:$W$54,MATCH(H17,'תיק'!$A$5:$A$54,0)))
B18: ='הגדרות'!A22 | C18: =SUMIFS('תיק'!$H$5:$H$54,'תיק'!$C$5:$C$54,B18) | E18: =IF($C$6=0,"",C18/$C$6) | H18: =IFERROR(INDEX('תיק'!$A$5:$A$54,MATCH(7,'תיק'!$X$5:$X$54,0)),"") | I18: =IF(H18="","",INDEX('תיק'!$W$5:$W$54,MATCH(H18,'תיק'!$A$5:$A$54,0)))
B19: ='הגדרות'!A23 | C19: =SUMIFS('תיק'!$H$5:$H$54,'תיק'!$C$5:$C$54,B19) | E19: =IF($C$6=0,"",C19/$C$6) | H19: =IFERROR(INDEX('תיק'!$A$5:$A$54,MATCH(8,'תיק'!$X$5:$X$54,0)),"") | I19: =IF(H19="","",INDEX('תיק'!$W$5:$W$54,MATCH(H19,'תיק'!$A$5:$A$54,0)))
B20: ='הגדרות'!A24 | C20: =SUMIFS('תיק'!$H$5:$H$54,'תיק'!$C$5:$C$54,B20) | E20: =IF($C$6=0,"",C20/$C$6) | H20: =IFERROR(INDEX('תיק'!$A$5:$A$54,MATCH(9,'תיק'!$X$5:$X$54,0)),"") | I20: =IF(H20="","",INDEX('תיק'!$W$5:$W$54,MATCH(H20,'תיק'!$A$5:$A$54,0)))
B21: ='הגדרות'!A25 | C21: =SUMIFS('תיק'!$H$5:$H$54,'תיק'!$C$5:$C$54,B21) | E21: =IF($C$6=0,"",C21/$C$6) | H21: =IFERROR(INDEX('תיק'!$A$5:$A$54,MATCH(10,'תיק'!$X$5:$X$54,0)),"") | I21: =IF(H21="","",INDEX('תיק'!$W$5:$W$54,MATCH(H21,'תיק'!$A$5:$A$54,0)))
B22: ='הגדרות'!A26 | C22: =SUMIFS('תיק'!$H$5:$H$54,'תיק'!$C$5:$C$54,B22) | E22: =IF($C$6=0,"",C22/$C$6)
B23: ='הגדרות'!A27 | C23: =SUMIFS('תיק'!$H$5:$H$54,'תיק'!$C$5:$C$54,B23) | E23: =IF($C$6=0,"",C23/$C$6)
B24: ='הגדרות'!A28 | C24: =SUMIFS('תיק'!$H$5:$H$54,'תיק'!$C$5:$C$54,B24) | E24: =IF($C$6=0,"",C24/$C$6)

Sheet תיק
A1: 💼 התיק שלי
A2: רשום טיקר, סקטור וסטופים — כל השאר מחושב מיומן העסקאות.
A4: טיקר | B4: שם | C4: סקטור | D4: כמות | E4: עלות ממוצעת $ | F4: מחיר ידני $ | G4: מחיר $ | H4: שווי שוק $ | I4: עלות $ | J4: רווח לא ממומש $ | K4: רווח % | L4: משקל בתיק | M4: משקל יעד | N4: איזון $ (+קנה / −מכור) | O4: סטופ התחלתי $ | P4: סטופ נוכחי $ | Q4: מרחק לסטופ | R4: R | S4: סיכון להון $ | T4: סיכון % מהתיק | U4: רווח ממומש $ | V4: דיבידנדים $ | W4: פעולה | X4: #
A5: AAPL | B5: Apple | C5: טכנולוגיה | D5: =IF(A5="","",SUMIFS('עסקאות'!$D$5:$D$1004,'עסקאות'!$C$5:$C$1004,A5,'עסקאות'!$B$5:$B$1004,"קנייה")-SUMIFS('עסקאות'!$D$5:$D$1004,'עסקאות'!$C$5:$C$1004,A5,'עסקאות'!$B$5:$B$1004,"מכירה")) | E5: =IF(A5="","",IFERROR(SUMIFS('עסקאות'!$I$5:$I$1004,'עסקאות'!$C$5:$C$1004,A5)/SUMIFS('עסקאות'!$D$5:$D$1004,'עסקאות'!$C$5:$C$1004,A5,'עסקאות'!$B$5:$B$1004,"קנייה"),0)) | F5: 232 | G5: =IF(A5="","",IFERROR(GOOGLEFINANCE(A5),F5)) | H5: =IF(A5="",0,D5*G5) | I5: =IF(A5="",0,D5*E5) | J5: =IF(A5="",0,H5-I5) | K5: =IF(I5=0,"",J5/I5) | L5: =IF(Equity=0,"",H5/Equity) | M5: 0.15 | N5: =IF(OR(A5="",M5=""),"",M5*Equity-H5) | O5: 170 | P5: 205 | Q5: =IF(OR(A5="",P5="",G5=0),"",(G5-P5)/G5) | R5: =IF(OR(A5="",O5="",E5<=O5),"",(G5-E5)/(E5-O5)) | S5: =IF(OR(A5="",P5=""),0,MAX(0,E5-P5)*D5) | T5: =IF(Equity=0,"",S5/Equity) | U5: =IF(A5="",0,SUMIFS('עסקאות'!$J$5:$J$1004,'עסקאות'!$C$5:$C$1004,A5)) | V5: =IF(A5="",0,SUMIFS('עסקאות'!$F$5:$F$1004,'עסקאות'!$C$5:$C$1004,A5,'עסקאות'!$B$5:$B$1004,"דיבידנד")) | W5: =IF(OR(A5="",D5<=0),"",IF(P5="","🟠 אין סטופ",IF(G5<=P5,"🔴 סטופ נפגע",IF(Q5<NearStop,"🟠 קרוב לסטופ",IF(AND(R5<>"",R5>=PartialR),"🟢 מימוש חלקי",IF(AND(R5<>"",R5>=1,P5<E5),"🟡 הזז לאיזון",IF(T5>RiskPct,"⚠️ סיכון חורג","✅ תקין"))))))) | X5: =IF(AND(W5<>"",W5<>"✅ תקין"),MAX($X$4:X4)+1,"")
A6: MSFT | B6: Microsoft | C6: טכנולוגיה | D6: =IF(A6="","",SUMIFS('עסקאות'!$D$5:$D$1004,'עסקאות'!$C$5:$C$1004,A6,'עסקאות'!$B$5:$B$1004,"קנייה")-SUMIFS('עסקאות'!$D$5:$D$1004,'עסקאות'!$C$5:$C$1004,A6,'עסקאות'!$B$5:$B$1004,"מכירה")) | E6: =IF(A6="","",IFERROR(SUMIFS('עסקאות'!$I$5:$I$1004,'עסקאות'!$C$5:$C$1004,A6)/SUMIFS('עסקאות'!$D$5:$D$1004,'עסקאות'!$C$5:$C$1004,A6,'עסקאות'!$B$5:$B$1004,"קנייה"),0)) | F6: 455 | G6: =IF(A6="","",IFERROR(GOOGLEFINANCE(A6),F6)) | H6: =IF(A6="",0,D6*G6) | I6: =IF(A6="",0,D6*E6) | J6: =IF(A6="",0,H6-I6) | K6: =IF(I6=0,"",J6/I6) | L6: =IF(Equity=0,"",H6/Equity) | M6: 0.15 | N6: =IF(OR(A6="",M6=""),"",M6*Equity-H6) | O6: 380 | P6: 400 | Q6: =IF(OR(A6="",P6="",G6=0),"",(G6-P6)/G6) | R6: =IF(OR(A6="",O6="",E6<=O6),"",(G6-E6)/(E6-O6)) | S6: =IF(OR(A6="",P6=""),0,MAX(0,E6-P6)*D6) | T6: =IF(Equity=0,"",S6/Equity) | U6: =IF(A6="",0,SUMIFS('עסקאות'!$J$5:$J$1004,'עסקאות'!$C$5:$C$1004,A6)) | V6: =IF(A6="",0,SUMIFS('עסקאות'!$F$5:$F$1004,'עסקאות'!$C$5:$C$1004,A6,'עסקאות'!$B$5:$B$1004,"דיבידנד")) | W6: =IF(OR(A6="",D6<=0),"",IF(P6="","🟠 אין סטופ",IF(G6<=P6,"🔴 סטופ נפגע",IF(Q6<NearStop,"🟠 קרוב לסטופ",IF(AND(R6<>"",R6>=PartialR),"🟢 מימוש חלקי",IF(AND(R6<>"",R6>=1,P6<E6),"🟡 הזז לאיזון",IF(T6>RiskPct,"⚠️ סיכון חורג","✅ תקין"))))))) | X6: =IF(AND(W6<>"",W6<>"✅ תקין"),MAX($X$4:X5)+1,"")
A7: NVDA | B7: Nvidia | C7: טכנולוגיה | D7: =IF(A7="","",SUMIFS('עסקאות'!$D$5:$D$1004,'עסקאות'!$C$5:$C$1004,A7,'עסקאות'!$B$5:$B$1004,"קנייה")-SUMIFS('עסקאות'!$D$5:$D$1004,'עסקאות'!$C$5:$C$1004,A7,'עסקאות'!$B$5:$B$1004,"מכירה")) | E7: =IF(A7="","",IFERROR(SUMIFS('עסקאות'!$I$5:$I$1004,'עסקאות'!$C$5:$C$1004,A7)/SUMIFS('עסקאות'!$D$5:$D$1004,'עסקאות'!$C$5:$C$1004,A7,'עסקאות'!$B$5:$B$1004,"קנייה"),0)) | F7: 178 | G7: =IF(A7="","",IFERROR(GOOGLEFINANCE(A7),F7)) | H7: =IF(A7="",0,D7*G7) | I7: =IF(A7="",0,D7*E7) | J7: =IF(A7="",0,H7-I7) | K7: =IF(I7=0,"",J7/I7) | L7: =IF(Equity=0,"",H7/Equity) | M7: 0.12 | N7: =IF(OR(A7="",M7=""),"",M7*Equity-H7) | O7: 105 | P7: 150 | Q7: =IF(OR(A7="",P7="",G7=0),"",(G7-P7)/G7) | R7: =IF(OR(A7="",O7="",E7<=O7),"",(G7-E7)/(E7-O7)) | S7: =IF(OR(A7="",P7=""),0,MAX(0,E7-P7)*D7) | T7: =IF(Equity=0,"",S7/Equity) | U7: =IF(A7="",0,SUMIFS('עסקאות'!$J$5:$J$1004,'עסקאות'!$C$5:$C$1004,A7)) | V7: =IF(A7="",0,SUMIFS('עסקאות'!$F$5:$F$1004,'עסקאות'!$C$5:$C$1004,A7,'עסקאות'!$B$5:$B$1004,"דיבידנד")) | W7: =IF(OR(A7="",D7<=0),"",IF(P7="","🟠 אין סטופ",IF(G7<=P7,"🔴 סטופ נפגע",IF(Q7<NearStop,"🟠 קרוב לסטופ",IF(AND(R7<>"",R7>=PartialR),"🟢 מימוש חלקי",IF(AND(R7<>"",R7>=1,P7<E7),"🟡 הזז לאיזון",IF(T7>RiskPct,"⚠️ סיכון חורג","✅ תקין"))))))) | X7: =IF(AND(W7<>"",W7<>"✅ תקין"),MAX($X$4:X6)+1,"")
A8: KO | B8: Coca-Cola | C8: צריכה בסיסית | D8: =IF(A8="","",SUMIFS('עסקאות'!$D$5:$D$1004,'עסקאות'!$C$5:$C$1004,A8,'עסקאות'!$B$5:$B$1004,"קנייה")-SUMIFS('עסקאות'!$D$5:$D$1004,'עסקאות'!$C$5:$C$1004,A8,'עסקאות'!$B$5:$B$1004,"מכירה")) | E8: =IF(A8="","",IFERROR(SUMIFS('עסקאות'!$I$5:$I$1004,'עסקאות'!$C$5:$C$1004,A8)/SUMIFS('עסקאות'!$D$5:$D$1004,'עסקאות'!$C$5:$C$1004,A8,'עסקאות'!$B$5:$B$1004,"קנייה"),0)) | F8: 68.5 | G8: =IF(A8="","",IFERROR(GOOGLEFINANCE(A8),F8)) | H8: =IF(A8="",0,D8*G8) | I8: =IF(A8="",0,D8*E8) | J8: =IF(A8="",0,H8-I8) | K8: =IF(I8=0,"",J8/I8) | L8: =IF(Equity=0,"",H8/Equity) | M8: 0.1 | N8: =IF(OR(A8="",M8=""),"",M8*Equity-H8) | O8: 58 | P8: 59 | Q8: =IF(OR(A8="",P8="",G8=0),"",(G8-P8)/G8) | R8: =IF(OR(A8="",O8="",E8<=O8),"",(G8-E8)/(E8-O8)) | S8: =IF(OR(A8="",P8=""),0,MAX(0,E8-P8)*D8) | T8: =IF(Equity=0,"",S8/Equity) | U8: =IF(A8="",0,SUMIFS('עסקאות'!$J$5:$J$1004,'עסקאות'!$C$5:$C$1004,A8)) | V8: =IF(A8="",0,SUMIFS('עסקאות'!$F$5:$F$1004,'עסקאות'!$C$5:$C$1004,A8,'עסקאות'!$B$5:$B$1004,"דיבידנד")) | W8: =IF(OR(A8="",D8<=0),"",IF(P8="","🟠 אין סטופ",IF(G8<=P8,"🔴 סטופ נפגע",IF(Q8<NearStop,"🟠 קרוב לסטופ",IF(AND(R8<>"",R8>=PartialR),"🟢 מימוש חלקי",IF(AND(R8<>"",R8>=1,P8<E8),"🟡 הזז לאיזון",IF(T8>RiskPct,"⚠️ סיכון חורג","✅ תקין"))))))) | X8: =IF(AND(W8<>"",W8<>"✅ תקין"),MAX($X$4:X7)+1,"")
A9: SPY | B9: S&P 500 ETF | C9: ETF / מדד | D9: =IF(A9="","",SUMIFS('עסקאות'!$D$5:$D$1004,'עסקאות'!$C$5:$C$1004,A9,'עסקאות'!$B$5:$B$1004,"קנייה")-SUMIFS('עסקאות'!$D$5:$D$1004,'עסקאות'!$C$5:$C$1004,A9,'עסקאות'!$B$5:$B$1004,"מכירה")) | E9: =IF(A9="","",IFERROR(SUMIFS('עסקאות'!$I$5:$I$1004,'עסקאות'!$C$5:$C$1004,A9)/SUMIFS('עסקאות'!$D$5:$D$1004,'עסקאות'!$C$5:$C$1004,A9,'עסקאות'!$B$5:$B$1004,"קנייה"),0)) | F9: 655 | G9: =IF(A9="","",IFERROR(GOOGLEFINANCE(A9),F9)) | H9: =IF(A9="",0,D9*G9) | I9: =IF(A9="",0,D9*E9) | J9: =IF(A9="",0,H9-I9) | K9: =IF(I9=0,"",J9/I9) | L9: =IF(Equity=0,"",H9/Equity) | M9: 0.3 | N9: =IF(OR(A9="",M9=""),"",M9*Equity-H9) | O9: 545 | Q9: =IF(OR(A9="",P9="",G9=0),"",(G9-P9)/G9) | R9: =IF(OR(A9="",O9="",E9<=O9),"",(G9-E9)/(E9-O9)) | S9: =IF(OR(A9="",P9=""),0,MAX(0,E9-P9)*D9) | T9: =IF(Equity=0,"",S9/Equity) | U9: =IF(A9="",0,SUMIFS('עסקאות'!$J$5:$J$1004,'עסקאות'!$C$5:$C$1004,A9)) | V9: =IF(A9="",0,SUMIFS('עסקאות'!$F$5:$F$1004,'עסקאות'!$C$5:$C$1004,A9,'עסקאות'!$B$5:$B$1004,"דיבידנד")) | W9: =IF(OR(A9="",D9<=0),"",IF(P9="","🟠 אין סטופ",IF(G9<=P9,"🔴 סטופ נפגע",IF(Q9<NearStop,"🟠 קרוב לסטופ",IF(AND(R9<>"",R9>=PartialR),"🟢 מימוש חלקי",IF(AND(R9<>"",R9>=1,P9<E9),"🟡 הזז לאיזון",IF(T9>RiskPct,"⚠️ סיכון חורג","✅ תקין"))))))) | X9: =IF(AND(W9<>"",W9<>"✅ תקין"),MAX($X$4:X8)+1,"")
D10: =IF(A10="","",SUMIFS('עסקאות'!$D$5:$D$1004,'עסקאות'!$C$5:$C$1004,A10,'עסקאות'!$B$5:$B$1004,"קנייה")-SUMIFS('עסקאות'!$D$5:$D$1004,'עסקאות'!$C$5:$C$1004,A10,'עסקאות'!$B$5:$B$1004,"מכירה")) | E10: =IF(A10="","",IFERROR(SUMIFS('עסקאות'!$I$5:$I$1004,'עסקאות'!$C$5:$C$1004,A10)/SUMIFS('עסקאות'!$D$5:$D$1004,'עסקאות'!$C$5:$C$1004,A10,'עסקאות'!$B$5:$B$1004,"קנייה"),0)) | G10: =IF(A10="","",IFERROR(GOOGLEFINANCE(A10),F10)) | H10: =IF(A10="",0,D10*G10) | I10: =IF(A10="",0,D10*E10) | J10: =IF(A10="",0,H10-I10) | K10: =IF(I10=0,"",J10/I10) | L10: =IF(Equity=0,"",H10/Equity) | N10: =IF(OR(A10="",M10=""),"",M10*Equity-H10) | Q10: =IF(OR(A10="",P10="",G10=0),"",(G10-P10)/G10) | R10: =IF(OR(A10="",O10="",E10<=O10),"",(G10-E10)/(E10-O10)) | S10: =IF(OR(A10="",P10=""),0,MAX(0,E10-P10)*D10) | T10: =IF(Equity=0,"",S10/Equity) | U10: =IF(A10="",0,SUMIFS('עסקאות'!$J$5:$J$1004,'עסקאות'!$C$5:$C$1004,A10)) | V10: =IF(A10="",0,SUMIFS('עסקאות'!$F$5:$F$1004,'עסקאות'!$C$5:$C$1004,A10,'עסקאות'!$B$5:$B$1004,"דיבידנד")) | W10: =IF(OR(A10="",D10<=0),"",IF(P10="","🟠 אין סטופ",IF(G10<=P10,"🔴 סטופ נפגע",IF(Q10<NearStop,"🟠 קרוב לסטופ",IF(AND(R10<>"",R10>=PartialR),"🟢 מימוש חלקי",IF(AND(R10<>"",R10>=1,P10<E10),"🟡 הזז לאיזון",IF(T10>RiskPct,"⚠️ סיכון חורג","✅ תקין"))))))) | X10: =IF(AND(W10<>"",W10<>"✅ תקין"),MAX($X$4:X9)+1,"")
D11: =IF(A11="","",SUMIFS('עסקאות'!$D$5:$D$1004,'עסקאות'!$C$5:$C$1004,A11,'עסקאות'!$B$5:$B$1004,"קנייה")-SUMIFS('עסקאות'!$D$5:$D$1004,'עסקאות'!$C$5:$C$1004,A11,'עסקאות'!$B$5:$B$1004,"מכירה")) | E11: =IF(A11="","",IFERROR(SUMIFS('עסקאות'!$I$5:$I$1004,'עסקאות'!$C$5:$C$1004,A11)/SUMIFS('עסקאות'!$D$5:$D$1004,'עסקאות'!$C$5:$C$1004,A11,'עסקאות'!$B$5:$B$1004,"קנייה"),0)) | G11: =IF(A11="","",IFERROR(GOOGLEFINANCE(A11),F11)) | H11: =IF(A11="",0,D11*G11) | I11: =IF(A11="",0,D11*E11) | J11: =IF(A11="",0,H11-I11) | K11: =IF(I11=0,"",J11/I11) | L11: =IF(Equity=0,"",H11/Equity) | N11: =IF(OR(A11="",M11=""),"",M11*Equity-H11) | Q11: =IF(OR(A11="",P11="",G11=0),"",(G11-P11)/G11) | R11: =IF(OR(A11="",O11="",E11<=O11),"",(G11-E11)/(E11-O11)) | S11: =IF(OR(A11="",P11=""),0,MAX(0,E11-P11)*D11) | T11: =IF(Equity=0,"",S11/Equity) | U11: =IF(A11="",0,SUMIFS('עסקאות'!$J$5:$J$1004,'עסקאות'!$C$5:$C$1004,A11)) | V11: =IF(A11="",0,SUMIFS('עסקאות'!$F$5:$F$1004,'עסקאות'!$C$5:$C$1004,A11,'עסקאות'!$B$5:$B$1004,"דיבידנד")) | W11: =IF(OR(A11="",D11<=0),"",IF(P11="","🟠 אין סטופ",IF(G11<=P11,"🔴 סטופ נפגע",IF(Q11<NearStop,"🟠 קרוב לסטופ",IF(AND(R11<>"",R11>=PartialR),"🟢 מימוש חלקי",IF(AND(R11<>"",R11>=1,P11<E11),"🟡 הזז לאיזון",IF(T11>RiskPct,"⚠️ סיכון חורג","✅ תקין"))))))) | X11: =IF(AND(W11<>"",W11<>"✅ תקין"),MAX($X$4:X10)+1,"")
D12: =IF(A12="","",SUMIFS('עסקאות'!$D$5:$D$1004,'עסקאות'!$C$5:$C$1004,A12,'עסקאות'!$B$5:$B$1004,"קנייה")-SUMIFS('עסקאות'!$D$5:$D$1004,'עסקאות'!$C$5:$C$1004,A12,'עסקאות'!$B$5:$B$1004,"מכירה")) | E12: =IF(A12="","",IFERROR(SUMIFS('עסקאות'!$I$5:$I$1004,'עסקאות'!$C$5:$C$1004,A12)/SUMIFS('עסקאות'!$D$5:$D$1004,'עסקאות'!$C$5:$C$1004,A12,'עסקאות'!$B$5:$B$1004,"קנייה"),0)) | G12: =IF(A12="","",IFERROR(GOOGLEFINANCE(A12),F12)) | H12: =IF(A12="",0,D12*G12) | I12: =IF(A12="",0,D12*E12) | J12: =IF(A12="",0,H12-I12) | K12: =IF(I12=0,"",J12/I12) | L12: =IF(Equity=0,"",H12/Equity) | N12: =IF(OR(A12="",M12=""),"",M12*Equity-H12) | Q12: =IF(OR(A12="",P12="",G12=0),"",(G12-P12)/G12) | R12: =IF(OR(A12="",O12="",E12<=O12),"",(G12-E12)/(E12-O12)) | S12: =IF(OR(A12="",P12=""),0,MAX(0,E12-P12)*D12) | T12: =IF(Equity=0,"",S12/Equity) | U12: =IF(A12="",0,SUMIFS('עסקאות'!$J$5:$J$1004,'עסקאות'!$C$5:$C$1004,A12)) | V12: =IF(A12="",0,SUMIFS('עסקאות'!$F$5:$F$1004,'עסקאות'!$C$5:$C$1004,A12,'עסקאות'!$B$5:$B$1004,"דיבידנד")) | W12: =IF(OR(A12="",D12<=0),"",IF(P12="","🟠 אין סטופ",IF(G12<=P12,"🔴 סטופ נפגע",IF(Q12<NearStop,"🟠 קרוב לסטופ",IF(AND(R12<>"",R12>=PartialR),"🟢 מימוש חלקי",IF(AND(R12<>"",R12>=1,P12<E12),"🟡 הזז לאיזון",IF(T12>RiskPct,"⚠️ סיכון חורג","✅ תקין"))))))) | X12: =IF(AND(W12<>"",W12<>"✅ תקין"),MAX($X$4:X11)+1,"")
D13: =IF(A13="","",SUMIFS('עסקאות'!$D$5:$D$1004,'עסקאות'!$C$5:$C$1004,A13,'עסקאות'!$B$5:$B$1004,"קנייה")-SUMIFS('עסקאות'!$D$5:$D$1004,'עסקאות'!$C$5:$C$1004,A13,'עסקאות'!$B$5:$B$1004,"מכירה")) | E13: =IF(A13="","",IFERROR(SUMIFS('עסקאות'!$I$5:$I$1004,'עסקאות'!$C$5:$C$1004,A13)/SUMIFS('עסקאות'!$D$5:$D$1004,'עסקאות'!$C$5:$C$1004,A13,'עסקאות'!$B$5:$B$1004,"קנייה"),0)) | G13: =IF(A13="","",IFERROR(GOOGLEFINANCE(A13),F13)) | H13: =IF(A13="",0,D13*G13) | I13: =IF(A13="",0,D13*E13) | J13: =IF(A13="",0,H13-I13) | K13: =IF(I13=0,"",J13/I13) | L13: =IF(Equity=0,"",H13/Equity) | N13: =IF(OR(A13="",M13=""),"",M13*Equity-H13) | Q13: =IF(OR(A13="",P13="",G13=0),"",(G13-P13)/G13) | R13: =IF(OR(A13="",O13="",E13<=O13),"",(G13-E13)/(E13-O13)) | S13: =IF(OR(A13="",P13=""),0,MAX(0,E13-P13)*D13) | T13: =IF(Equity=0,"",S13/Equity) | U13: =IF(A13="",0,SUMIFS('עסקאות'!$J$5:$J$1004,'עסקאות'!$C$5:$C$1004,A13)) | V13: =IF(A13="",0,SUMIFS('עסקאות'!$F$5:$F$1004,'עסקאות'!$C$5:$C$1004,A13,'עסקאות'!$B$5:$B$1004,"דיבידנד")) | W13: =IF(OR(A13="",D13<=0),"",IF(P13="","🟠 אין סטופ",IF(G13<=P13,"🔴 סטופ נפגע",IF(Q13<NearStop,"🟠 קרוב לסטופ",IF(AND(R13<>"",R13>=PartialR),"🟢 מימוש חלקי",IF(AND(R13<>"",R13>=1,P13<E13),"🟡 הזז לאיזון",IF(T13>RiskPct,"⚠️ סיכון חורג","✅ תקין"))))))) | X13: =IF(AND(W13<>"",W13<>"✅ תקין"),MAX($X$4:X12)+1,"")
D14: =IF(A14="","",SUMIFS('עסקאות'!$D$5:$D$1004,'עסקאות'!$C$5:$C$1004,A14,'עסקאות'!$B$5:$B$1004,"קנייה")-SUMIFS('עסקאות'!$D$5:$D$1004,'עסקאות'!$C$5:$C$1004,A14,'עסקאות'!$B$5:$B$1004,"מכירה")) | E14: =IF(A14="","",IFERROR(SUMIFS('עסקאות'!$I$5:$I$1004,'עסקאות'!$C$5:$C$1004,A14)/SUMIFS('עסקאות'!$D$5:$D$1004,'עסקאות'!$C$5:$C$1004,A14,'עסקאות'!$B$5:$B$1004,"קנייה"),0)) | G14: =IF(A14="","",IFERROR(GOOGLEFINANCE(A14),F14)) | H14: =IF(A14="",0,D14*G14) | I14: =IF(A14="",0,D14*E14) | J14: =IF(A14="",0,H14-I14) | K14: =IF(I14=0,"",J14/I14) | L14: =IF(Equity=0,"",H14/Equity) | N14: =IF(OR(A14="",M14=""),"",M14*Equity-H14) | Q14: =IF(OR(A14="",P14="",G14=0),"",(G14-P14)/G14) | R14: =IF(OR(A14="",O14="",E14<=O14),"",(G14-E14)/(E14-O14)) | S14: =IF(OR(A14="",P14=""),0,MAX(0,E14-P14)*D14) | T14: =IF(Equity=0,"",S14/Equity) | U14: =IF(A14="",0,SUMIFS('עסקאות'!$J$5:$J$1004,'עסקאות'!$C$5:$C$1004,A14)) | V14: =IF(A14="",0,SUMIFS('עסקאות'!$F$5:$F$1004,'עסקאות'!$C$5:$C$1004,A14,'עסקאות'!$B$5:$B$1004,"דיבידנד")) | W14: =IF(OR(A14="",D14<=0),"",IF(P14="","🟠 אין סטופ",IF(G14<=P14,"🔴 סטופ נפגע",IF(Q14<NearStop,"🟠 קרוב לסטופ",IF(AND(R14<>"",R14>=PartialR),"🟢 מימוש חלקי",IF(AND(R14<>"",R14>=1,P14<E14),"🟡 הזז לאיזון",IF(T14>RiskPct,"⚠️ סיכון חורג","✅ תקין"))))))) | X14: =IF(AND(W14<>"",W14<>"✅ תקין"),MAX($X$4:X13)+1,"")
D15: =IF(A15="","",SUMIFS('עסקאות'!$D$5:$D$1004,'עסקאות'!$C$5:$C$1004,A15,'עסקאות'!$B$5:$B$1004,"קנייה")-SUMIFS('עסקאות'!$D$5:$D$1004,'עסקאות'!$C$5:$C$1004,A15,'עסקאות'!$B$5:$B$1004,"מכירה")) | E15: =IF(A15="","",IFERROR(SUMIFS('עסקאות'!$I$5:$I$1004,'עסקאות'!$C$5:$C$1004,A15)/SUMIFS('עסקאות'!$D$5:$D$1004,'עסקאות'!$C$5:$C$1004,A15,'עסקאות'!$B$5:$B$1004,"קנייה"),0)) | G15: =IF(A15="","",IFERROR(GOOGLEFINANCE(A15),F15)) | H15: =IF(A15="",0,D15*G15) | I15: =IF(A15="",0,D15*E15) | J15: =IF(A15="",0,H15-I15) | K15: =IF(I15=0,"",J15/I15) | L15: =IF(Equity=0,"",H15/Equity) | N15: =IF(OR(A15="",M15=""),"",M15*Equity-H15) | Q15: =IF(OR(A15="",P15="",G15=0),"",(G15-P15)/G15) | R15: =IF(OR(A15="",O15="",E15<=O15),"",(G15-E15)/(E15-O15)) | S15: =IF(OR(A15="",P15=""),0,MAX(0,E15-P15)*D15) | T15: =IF(Equity=0,"",S15/Equity) | U15: =IF(A15="",0,SUMIFS('עסקאות'!$J$5:$J$1004,'עסקאות'!$C$5:$C$1004,A15)) | V15: =IF(A15="",0,SUMIFS('עסקאות'!$F$5:$F$1004,'עסקאות'!$C$5:$C$1004,A15,'עסקאות'!$B$5:$B$1004,"דיבידנד")) | W15: =IF(OR(A15="",D15<=0),"",IF(P15="","🟠 אין סטופ",IF(G15<=P15,"🔴 סטופ נפגע",IF(Q15<NearStop,"🟠 קרוב לסטופ",IF(AND(R15<>"",R15>=PartialR),"🟢 מימוש חלקי",IF(AND(R15<>"",R15>=1,P15<E15),"🟡 הזז לאיזון",IF(T15>RiskPct,"⚠️ סיכון חורג","✅ תקין"))))))) | X15: =IF(AND(W15<>"",W15<>"✅ תקין"),MAX($X$4:X14)+1,"")
D16: =IF(A16="","",SUMIFS('עסקאות'!$D$5:$D$1004,'עסקאות'!$C$5:$C$1004,A16,'עסקאות'!$B$5:$B$1004,"קנייה")-SUMIFS('עסקאות'!$D$5:$D$1004,'עסקאות'!$C$5:$C$1004,A16,'עסקאות'!$B$5:$B$1004,"מכירה")) | E16: =IF(A16="","",IFERROR(SUMIFS('עסקאות'!$I$5:$I$1004,'עסקאות'!$C$5:$C$1004,A16)/SUMIFS('עסקאות'!$D$5:$D$1004,'עסקאות'!$C$5:$C$1004,A16,'עסקאות'!$B$5:$B$1004,"קנייה"),0)) | G16: =IF(A16="","",IFERROR(GOOGLEFINANCE(A16),F16)) | H16: =IF(A16="",0,D16*G16) | I16: =IF(A16="",0,D16*E16) | J16: =IF(A16="",0,H16-I16) | K16: =IF(I16=0,"",J16/I16) | L16: =IF(Equity=0,"",H16/Equity) | N16: =IF(OR(A16="",M16=""),"",M16*Equity-H16) | Q16: =IF(OR(A16="",P16="",G16=0),"",(G16-P16)/G16) | R16: =IF(OR(A16="",O16="",E16<=O16),"",(G16-E16)/(E16-O16)) | S16: =IF(OR(A16="",P16=""),0,MAX(0,E16-P16)*D16) | T16: =IF(Equity=0,"",S16/Equity) | U16: =IF(A16="",0,SUMIFS('עסקאות'!$J$5:$J$1004,'עסקאות'!$C$5:$C$1004,A16)) | V16: =IF(A16="",0,SUMIFS('עסקאות'!$F$5:$F$1004,'עסקאות'!$C$5:$C$1004,A16,'עסקאות'!$B$5:$B$1004,"דיבידנד")) | W16: =IF(OR(A16="",D16<=0),"",IF(P16="","🟠 אין סטופ",IF(G16<=P16,"🔴 סטופ נפגע",IF(Q16<NearStop,"🟠 קרוב לסטופ",IF(AND(R16<>"",R16>=PartialR),"🟢 מימוש חלקי",IF(AND(R16<>"",R16>=1,P16<E16),"🟡 הזז לאיזון",IF(T16>RiskPct,"⚠️ סיכון חורג","✅ תקין"))))))) | X16: =IF(AND(W16<>"",W16<>"✅ תקין"),MAX($X$4:X15)+1,"")
D17: =IF(A17="","",SUMIFS('עסקאות'!$D$5:$D$1004,'עסקאות'!$C$5:$C$1004,A17,'עסקאות'!$B$5:$B$1004,"קנייה")-SUMIFS('עסקאות'!$D$5:$D$1004,'עסקאות'!$C$5:$C$1004,A17,'עסקאות'!$B$5:$B$1004,"מכירה")) | E17: =IF(A17="","",IFERROR(SUMIFS('עסקאות'!$I$5:$I$1004,'עסקאות'!$C$5:$C$1004,A17)/SUMIFS('עסקאות'!$D$5:$D$1004,'עסקאות'!$C$5:$C$1004,A17,'עסקאות'!$B$5:$B$1004,"קנייה"),0)) | G17: =IF(A17="","",IFERROR(GOOGLEFINANCE(A17),F17)) | H17: =IF(A17="",0,D17*G17) | I17: =IF(A17="",0,D17*E17) | J17: =IF(A17="",0,H17-I17) | K17: =IF(I17=0,"",J17/I17) | L17: =IF(Equity=0,"",H17/Equity) | N17: =IF(OR(A17="",M17=""),"",M17*Equity-H17) | Q17: =IF(OR(A17="",P17="",G17=0),"",(G17-P17)/G17) | R17: =IF(OR(A17="",O17="",E17<=O17),"",(G17-E17)/(E17-O17)) | S17: =IF(OR(A17="",P17=""),0,MAX(0,E17-P17)*D17) | T17: =IF(Equity=0,"",S17/Equity) | U17: =IF(A17="",0,SUMIFS('עסקאות'!$J$5:$J$1004,'עסקאות'!$C$5:$C$1004,A17)) | V17: =IF(A17="",0,SUMIFS('עסקאות'!$F$5:$F$1004,'עסקאות'!$C$5:$C$1004,A17,'עסקאות'!$B$5:$B$1004,"דיבידנד")) | W17: =IF(OR(A17="",D17<=0),"",IF(P17="","🟠 אין סטופ",IF(G17<=P17,"🔴 סטופ נפגע",IF(Q17<NearStop,"🟠 קרוב לסטופ",IF(AND(R17<>"",R17>=PartialR),"🟢 מימוש חלקי",IF(AND(R17<>"",R17>=1,P17<E17),"🟡 הזז לאיזון",IF(T17>RiskPct,"⚠️ סיכון חורג","✅ תקין"))))))) | X17: =IF(AND(W17<>"",W17<>"✅ תקין"),MAX($X$4:X16)+1,"")
D18: =IF(A18="","",SUMIFS('עסקאות'!$D$5:$D$1004,'עסקאות'!$C$5:$C$1004,A18,'עסקאות'!$B$5:$B$1004,"קנייה")-SUMIFS('עסקאות'!$D$5:$D$1004,'עסקאות'!$C$5:$C$1004,A18,'עסקאות'!$B$5:$B$1004,"מכירה")) | E18: =IF(A18="","",IFERROR(SUMIFS('עסקאות'!$I$5:$I$1004,'עסקאות'!$C$5:$C$1004,A18)/SUMIFS('עסקאות'!$D$5:$D$1004,'עסקאות'!$C$5:$C$1004,A18,'עסקאות'!$B$5:$B$1004,"קנייה"),0)) | G18: =IF(A18="","",IFERROR(GOOGLEFINANCE(A18),F18)) | H18: =IF(A18="",0,D18*G18) | I18: =IF(A18="",0,D18*E18) | J18: =IF(A18="",0,H18-I18) | K18: =IF(I18=0,"",J18/I18) | L18: =IF(Equity=0,"",H18/Equity) | N18: =IF(OR(A18="",M18=""),"",M18*Equity-H18) | Q18: =IF(OR(A18="",P18="",G18=0),"",(G18-P18)/G18) | R18: =IF(OR(A18="",O18="",E18<=O18),"",(G18-E18)/(E18-O18)) | S18: =IF(OR(A18="",P18=""),0,MAX(0,E18-P18)*D18) | T18: =IF(Equity=0,"",S18/Equity) | U18: =IF(A18="",0,SUMIFS('עסקאות'!$J$5:$J$1004,'עסקאות'!$C$5:$C$1004,A18)) | V18: =IF(A18="",0,SUMIFS('עסקאות'!$F$5:$F$1004,'עסקאות'!$C$5:$C$1004,A18,'עסקאות'!$B$5:$B$1004,"דיבידנד")) | W18: =IF(OR(A18="",D18<=0),"",IF(P18="","🟠 אין סטופ",IF(G18<=P18,"🔴 סטופ נפגע",IF(Q18<NearStop,"🟠 קרוב לסטופ",IF(AND(R18<>"",R18>=PartialR),"🟢 מימוש חלקי",IF(AND(R18<>"",R18>=1,P18<E18),"🟡 הזז לאיזון",IF(T18>RiskPct,"⚠️ סיכון חורג","✅ תקין"))))))) | X18: =IF(AND(W18<>"",W18<>"✅ תקין"),MAX($X$4:X17)+1,"")
D19: =IF(A19="","",SUMIFS('עסקאות'!$D$5:$D$1004,'עסקאות'!$C$5:$C$1004,A19,'עסקאות'!$B$5:$B$1004,"קנייה")-SUMIFS('עסקאות'!$D$5:$D$1004,'עסקאות'!$C$5:$C$1004,A19,'עסקאות'!$B$5:$B$1004,"מכירה")) | E19: =IF(A19="","",IFERROR(SUMIFS('עסקאות'!$I$5:$I$1004,'עסקאות'!$C$5:$C$1004,A19)/SUMIFS('עסקאות'!$D$5:$D$1004,'עסקאות'!$C$5:$C$1004,A19,'עסקאות'!$B$5:$B$1004,"קנייה"),0)) | G19: =IF(A19="","",IFERROR(GOOGLEFINANCE(A19),F19)) | H19: =IF(A19="",0,D19*G19) | I19: =IF(A19="",0,D19*E19) | J19: =IF(A19="",0,H19-I19) | K19: =IF(I19=0,"",J19/I19) | L19: =IF(Equity=0,"",H19/Equity) | N19: =IF(OR(A19="",M19=""),"",M19*Equity-H19) | Q19: =IF(OR(A19="",P19="",G19=0),"",(G19-P19)/G19) | R19: =IF(OR(A19="",O19="",E19<=O19),"",(G19-E19)/(E19-O19)) | S19: =IF(OR(A19="",P19=""),0,MAX(0,E19-P19)*D19) | T19: =IF(Equity=0,"",S19/Equity) | U19: =IF(A19="",0,SUMIFS('עסקאות'!$J$5:$J$1004,'עסקאות'!$C$5:$C$1004,A19)) | V19: =IF(A19="",0,SUMIFS('עסקאות'!$F$5:$F$1004,'עסקאות'!$C$5:$C$1004,A19,'עסקאות'!$B$5:$B$1004,"דיבידנד")) | W19: =IF(OR(A19="",D19<=0),"",IF(P19="","🟠 אין סטופ",IF(G19<=P19,"🔴 סטופ נפגע",IF(Q19<NearStop,"🟠 קרוב לסטופ",IF(AND(R19<>"",R19>=PartialR),"🟢 מימוש חלקי",IF(AND(R19<>"",R19>=1,P19<E19),"🟡 הזז לאיזון",IF(T19>RiskPct,"⚠️ סיכון חורג","✅ תקין"))))))) | X19: =IF(AND(W19<>"",W19<>"✅ תקין"),MAX($X$4:X18)+1,"")
D20: =IF(A20="","",SUMIFS('עסקאות'!$D$5:$D$1004,'עסקאות'!$C$5:$C$1004,A20,'עסקאות'!$B$5:$B$1004,"קנייה")-SUMIFS('עסקאות'!$D$5:$D$1004,'עסקאות'!$C$5:$C$1004,A20,'עסקאות'!$B$5:$B$1004,"מכירה")) | E20: =IF(A20="","",IFERROR(SUMIFS('עסקאות'!$I$5:$I$1004,'עסקאות'!$C$5:$C$1004,A20)/SUMIFS('עסקאות'!$D$5:$D$1004,'עסקאות'!$C$5:$C$1004,A20,'עסקאות'!$B$5:$B$1004,"קנייה"),0)) | G20: =IF(A20="","",IFERROR(GOOGLEFINANCE(A20),F20)) | H20: =IF(A20="",0,D20*G20) | I20: =IF(A20="",0,D20*E20) | J20: =IF(A20="",0,H20-I20) | K20: =IF(I20=0,"",J20/I20) | L20: =IF(Equity=0,"",H20/Equity) | N20: =IF(OR(A20="",M20=""),"",M20*Equity-H20) | Q20: =IF(OR(A20="",P20="",G20=0),"",(G20-P20)/G20) | R20: =IF(OR(A20="",O20="",E20<=O20),"",(G20-E20)/(E20-O20)) | S20: =IF(OR(A20="",P20=""),0,MAX(0,E20-P20)*D20) | T20: =IF(Equity=0,"",S20/Equity) | U20: =IF(A20="",0,SUMIFS('עסקאות'!$J$5:$J$1004,'עסקאות'!$C$5:$C$1004,A20)) | V20: =IF(A20="",0,SUMIFS('עסקאות'!$F$5:$F$1004,'עסקאות'!$C$5:$C$1004,A20,'עסקאות'!$B$5:$B$1004,"דיבידנד")) | W20: =IF(OR(A20="",D20<=0),"",IF(P20="","🟠 אין סטופ",IF(G20<=P20,"🔴 סטופ נפגע",IF(Q20<NearStop,"🟠 קרוב לסטופ",IF(AND(R20<>"",R20>=PartialR),"🟢 מימוש חלקי",IF(AND(R20<>"",R20>=1,P20<E20),"🟡 הזז לאיזון",IF(T20>RiskPct,"⚠️ סיכון חורג","✅ תקין"))))))) | X20: =IF(AND(W20<>"",W20<>"✅ תקין"),MAX($X$4:X19)+1,"")
D21: =IF(A21="","",SUMIFS('עסקאות'!$D$5:$D$1004,'עסקאות'!$C$5:$C$1004,A21,'עסקאות'!$B$5:$B$1004,"קנייה")-SUMIFS('עסקאות'!$D$5:$D$1004,'עסקאות'!$C$5:$C$1004,A21,'עסקאות'!$B$5:$B$1004,"מכירה")) | E21: =IF(A21="","",IFERROR(SUMIFS('עסקאות'!$I$5:$I$1004,'עסקאות'!$C$5:$C$1004,A21)/SUMIFS('עסקאות'!$D$5:$D$1004,'עסקאות'!$C$5:$C$1004,A21,'עסקאות'!$B$5:$B$1004,"קנייה"),0)) | G21: =IF(A21="","",IFERROR(GOOGLEFINANCE(A21),F21)) | H21: =IF(A21="",0,D21*G21) | I21: =IF(A21="",0,D21*E21) | J21: =IF(A21="",0,H21-I21) | K21: =IF(I21=0,"",J21/I21) | L21: =IF(Equity=0,"",H21/Equity) | N21: =IF(OR(A21="",M21=""),"",M21*Equity-H21) | Q21: =IF(OR(A21="",P21="",G21=0),"",(G21-P21)/G21) | R21: =IF(OR(A21="",O21="",E21<=O21),"",(G21-E21)/(E21-O21)) | S21: =IF(OR(A21="",P21=""),0,MAX(0,E21-P21)*D21) | T21: =IF(Equity=0,"",S21/Equity) | U21: =IF(A21="",0,SUMIFS('עסקאות'!$J$5:$J$1004,'עסקאות'!$C$5:$C$1004,A21)) | V21: =IF(A21="",0,SUMIFS('עסקאות'!$F$5:$F$1004,'עסקאות'!$C$5:$C$1004,A21,'עסקאות'!$B$5:$B$1004,"דיבידנד")) | W21: =IF(OR(A21="",D21<=0),"",IF(P21="","🟠 אין סטופ",IF(G21<=P21,"🔴 סטופ נפגע",IF(Q21<NearStop,"🟠 קרוב לסטופ",IF(AND(R21<>"",R21>=PartialR),"🟢 מימוש חלקי",IF(AND(R21<>"",R21>=1,P21<E21),"🟡 הזז לאיזון",IF(T21>RiskPct,"⚠️ סיכון חורג","✅ תקין"))))))) | X21: =IF(AND(W21<>"",W21<>"✅ תקין"),MAX($X$4:X20)+1,"")
... D54: =IF(A54="","",SUMIFS('עסקאות'!$D$5:$D$1004,'עסקאות'!$C$5:$C$1004,A54,'עסקאות'!$B$5:$B$1004,"קנייה")-SUMIFS('עסקאות'!$D$5:$D$1004,'עסקאות'!$C$5:$C$1004,A54,'עסקאות'!$B$5:$B$1004,"מכירה")) | E54: =IF(A54="","",IFERROR(SUMIFS('עסקאות'!$I$5:$I$1004,'עסקאות'!$C$5:$C$1004,A54)/SUMIFS('עסקאות'!$D$5:$D$1004,'עסקאות'!$C$5:$C$1004,A54,'עסקאות'!$B$5:$B$1004,"קנייה"),0)) | G54: =IF(A54="","",IFERROR(GOOGLEFINANCE(A54),F54)) | H54: =IF(A54="",0,D54*G54) | I54: =IF(A54="",0,D54*E54) | J54: =IF(A54="",0,H54-I54) | K54: =IF(I54=0,"",J54/I54) | L54: =IF(Equity=0,"",H54/Equity) | N54: =IF(OR(A54="",M54=""),"",M54*Equity-H54) | Q54: =IF(OR(A54="",P54="",G54=0),"",(G54-P54)/G54) | R54: =IF(OR(A54="",O54="",E54<=O54),"",(G54-E54)/(E54-O54)) | S54: =IF(OR(A54="",P54=""),0,MAX(0,E54-P54)*D54) | T54: =IF(Equity=0,"",S54/Equity) | U54: =IF(A54="",0,SUMIFS('עסקאות'!$J$5:$J$1004,'עסקאות'!$C$5:$C$1004,A54)) | V54: =IF(A54="",0,SUMIFS('עסקאות'!$F$5:$F$1004,'עסקאות'!$C$5:$C$1004,A54,'עסקאות'!$B$5:$B$1004,"דיבידנד")) | W54: =IF(OR(A54="",D54<=0),"",IF(P54="","🟠 אין סטופ",IF(G54<=P54,"🔴 סטופ נפגע",IF(Q54<NearStop,"🟠 קרוב לסטופ",IF(AND(R54<>"",R54>=PartialR),"🟢 מימוש חלקי",IF(AND(R54<>"",R54>=1,P54<E54),"🟡 הזז לאיזון",IF(T54>RiskPct,"⚠️ סיכון חורג","✅ תקין"))))))) | X54: =IF(AND(W54<>"",W54<>"✅ תקין"),MAX($X$4:X53)+1,"")
A55: סה"כ | H55: =SUM(H5:H54) | I55: =SUM(I5:I54) | J55: =SUM(J5:J54) | K55: =IF(I55=0,"",J55/I55) | L55: =SUM(L5:L54) | M55: =SUM(M5:M54) | S55: =SUM(S5:S54) | T55: =SUM(T5:T54) | U55: =SUM(U5:U54) | V55: =SUM(V5:V54)

Sheet עסקאות
A1: 📒 יומן עסקאות
A2: כל תנועה בתיק בשורה אחת. מכאן מחושב הכול.
A4: תאריך | B4: סוג | C4: טיקר | D4: כמות | E4: מחיר למניה $ | F4: סכום $ (דיבידנד/הפקדה/משיכה) | G4: עמלה $ | H4: תזרים מזומן $ | I4: עלות קנייה $ | J4: רווח ממומש $ | K4: הערות
A5: 46024 | B5: הפקדה | F5: 100000 | G5: 0 | H5: =IF(B5="","",IF(B5="קנייה",-(D5*E5+G5),IF(B5="מכירה",D5*E5-G5,IF(B5="דיבידנד",F5-G5,IF(B5="הפקדה",F5-G5,IF(B5="משיכה",-F5-G5,-G5)))))) | I5: =IF(B5="קנייה",D5*E5+G5,0) | J5: =IF(B5="מכירה",D5*E5-G5-D5*IFERROR(SUMIFS($I$5:I5,$C$5:C5,C5)/SUMIFS($D$5:D5,$C$5:C5,C5,$B$5:B5,"קנייה"),0),0) | K5: דוגמה — למחיקה
A6: 46027 | B6: קנייה | C6: AAPL | D6: 60 | E6: 185 | G6: 2.5 | H6: =IF(B6="","",IF(B6="קנייה",-(D6*E6+G6),IF(B6="מכירה",D6*E6-G6,IF(B6="דיבידנד",F6-G6,IF(B6="הפקדה",F6-G6,IF(B6="משיכה",-F6-G6,-G6)))))) | I6: =IF(B6="קנייה",D6*E6+G6,0) | J6: =IF(B6="מכירה",D6*E6-G6-D6*IFERROR(SUMIFS($I$5:I6,$C$5:C6,C6)/SUMIFS($D$5:D6,$C$5:C6,C6,$B$5:B6,"קנייה"),0),0) | K6: דוגמה — למחיקה
A7: 46027 | B7: קנייה | C7: MSFT | D7: 30 | E7: 410 | G7: 2.5 | H7: =IF(B7="","",IF(B7="קנייה",-(D7*E7+G7),IF(B7="מכירה",D7*E7-G7,IF(B7="דיבידנד",F7-G7,IF(B7="הפקדה",F7-G7,IF(B7="משיכה",-F7-G7,-G7)))))) | I7: =IF(B7="קנייה",D7*E7+G7,0) | J7: =IF(B7="מכירה",D7*E7-G7-D7*IFERROR(SUMIFS($I$5:I7,$C$5:C7,C7)/SUMIFS($D$5:D7,$C$5:C7,C7,$B$5:B7,"קנייה"),0),0) | K7: דוגמה — למחיקה
A8: 46034 | B8: קנייה | C8: NVDA | D8: 100 | E8: 120 | G8: 2.5 | H8: =IF(B8="","",IF(B8="קנייה",-(D8*E8+G8),IF(B8="מכירה",D8*E8-G8,IF(B8="דיבידנד",F8-G8,IF(B8="הפקדה",F8-G8,IF(B8="משיכה",-F8-G8,-G8)))))) | I8: =IF(B8="קנייה",D8*E8+G8,0) | J8: =IF(B8="מכירה",D8*E8-G8-D8*IFERROR(SUMIFS($I$5:I8,$C$5:C8,C8)/SUMIFS($D$5:D8,$C$5:C8,C8,$B$5:B8,"קנייה"),0),0) | K8: דוגמה — למחיקה
A9: 46056 | B9: קנייה | C9: KO | D9: 150 | E9: 62 | G9: 2.5 | H9: =IF(B9="","",IF(B9="קנייה",-(D9*E9+G9),IF(B9="מכירה",D9*E9-G9,IF(B9="דיבידנד",F9-G9,IF(B9="הפקדה",F9-G9,IF(B9="משיכה",-F9-G9,-G9)))))) | I9: =IF(B9="קנייה",D9*E9+G9,0) | J9: =IF(B9="מכירה",D9*E9-G9-D9*IFERROR(SUMIFS($I$5:I9,$C$5:C9,C9)/SUMIFS($D$5:D9,$C$5:C9,C9,$B$5:B9,"קנייה"),0),0) | K9: דוגמה — למחיקה
A10: 46070 | B10: קנייה | C10: SPY | D10: 25 | E10: 580 | G10: 2.5 | H10: =IF(B10="","",IF(B10="קנייה",-(D10*E10+G10),IF(B10="מכירה",D10*E10-G10,IF(B10="דיבידנד",F10-G10,IF(B10="הפקדה",F10-G10,IF(B10="משיכה",-F10-G10,-G10)))))) | I10: =IF(B10="קנייה",D10*E10+G10,0) | J10: =IF(B10="מכירה",D10*E10-G10-D10*IFERROR(SUMIFS($I$5:I10,$C$5:C10,C10)/SUMIFS($D$5:D10,$C$5:C10,C10,$B$5:B10,"קנייה"),0),0) | K10: דוגמה — למחיקה
A11: 46090 | B11: קנייה | C11: AAPL | D11: 20 | E11: 172 | G11: 2.5 | H11: =IF(B11="","",IF(B11="קנייה",-(D11*E11+G11),IF(B11="מכירה",D11*E11-G11,IF(B11="דיבידנד",F11-G11,IF(B11="הפקדה",F11-G11,IF(B11="משיכה",-F11-G11,-G11)))))) | I11: =IF(B11="קנייה",D11*E11+G11,0) | J11: =IF(B11="מכירה",D11*E11-G11-D11*IFERROR(SUMIFS($I$5:I11,$C$5:C11,C11)/SUMIFS($D$5:D11,$C$5:C11,C11,$B$5:B11,"קנייה"),0),0) | K11: דוגמה — למחיקה
A12: 46113 | B12: דיבידנד | C12: KO | F12: 65.03 | G12: 0 | H12: =IF(B12="","",IF(B12="קנייה",-(D12*E12+G12),IF(B12="מכירה",D12*E12-G12,IF(B12="דיבידנד",F12-G12,IF(B12="הפקדה",F12-G12,IF(B12="משיכה",-F12-G12,-G12)))))) | I12: =IF(B12="קנייה",D12*E12+G12,0) | J12: =IF(B12="מכירה",D12*E12-G12-D12*IFERROR(SUMIFS($I$5:I12,$C$5:C12,C12)/SUMIFS($D$5:D12,$C$5:C12,C12,$B$5:B12,"קנייה"),0),0) | K12: דוגמה — למחיקה
A13: 46156 | B13: דיבידנד | C13: AAPL | F13: 17 | G13: 0 | H13: =IF(B13="","",IF(B13="קנייה",-(D13*E13+G13),IF(B13="מכירה",D13*E13-G13,IF(B13="דיבידנד",F13-G13,IF(B13="הפקדה",F13-G13,IF(B13="משיכה",-F13-G13,-G13)))))) | I13: =IF(B13="קנייה",D13*E13+G13,0) | J13: =IF(B13="מכירה",D13*E13-G13-D13*IFERROR(SUMIFS($I$5:I13,$C$5:C13,C13)/SUMIFS($D$5:D13,$C$5:C13,C13,$B$5:B13,"קנייה"),0),0) | K13: דוגמה — למחיקה
A14: 46183 | B14: מכירה | C14: NVDA | D14: 40 | E14: 165 | G14: 2.5 | H14: =IF(B14="","",IF(B14="קנייה",-(D14*E14+G14),IF(B14="מכירה",D14*E14-G14,IF(B14="דיבידנד",F14-G14,IF(B14="הפקדה",F14-G14,IF(B14="משיכה",-F14-G14,-G14)))))) | I14: =IF(B14="קנייה",D14*E14+G14,0) | J14: =IF(B14="מכירה",D14*E14-G14-D14*IFERROR(SUMIFS($I$5:I14,$C$5:C14,C14)/SUMIFS($D$5:D14,$C$5:C14,C14,$B$5:B14,"קנייה"),0),0) | K14: דוגמה — למחיקה
A15: 46204 | B15: דיבידנד | C15: KO | F15: 65.03 | G15: 0 | H15: =IF(B15="","",IF(B15="קנייה",-(D15*E15+G15),IF(B15="מכירה",D15*E15-G15,IF(B15="דיבידנד",F15-G15,IF(B15="הפקדה",F15-G15,IF(B15="משיכה",-F15-G15,-G15)))))) | I15: =IF(B15="קנייה",D15*E15+G15,0) | J15: =IF(B15="מכירה",D15*E15-G15-D15*IFERROR(SUMIFS($I$5:I15,$C$5:C15,C15)/SUMIFS($D$5:D15,$C$5:C15,C15,$B$5:B15,"קנייה"),0),0) | K15: דוגמה — למחיקה
A16: 46205 | B16: הפקדה | F16: 10000 | G16: 0 | H16: =IF(B16="","",IF(B16="קנייה",-(D16*E16+G16),IF(B16="מכירה",D16*E16-G16,IF(B16="דיבידנד",F16-G16,IF(B16="הפקדה",F16-G16,IF(B16="משיכה",-F16-G16,-G16)))))) | I16: =IF(B16="קנייה",D16*E16+G16,0) | J16: =IF(B16="מכירה",D16*E16-G16-D16*IFERROR(SUMIFS($I$5:I16,$C$5:C16,C16)/SUMIFS($D$5:D16,$C$5:C16,C16,$B$5:B16,"קנייה"),0),0) | K16: דוגמה — למחיקה
A17: 46247 | B17: דיבידנד | C17: AAPL | F17: 17.6 | G17: 0 | H17: =IF(B17="","",IF(B17="קנייה",-(D17*E17+G17),IF(B17="מכירה",D17*E17-G17,IF(B17="דיבידנד",F17-G17,IF(B17="הפקדה",F17-G17,IF(B17="משיכה",-F17-G17,-G17)))))) | I17: =IF(B17="קנייה",D17*E17+G17,0) | J17: =IF(B17="מכירה",D17*E17-G17-D17*IFERROR(SUMIFS($I$5:I17,$C$5:C17,C17)/SUMIFS($D$5:D17,$C$5:C17,C17,$B$5:B17,"קנייה"),0),0) | K17: דוגמה — למחיקה
A18: 46276 | B18: דיבידנד | C18: MSFT | F18: 21 | G18: 0 | H18: =IF(B18="","",IF(B18="קנייה",-(D18*E18+G18),IF(B18="מכירה",D18*E18-G18,IF(B18="דיבידנד",F18-G18,IF(B18="הפקדה",F18-G18,IF(B18="משיכה",-F18-G18,-G18)))))) | I18: =IF(B18="קנייה",D18*E18+G18,0) | J18: =IF(B18="מכירה",D18*E18-G18-D18*IFERROR(SUMIFS($I$5:I18,$C$5:C18,C18)/SUMIFS($D$5:D18,$C$5:C18,C18,$B$5:B18,"קנייה"),0),0) | K18: דוגמה — למחיקה
H19: =IF(B19="","",IF(B19="קנייה",-(D19*E19+G19),IF(B19="מכירה",D19*E19-G19,IF(B19="דיבידנד",F19-G19,IF(B19="הפקדה",F19-G19,IF(B19="משיכה",-F19-G19,-G19)))))) | I19: =IF(B19="קנייה",D19*E19+G19,0) | J19: =IF(B19="מכירה",D19*E19-G19-D19*IFERROR(SUMIFS($I$5:I19,$C$5:C19,C19)/SUMIFS($D$5:D19,$C$5:C19,C19,$B$5:B19,"קנייה"),0),0)
H20: =IF(B20="","",IF(B20="קנייה",-(D20*E20+G20),IF(B20="מכירה",D20*E20-G20,IF(B20="דיבידנד",F20-G20,IF(B20="הפקדה",F20-G20,IF(B20="משיכה",-F20-G20,-G20)))))) | I20: =IF(B20="קנייה",D20*E20+G20,0) | J20: =IF(B20="מכירה",D20*E20-G20-D20*IFERROR(SUMIFS($I$5:I20,$C$5:C20,C20)/SUMIFS($D$5:D20,$C$5:C20,C20,$B$5:B20,"קנייה"),0),0)
H21: =IF(B21="","",IF(B21="קנייה",-(D21*E21+G21),IF(B21="מכירה",D21*E21-G21,IF(B21="דיבידנד",F21-G21,IF(B21="הפקדה",F21-G21,IF(B21="משיכה",-F21-G21,-G21)))))) | I21: =IF(B21="קנייה",D21*E21+G21,0) | J21: =IF(B21="מכירה",D21*E21-G21-D21*IFERROR(SUMIFS($I$5:I21,$C$5:C21,C21)/SUMIFS($D$5:D21,$C$5:C21,C21,$B$5:B21,"קנייה"),0),0)
H22: =IF(B22="","",IF(B22="קנייה",-(D22*E22+G22),IF(B22="מכירה",D22*E22-G22,IF(B22="דיבידנד",F22-G22,IF(B22="הפקדה",F22-G22,IF(B22="משיכה",-F22-G22,-G22)))))) | I22: =IF(B22="קנייה",D22*E22+G22,0) | J22: =IF(B22="מכירה",D22*E22-G22-D22*IFERROR(SUMIFS($I$5:I22,$C$5:C22,C22)/SUMIFS($D$5:D22,$C$5:C22,C22,$B$5:B22,"קנייה"),0),0)
H23: =IF(B23="","",IF(B23="קנייה",-(D23*E23+G23),IF(B23="מכירה",D23*E23-G23,IF(B23="דיבידנד",F23-G23,IF(B23="הפקדה",F23-G23,IF(B23="משיכה",-F23-G23,-G23)))))) | I23: =IF(B23="קנייה",D23*E23+G23,0) | J23: =IF(B23="מכירה",D23*E23-G23-D23*IFERROR(SUMIFS($I$5:I23,$C$5:C23,C23)/SUMIFS($D$5:D23,$C$5:C23,C23,$B$5:B23,"קנייה"),0),0)
H24: =IF(B24="","",IF(B24="קנייה",-(D24*E24+G24),IF(B24="מכירה",D24*E24-G24,IF(B24="דיבידנד",F24-G24,IF(B24="הפקדה",F24-G24,IF(B24="משיכה",-F24-G24,-G24)))))) | I24: =IF(B24="קנייה",D24*E24+G24,0) | J24: =IF(B24="מכירה",D24*E24-G24-D24*IFERROR(SUMIFS($I$5:I24,$C$5:C24,C24)/SUMIFS($D$5:D24,$C$5:C24,C24,$B$5:B24,"קנייה"),0),0)
H25: =IF(B25="","",IF(B25="קנייה",-(D25*E25+G25),IF(B25="מכירה",D25*E25-G25,IF(B25="דיבידנד",F25-G25,IF(B25="הפקדה",F25-G25,IF(B25="משיכה",-F25-G25,-G25)))))) | I25: =IF(B25="קנייה",D25*E25+G25,0) | J25: =IF(B25="מכירה",D25*E25-G25-D25*IFERROR(SUMIFS($I$5:I25,$C$5:C25,C25)/SUMIFS($D$5:D25,$C$5:C25,C25,$B$5:B25,"קנייה"),0),0)
H26: =IF(B26="","",IF(B26="קנייה",-(D26*E26+G26),IF(B26="מכירה",D26*E26-G26,IF(B26="דיבידנד",F26-G26,IF(B26="הפקדה",F26-G26,IF(B26="משיכה",-F26-G26,-G26)))))) | I26: =IF(B26="קנייה",D26*E26+G26,0) | J26: =IF(B26="מכירה",D26*E26-G26-D26*IFERROR(SUMIFS($I$5:I26,$C$5:C26,C26)/SUMIFS($D$5:D26,$C$5:C26,C26,$B$5:B26,"קנייה"),0),0)
H27: =IF(B27="","",IF(B27="קנייה",-(D27*E27+G27),IF(B27="מכירה",D27*E27-G27,IF(B27="דיבידנד",F27-G27,IF(B27="הפקדה",F27-G27,IF(B27="משיכה",-F27-G27,-G27)))))) | I27: =IF(B27="קנייה",D27*E27+G27,0) | J27: =IF(B27="מכירה",D27*E27-G27-D27*IFERROR(SUMIFS($I$5:I27,$C$5:C27,C27)/SUMIFS($D$5:D27,$C$5:C27,C27,$B$5:B27,"קנייה"),0),0)
H28: =IF(B28="","",IF(B28="קנייה",-(D28*E28+G28),IF(B28="מכירה",D28*E28-G28,IF(B28="דיבידנד",F28-G28,IF(B28="הפקדה",F28-G28,IF(B28="משיכה",-F28-G28,-G28)))))) | I28: =IF(B28="קנייה",D28*E28+G28,0) | J28: =IF(B28="מכירה",D28*E28-G28-D28*IFERROR(SUMIFS($I$5:I28,$C$5:C28,C28)/SUMIFS($D$5:D28,$C$5:C28,C28,$B$5:B28,"קנייה"),0),0)
H29: =IF(B29="","",IF(B29="קנייה",-(D29*E29+G29),IF(B29="מכירה",D29*E29-G29,IF(B29="דיבידנד",F29-G29,IF(B29="הפקדה",F29-G29,IF(B29="משיכה",-F29-G29,-G29)))))) | I29: =IF(B29="קנייה",D29*E29+G29,0) | J29: =IF(B29="מכירה",D29*E29-G29-D29*IFERROR(SUMIFS($I$5:I29,$C$5:C29,C29)/SUMIFS($D$5:D29,$C$5:C29,C29,$B$5:B29,"קנייה"),0),0)
H30: =IF(B30="","",IF(B30="קנייה",-(D30*E30+G30),IF(B30="מכירה",D30*E30-G30,IF(B30="דיבידנד",F30-G30,IF(B30="הפקדה",F30-G30,IF(B30="משיכה",-F30-G30,-G30)))))) | I30: =IF(B30="קנייה",D30*E30+G30,0) | J30: =IF(B30="מכירה",D30*E30-G30-D30*IFERROR(SUMIFS($I$5:I30,$C$5:C30,C30)/SUMIFS($D$5:D30,$C$5:C30,C30,$B$5:B30,"קנייה"),0),0)
... H1004: =IF(B1004="","",IF(B1004="קנייה",-(D1004*E1004+G1004),IF(B1004="מכירה",D1004*E1004-G1004,IF(B1004="דיבידנד",F1004-G1004,IF(B1004="הפקדה",F1004-G1004,IF(B1004="משיכה",-F1004-G1004,-G1004)))))) | I1004: =IF(B1004="קנייה",D1004*E1004+G1004,0) | J1004: =IF(B1004="מכירה",D1004*E1004-G1004-D1004*IFERROR(SUMIFS($I$5:I1004,$C$5:C1004,C1004)/SUMIFS($D$5:D1004,$C$5:C1004,C1004,$B$5:B1004,"קנייה"),0),0)

Sheet מעקב
A1: 👁️ רשימת מעקב ותכנון כניסות
A2: הגדר כניסה, סטופ ויעדים — המערכת מחשבת גודל פוזיציה לפי מדיניות הסיכון.
A4: טיקר | B4: שם | C4: סטאפ / סיבה | D4: מחיר ידני $ | E4: מחיר $ | F4: כניסה $ | G4: סטופ $ | H4: יעד 1 $ | I4: יעד 2 $ | J4: סיכון למניה $ | K4: סיכוי:סיכון (יעד 1) | L4: כמות מניות לפי סיכון | M4: גודל פוזיציה $ | N4: % מהתיק | O4: מרחק לכניסה | P4: רווח ביעד 1 $ | Q4: הפסד בסטופ $ | R4: סטטוס
A5: AMZN | B5: Amazon | C5: תיקון לממוצע 50 | D5: 228 | E5: =IF(A5="","",IFERROR(GOOGLEFINANCE(A5),D5)) | F5: 225 | G5: 214 | H5: 250 | I5: 270 | J5: =IF(OR(F5="",G5="",F5<=G5),"",F5-G5) | K5: =IF(OR(J5="",H5=""),"",(H5-F5)/J5) | L5: =IF(J5="","",MIN(ROUNDDOWN(Equity*RiskPct/J5,0),ROUNDDOWN(Equity*MaxPos/F5,0),ROUNDDOWN(MAX(0,Cash)/F5,0))) | M5: =IF(L5="","",L5*F5) | N5: =IF(OR(M5="",Equity=0),"",M5/Equity) | O5: =IF(OR(E5="",F5=""),"",E5/F5-1) | P5: =IF(OR(L5="",H5=""),"",L5*(H5-F5)) | Q5: =IF(L5="","",-L5*J5) | R5: =IF(OR(A5="",F5=""),"",IF(E5<=G5,"⛔ מתחת לסטופ",IF(E5<=F5*(1+EntryZone),IF(AND(K5<>"",K5<2),"🟡 באזור — R:R נמוך","🟢 באזור כניסה"),"⏳ ממתין")))
A6: GOOGL | B6: Alphabet | C6: פריצת שיא 20 יום | D6: 245 | E6: =IF(A6="","",IFERROR(GOOGLEFINANCE(A6),D6)) | F6: 240 | G6: 228 | H6: 270 | I6: 290 | J6: =IF(OR(F6="",G6="",F6<=G6),"",F6-G6) | K6: =IF(OR(J6="",H6=""),"",(H6-F6)/J6) | L6: =IF(J6="","",MIN(ROUNDDOWN(Equity*RiskPct/J6,0),ROUNDDOWN(Equity*MaxPos/F6,0),ROUNDDOWN(MAX(0,Cash)/F6,0))) | M6: =IF(L6="","",L6*F6) | N6: =IF(OR(M6="",Equity=0),"",M6/Equity) | O6: =IF(OR(E6="",F6=""),"",E6/F6-1) | P6: =IF(OR(L6="",H6=""),"",L6*(H6-F6)) | Q6: =IF(L6="","",-L6*J6) | R6: =IF(OR(A6="",F6=""),"",IF(E6<=G6,"⛔ מתחת לסטופ",IF(E6<=F6*(1+EntryZone),IF(AND(K6<>"",K6<2),"🟡 באזור — R:R נמוך","🟢 באזור כניסה"),"⏳ ממתין")))
E7: =IF(A7="","",IFERROR(GOOGLEFINANCE(A7),D7)) | J7: =IF(OR(F7="",G7="",F7<=G7),"",F7-G7) | K7: =IF(OR(J7="",H7=""),"",(H7-F7)/J7) | L7: =IF(J7="","",MIN(ROUNDDOWN(Equity*RiskPct/J7,0),ROUNDDOWN(Equity*MaxPos/F7,0),ROUNDDOWN(MAX(0,Cash)/F7,0))) | M7: =IF(L7="","",L7*F7) | N7: =IF(OR(M7="",Equity=0),"",M7/Equity) | O7: =IF(OR(E7="",F7=""),"",E7/F7-1) | P7: =IF(OR(L7="",H7=""),"",L7*(H7-F7)) | Q7: =IF(L7="","",-L7*J7) | R7: =IF(OR(A7="",F7=""),"",IF(E7<=G7,"⛔ מתחת לסטופ",IF(E7<=F7*(1+EntryZone),IF(AND(K7<>"",K7<2),"🟡 באזור — R:R נמוך","🟢 באזור כניסה"),"⏳ ממתין")))
E8: =IF(A8="","",IFERROR(GOOGLEFINANCE(A8),D8)) | J8: =IF(OR(F8="",G8="",F8<=G8),"",F8-G8) | K8: =IF(OR(J8="",H8=""),"",(H8-F8)/J8) | L8: =IF(J8="","",MIN(ROUNDDOWN(Equity*RiskPct/J8,0),ROUNDDOWN(Equity*MaxPos/F8,0),ROUNDDOWN(MAX(0,Cash)/F8,0))) | M8: =IF(L8="","",L8*F8) | N8: =IF(OR(M8="",Equity=0),"",M8/Equity) | O8: =IF(OR(E8="",F8=""),"",E8/F8-1) | P8: =IF(OR(L8="",H8=""),"",L8*(H8-F8)) | Q8: =IF(L8="","",-L8*J8) | R8: =IF(OR(A8="",F8=""),"",IF(E8<=G8,"⛔ מתחת לסטופ",IF(E8<=F8*(1+EntryZone),IF(AND(K8<>"",K8<2),"🟡 באזור — R:R נמוך","🟢 באזור כניסה"),"⏳ ממתין")))
E9: =IF(A9="","",IFERROR(GOOGLEFINANCE(A9),D9)) | J9: =IF(OR(F9="",G9="",F9<=G9),"",F9-G9) | K9: =IF(OR(J9="",H9=""),"",(H9-F9)/J9) | L9: =IF(J9="","",MIN(ROUNDDOWN(Equity*RiskPct/J9,0),ROUNDDOWN(Equity*MaxPos/F9,0),ROUNDDOWN(MAX(0,Cash)/F9,0))) | M9: =IF(L9="","",L9*F9) | N9: =IF(OR(M9="",Equity=0),"",M9/Equity) | O9: =IF(OR(E9="",F9=""),"",E9/F9-1) | P9: =IF(OR(L9="",H9=""),"",L9*(H9-F9)) | Q9: =IF(L9="","",-L9*J9) | R9: =IF(OR(A9="",F9=""),"",IF(E9<=G9,"⛔ מתחת לסטופ",IF(E9<=F9*(1+EntryZone),IF(AND(K9<>"",K9<2),"🟡 באזור — R:R נמוך","🟢 באזור כניסה"),"⏳ ממתין")))
E10: =IF(A10="","",IFERROR(GOOGLEFINANCE(A10),D10)) | J10: =IF(OR(F10="",G10="",F10<=G10),"",F10-G10) | K10: =IF(OR(J10="",H10=""),"",(H10-F10)/J10) | L10: =IF(J10="","",MIN(ROUNDDOWN(Equity*RiskPct/J10,0),ROUNDDOWN(Equity*MaxPos/F10,0),ROUNDDOWN(MAX(0,Cash)/F10,0))) | M10: =IF(L10="","",L10*F10) | N10: =IF(OR(M10="",Equity=0),"",M10/Equity) | O10: =IF(OR(E10="",F10=""),"",E10/F10-1) | P10: =IF(OR(L10="",H10=""),"",L10*(H10-F10)) | Q10: =IF(L10="","",-L10*J10) | R10: =IF(OR(A10="",F10=""),"",IF(E10<=G10,"⛔ מתחת לסטופ",IF(E10<=F10*(1+EntryZone),IF(AND(K10<>"",K10<2),"🟡 באזור — R:R נמוך","🟢 באזור כניסה"),"⏳ ממתין")))
E11: =IF(A11="","",IFERROR(GOOGLEFINANCE(A11),D11)) | J11: =IF(OR(F11="",G11="",F11<=G11),"",F11-G11) | K11: =IF(OR(J11="",H11=""),"",(H11-F11)/J11) | L11: =IF(J11="","",MIN(ROUNDDOWN(Equity*RiskPct/J11,0),ROUNDDOWN(Equity*MaxPos/F11,0),ROUNDDOWN(MAX(0,Cash)/F11,0))) | M11: =IF(L11="","",L11*F11) | N11: =IF(OR(M11="",Equity=0),"",M11/Equity) | O11: =IF(OR(E11="",F11=""),"",E11/F11-1) | P11: =IF(OR(L11="",H11=""),"",L11*(H11-F11)) | Q11: =IF(L11="","",-L11*J11) | R11: =IF(OR(A11="",F11=""),"",IF(E11<=G11,"⛔ מתחת לסטופ",IF(E11<=F11*(1+EntryZone),IF(AND(K11<>"",K11<2),"🟡 באזור — R:R נמוך","🟢 באזור כניסה"),"⏳ ממתין")))
E12: =IF(A12="","",IFERROR(GOOGLEFINANCE(A12),D12)) | J12: =IF(OR(F12="",G12="",F12<=G12),"",F12-G12) | K12: =IF(OR(J12="",H12=""),"",(H12-F12)/J12) | L12: =IF(J12="","",MIN(ROUNDDOWN(Equity*RiskPct/J12,0),ROUNDDOWN(Equity*MaxPos/F12,0),ROUNDDOWN(MAX(0,Cash)/F12,0))) | M12: =IF(L12="","",L12*F12) | N12: =IF(OR(M12="",Equity=0),"",M12/Equity) | O12: =IF(OR(E12="",F12=""),"",E12/F12-1) | P12: =IF(OR(L12="",H12=""),"",L12*(H12-F12)) | Q12: =IF(L12="","",-L12*J12) | R12: =IF(OR(A12="",F12=""),"",IF(E12<=G12,"⛔ מתחת לסטופ",IF(E12<=F12*(1+EntryZone),IF(AND(K12<>"",K12<2),"🟡 באזור — R:R נמוך","🟢 באזור כניסה"),"⏳ ממתין")))
E13: =IF(A13="","",IFERROR(GOOGLEFINANCE(A13),D13)) | J13: =IF(OR(F13="",G13="",F13<=G13),"",F13-G13) | K13: =IF(OR(J13="",H13=""),"",(H13-F13)/J13) | L13: =IF(J13="","",MIN(ROUNDDOWN(Equity*RiskPct/J13,0),ROUNDDOWN(Equity*MaxPos/F13,0),ROUNDDOWN(MAX(0,Cash)/F13,0))) | M13: =IF(L13="","",L13*F13) | N13: =IF(OR(M13="",Equity=0),"",M13/Equity) | O13: =IF(OR(E13="",F13=""),"",E13/F13-1) | P13: =IF(OR(L13="",H13=""),"",L13*(H13-F13)) | Q13: =IF(L13="","",-L13*J13) | R13: =IF(OR(A13="",F13=""),"",IF(E13<=G13,"⛔ מתחת לסטופ",IF(E13<=F13*(1+EntryZone),IF(AND(K13<>"",K13<2),"🟡 באזור — R:R נמוך","🟢 באזור כניסה"),"⏳ ממתין")))
E14: =IF(A14="","",IFERROR(GOOGLEFINANCE(A14),D14)) | J14: =IF(OR(F14="",G14="",F14<=G14),"",F14-G14) | K14: =IF(OR(J14="",H14=""),"",(H14-F14)/J14) | L14: =IF(J14="","",MIN(ROUNDDOWN(Equity*RiskPct/J14,0),ROUNDDOWN(Equity*MaxPos/F14,0),ROUNDDOWN(MAX(0,Cash)/F14,0))) | M14: =IF(L14="","",L14*F14) | N14: =IF(OR(M14="",Equity=0),"",M14/Equity) | O14: =IF(OR(E14="",F14=""),"",E14/F14-1) | P14: =IF(OR(L14="",H14=""),"",L14*(H14-F14)) | Q14: =IF(L14="","",-L14*J14) | R14: =IF(OR(A14="",F14=""),"",IF(E14<=G14,"⛔ מתחת לסטופ",IF(E14<=F14*(1+EntryZone),IF(AND(K14<>"",K14<2),"🟡 באזור — R:R נמוך","🟢 באזור כניסה"),"⏳ ממתין")))
E15: =IF(A15="","",IFERROR(GOOGLEFINANCE(A15),D15)) | J15: =IF(OR(F15="",G15="",F15<=G15),"",F15-G15) | K15: =IF(OR(J15="",H15=""),"",(H15-F15)/J15) | L15: =IF(J15="","",MIN(ROUNDDOWN(Equity*RiskPct/J15,0),ROUNDDOWN(Equity*MaxPos/F15,0),ROUNDDOWN(MAX(0,Cash)/F15,0))) | M15: =IF(L15="","",L15*F15) | N15: =IF(OR(M15="",Equity=0),"",M15/Equity) | O15: =IF(OR(E15="",F15=""),"",E15/F15-1) | P15: =IF(OR(L15="",H15=""),"",L15*(H15-F15)) | Q15: =IF(L15="","",-L15*J15) | R15: =IF(OR(A15="",F15=""),"",IF(E15<=G15,"⛔ מתחת לסטופ",IF(E15<=F15*(1+EntryZone),IF(AND(K15<>"",K15<2),"🟡 באזור — R:R נמוך","🟢 באזור כניסה"),"⏳ ממתין")))
E16: =IF(A16="","",IFERROR(GOOGLEFINANCE(A16),D16)) | J16: =IF(OR(F16="",G16="",F16<=G16),"",F16-G16) | K16: =IF(OR(J16="",H16=""),"",(H16-F16)/J16) | L16: =IF(J16="","",MIN(ROUNDDOWN(Equity*RiskPct/J16,0),ROUNDDOWN(Equity*MaxPos/F16,0),ROUNDDOWN(MAX(0,Cash)/F16,0))) | M16: =IF(L16="","",L16*F16) | N16: =IF(OR(M16="",Equity=0),"",M16/Equity) | O16: =IF(OR(E16="",F16=""),"",E16/F16-1) | P16: =IF(OR(L16="",H16=""),"",L16*(H16-F16)) | Q16: =IF(L16="","",-L16*J16) | R16: =IF(OR(A16="",F16=""),"",IF(E16<=G16,"⛔ מתחת לסטופ",IF(E16<=F16*(1+EntryZone),IF(AND(K16<>"",K16<2),"🟡 באזור — R:R נמוך","🟢 באזור כניסה"),"⏳ ממתין")))
E17: =IF(A17="","",IFERROR(GOOGLEFINANCE(A17),D17)) | J17: =IF(OR(F17="",G17="",F17<=G17),"",F17-G17) | K17: =IF(OR(J17="",H17=""),"",(H17-F17)/J17) | L17: =IF(J17="","",MIN(ROUNDDOWN(Equity*RiskPct/J17,0),ROUNDDOWN(Equity*MaxPos/F17,0),ROUNDDOWN(MAX(0,Cash)/F17,0))) | M17: =IF(L17="","",L17*F17) | N17: =IF(OR(M17="",Equity=0),"",M17/Equity) | O17: =IF(OR(E17="",F17=""),"",E17/F17-1) | P17: =IF(OR(L17="",H17=""),"",L17*(H17-F17)) | Q17: =IF(L17="","",-L17*J17) | R17: =IF(OR(A17="",F17=""),"",IF(E17<=G17,"⛔ מתחת לסטופ",IF(E17<=F17*(1+EntryZone),IF(AND(K17<>"",K17<2),"🟡 באזור — R:R נמוך","🟢 באזור כניסה"),"⏳ ממתין")))
E18: =IF(A18="","",IFERROR(GOOGLEFINANCE(A18),D18)) | J18: =IF(OR(F18="",G18="",F18<=G18),"",F18-G18) | K18: =IF(OR(J18="",H18=""),"",(H18-F18)/J18) | L18: =IF(J18="","",MIN(ROUNDDOWN(Equity*RiskPct/J18,0),ROUNDDOWN(Equity*MaxPos/F18,0),ROUNDDOWN(MAX(0,Cash)/F18,0))) | M18: =IF(L18="","",L18*F18) | N18: =IF(OR(M18="",Equity=0),"",M18/Equity) | O18: =IF(OR(E18="",F18=""),"",E18/F18-1) | P18: =IF(OR(L18="",H18=""),"",L18*(H18-F18)) | Q18: =IF(L18="","",-L18*J18) | R18: =IF(OR(A18="",F18=""),"",IF(E18<=G18,"⛔ מתחת לסטופ",IF(E18<=F18*(1+EntryZone),IF(AND(K18<>"",K18<2),"🟡 באזור — R:R נמוך","🟢 באזור כניסה"),"⏳ ממתין")))
... E44: =IF(A44="","",IFERROR(GOOGLEFINANCE(A44),D44)) | J44: =IF(OR(F44="",G44="",F44<=G44),"",F44-G44) | K44: =IF(OR(J44="",H44=""),"",(H44-F44)/J44) | L44: =IF(J44="","",MIN(ROUNDDOWN(Equity*RiskPct/J44,0),ROUNDDOWN(Equity*MaxPos/F44,0),ROUNDDOWN(MAX(0,Cash)/F44,0))) | M44: =IF(L44="","",L44*F44) | N44: =IF(OR(M44="",Equity=0),"",M44/Equity) | O44: =IF(OR(E44="",F44=""),"",E44/F44-1) | P44: =IF(OR(L44="",H44=""),"",L44*(H44-F44)) | Q44: =IF(L44="","",-L44*J44) | R44: =IF(OR(A44="",F44=""),"",IF(E44<=G44,"⛔ מתחת לסטופ",IF(E44<=F44*(1+EntryZone),IF(AND(K44<>"",K44<2),"🟡 באזור — R:R נמוך","🟢 באזור כניסה"),"⏳ ממתין")))

Sheet דיבידנדים
A1: 💰 לוח דיבידנדים
A2: דיבידנדים נטו שהתקבלו לפי מניה וחודש. שנה: ראה הגדרות.
A3: שנה: | B3: =DivYear
A4: טיקר | B4: ינו | C4: פבר | D4: מרץ | E4: אפר | F4: מאי | G4: יונ | H4: יול | I4: אוג | J4: ספט | K4: אוק | L4: נוב | M4: דצמ | N4: סה"כ שנה | O4: תשואה על עלות
A5: =IF('תיק'!A5="","",'תיק'!A5) | B5: =IF($A5="",0,SUMPRODUCT(('עסקאות'!$B$5:$B$1004="דיבידנד")*('עסקאות'!$C$5:$C$1004=$A5)*(YEAR('עסקאות'!$A$5:$A$1004)=DivYear)*(MONTH('עסקאות'!$A$5:$A$1004)=1)*'עסקאות'!$F$5:$F$1004)) | C5: =IF($A5="",0,SUMPRODUCT(('עסקאות'!$B$5:$B$1004="דיבידנד")*('עסקאות'!$C$5:$C$1004=$A5)*(YEAR('עסקאות'!$A$5:$A$1004)=DivYear)*(MONTH('עסקאות'!$A$5:$A$1004)=2)*'עסקאות'!$F$5:$F$1004)) | D5: =IF($A5="",0,SUMPRODUCT(('עסקאות'!$B$5:$B$1004="דיבידנד")*('עסקאות'!$C$5:$C$1004=$A5)*(YEAR('עסקאות'!$A$5:$A$1004)=DivYear)*(MONTH('עסקאות'!$A$5:$A$1004)=3)*'עסקאות'!$F$5:$F$1004)) | E5: =IF($A5="",0,SUMPRODUCT(('עסקאות'!$B$5:$B$1004="דיבידנד")*('עסקאות'!$C$5:$C$1004=$A5)*(YEAR('עסקאות'!$A$5:$A$1004)=DivYear)*(MONTH('עסקאות'!$A$5:$A$1004)=4)*'עסקאות'!$F$5:$F$1004)) | F5: =IF($A5="",0,SUMPRODUCT(('עסקאות'!$B$5:$B$1004="דיבידנד")*('עסקאות'!$C$5:$C$1004=$A5)*(YEAR('עסקאות'!$A$5:$A$1004)=DivYear)*(MONTH('עסקאות'!$A$5:$A$1004)=5)*'עסקאות'!$F$5:$F$1004)) | G5: =IF($A5="",0,SUMPRODUCT(('עסקאות'!$B$5:$B$1004="דיבידנד")*('עסקאות'!$C$5:$C$1004=$A5)*(YEAR('עסקאות'!$A$5:$A$1004)=DivYear)*(MONTH('עסקאות'!$A$5:$A$1004)=6)*'עסקאות'!$F$5:$F$1004)) | H5: =IF($A5="",0,SUMPRODUCT(('עסקאות'!$B$5:$B$1004="דיבידנד")*('עסקאות'!$C$5:$C$1004=$A5)*(YEAR('עסקאות'!$A$5:$A$1004)=DivYear)*(MONTH('עסקאות'!$A$5:$A$1004)=7)*'עסקאות'!$F$5:$F$1004)) | I5: =IF($A5="",0,SUMPRODUCT(('עסקאות'!$B$5:$B$1004="דיבידנד")*('עסקאות'!$C$5:$C$1004=$A5)*(YEAR('עסקאות'!$A$5:$A$1004)=DivYear)*(MONTH('עסקאות'!$A$5:$A$1004)=8)*'עסקאות'!$F$5:$F$1004)) | J5: =IF($A5="",0,SUMPRODUCT(('עסקאות'!$B$5:$B$1004="דיבידנד")*('עסקאות'!$C$5:$C$1004=$A5)*(YEAR('עסקאות'!$A$5:$A$1004)=DivYear)*(MONTH('עסקאות'!$A$5:$A$1004)=9)*'עסקאות'!$F$5:$F$1004)) | K5: =IF($A5="",0,SUMPRODUCT(('עסקאות'!$B$5:$B$1004="דיבידנד")*('עסקאות'!$C$5:$C$1004=$A5)*(YEAR('עסקאות'!$A$5:$A$1004)=DivYear)*(MONTH('עסקאות'!$A$5:$A$1004)=10)*'עסקאות'!$F$5:$F$1004)) | L5: =IF($A5="",0,SUMPRODUCT(('עסקאות'!$B$5:$B$1004="דיבידנד")*('עסקאות'!$C$5:$C$1004=$A5)*(YEAR('עסקאות'!$A$5:$A$1004)=DivYear)*(MONTH('עסקאות'!$A$5:$A$1004)=11)*'עסקאות'!$F$5:$F$1004)) | M5: =IF($A5="",0,SUMPRODUCT(('עסקאות'!$B$5:$B$1004="דיבידנד")*('עסקאות'!$C$5:$C$1004=$A5)*(YEAR('עסקאות'!$A$5:$A$1004)=DivYear)*(MONTH('עסקאות'!$A$5:$A$1004)=12)*'עסקאות'!$F$5:$F$1004)) | N5: =SUM(B5:M5) | O5: =IF(OR(A5="",'תיק'!I5=0),"",N5/'תיק'!I5)
A6: =IF('תיק'!A6="","",'תיק'!A6) | B6: =IF($A6="",0,SUMPRODUCT(('עסקאות'!$B$5:$B$1004="דיבידנד")*('עסקאות'!$C$5:$C$1004=$A6)*(YEAR('עסקאות'!$A$5:$A$1004)=DivYear)*(MONTH('עסקאות'!$A$5:$A$1004)=1)*'עסקאות'!$F$5:$F$1004)) | C6: =IF($A6="",0,SUMPRODUCT(('עסקאות'!$B$5:$B$1004="דיבידנד")*('עסקאות'!$C$5:$C$1004=$A6)*(YEAR('עסקאות'!$A$5:$A$1004)=DivYear)*(MONTH('עסקאות'!$A$5:$A$1004)=2)*'עסקאות'!$F$5:$F$1004)) | D6: =IF($A6="",0,SUMPRODUCT(('עסקאות'!$B$5:$B$1004="דיבידנד")*('עסקאות'!$C$5:$C$1004=$A6)*(YEAR('עסקאות'!$A$5:$A$1004)=DivYear)*(MONTH('עסקאות'!$A$5:$A$1004)=3)*'עסקאות'!$F$5:$F$1004)) | E6: =IF($A6="",0,SUMPRODUCT(('עסקאות'!$B$5:$B$1004="דיבידנד")*('עסקאות'!$C$5:$C$1004=$A6)*(YEAR('עסקאות'!$A$5:$A$1004)=DivYear)*(MONTH('עסקאות'!$A$5:$A$1004)=4)*'עסקאות'!$F$5:$F$1004)) | F6: =IF($A6="",0,SUMPRODUCT(('עסקאות'!$B$5:$B$1004="דיבידנד")*('עסקאות'!$C$5:$C$1004=$A6)*(YEAR('עסקאות'!$A$5:$A$1004)=DivYear)*(MONTH('עסקאות'!$A$5:$A$1004)=5)*'עסקאות'!$F$5:$F$1004)) | G6: =IF($A6="",0,SUMPRODUCT(('עסקאות'!$B$5:$B$1004="דיבידנד")*('עסקאות'!$C$5:$C$1004=$A6)*(YEAR('עסקאות'!$A$5:$A$1004)=DivYear)*(MONTH('עסקאות'!$A$5:$A$1004)=6)*'עסקאות'!$F$5:$F$1004)) | H6: =IF($A6="",0,SUMPRODUCT(('עסקאות'!$B$5:$B$1004="דיבידנד")*('עסקאות'!$C$5:$C$1004=$A6)*(YEAR('עסקאות'!$A$5:$A$1004)=DivYear)*(MONTH('עסקאות'!$A$5:$A$1004)=7)*'עסקאות'!$F$5:$F$1004)) | I6: =IF($A6="",0,SUMPRODUCT(('עסקאות'!$B$5:$B$1004="דיבידנד")*('עסקאות'!$C$5:$C$1004=$A6)*(YEAR('עסקאות'!$A$5:$A$1004)=DivYear)*(MONTH('עסקאות'!$A$5:$A$1004)=8)*'עסקאות'!$F$5:$F$1004)) | J6: =IF($A6="",0,SUMPRODUCT(('עסקאות'!$B$5:$B$1004="דיבידנד")*('עסקאות'!$C$5:$C$1004=$A6)*(YEAR('עסקאות'!$A$5:$A$1004)=DivYear)*(MONTH('עסקאות'!$A$5:$A$1004)=9)*'עסקאות'!$F$5:$F$1004)) | K6: =IF($A6="",0,SUMPRODUCT(('עסקאות'!$B$5:$B$1004="דיבידנד")*('עסקאות'!$C$5:$C$1004=$A6)*(YEAR('עסקאות'!$A$5:$A$1004)=DivYear)*(MONTH('עסקאות'!$A$5:$A$1004)=10)*'עסקאות'!$F$5:$F$1004)) | L6: =IF($A6="",0,SUMPRODUCT(('עסקאות'!$B$5:$B$1004="דיבידנד")*('עסקאות'!$C$5:$C$1004=$A6)*(YEAR('עסקאות'!$A$5:$A$1004)=DivYear)*(MONTH('עסקאות'!$A$5:$A$1004)=11)*'עסקאות'!$F$5:$F$1004)) | M6: =IF($A6="",0,SUMPRODUCT(('עסקאות'!$B$5:$B$1004="דיבידנד")*('עסקאות'!$C$5:$C$1004=$A6)*(YEAR('עסקאות'!$A$5:$A$1004)=DivYear)*(MONTH('עסקאות'!$A$5:$A$1004)=12)*'עסקאות'!$F$5:$F$1004)) | N6: =SUM(B6:M6) | O6: =IF(OR(A6="",'תיק'!I6=0),"",N6/'תיק'!I6)
A7: =IF('תיק'!A7="","",'תיק'!A7) | B7: =IF($A7="",0,SUMPRODUCT(('עסקאות'!$B$5:$B$1004="דיבידנד")*('עסקאות'!$C$5:$C$1004=$A7)*(YEAR('עסקאות'!$A$5:$A$1004)=DivYear)*(MONTH('עסקאות'!$A$5:$A$1004)=1)*'עסקאות'!$F$5:$F$1004)) | C7: =IF($A7="",0,SUMPRODUCT(('עסקאות'!$B$5:$B$1004="דיבידנד")*('עסקאות'!$C$5:$C$1004=$A7)*(YEAR('עסקאות'!$A$5:$A$1004)=DivYear)*(MONTH('עסקאות'!$A$5:$A$1004)=2)*'עסקאות'!$F$5:$F$1004)) | D7: =IF($A7="",0,SUMPRODUCT(('עסקאות'!$B$5:$B$1004="דיבידנד")*('עסקאות'!$C$5:$C$1004=$A7)*(YEAR('עסקאות'!$A$5:$A$1004)=DivYear)*(MONTH('עסקאות'!$A$5:$A$1004)=3)*'עסקאות'!$F$5:$F$1004)) | E7: =IF($A7="",0,SUMPRODUCT(('עסקאות'!$B$5:$B$1004="דיבידנד")*('עסקאות'!$C$5:$C$1004=$A7)*(YEAR('עסקאות'!$A$5:$A$1004)=DivYear)*(MONTH('עסקאות'!$A$5:$A$1004)=4)*'עסקאות'!$F$5:$F$1004)) | F7: =IF($A7="",0,SUMPRODUCT(('עסקאות'!$B$5:$B$1004="דיבידנד")*('עסקאות'!$C$5:$C$1004=$A7)*(YEAR('עסקאות'!$A$5:$A$1004)=DivYear)*(MONTH('עסקאות'!$A$5:$A$1004)=5)*'עסקאות'!$F$5:$F$1004)) | G7: =IF($A7="",0,SUMPRODUCT(('עסקאות'!$B$5:$B$1004="דיבידנד")*('עסקאות'!$C$5:$C$1004=$A7)*(YEAR('עסקאות'!$A$5:$A$1004)=DivYear)*(MONTH('עסקאות'!$A$5:$A$1004)=6)*'עסקאות'!$F$5:$F$1004)) | H7: =IF($A7="",0,SUMPRODUCT(('עסקאות'!$B$5:$B$1004="דיבידנד")*('עסקאות'!$C$5:$C$1004=$A7)*(YEAR('עסקאות'!$A$5:$A$1004)=DivYear)*(MONTH('עסקאות'!$A$5:$A$1004)=7)*'עסקאות'!$F$5:$F$1004)) | I7: =IF($A7="",0,SUMPRODUCT(('עסקאות'!$B$5:$B$1004="דיבידנד")*('עסקאות'!$C$5:$C$1004=$A7)*(YEAR('עסקאות'!$A$5:$A$1004)=DivYear)*(MONTH('עסקאות'!$A$5:$A$1004)=8)*'עסקאות'!$F$5:$F$1004)) | J7: =IF($A7="",0,SUMPRODUCT(('עסקאות'!$B$5:$B$1004="דיבידנד")*('עסקאות'!$C$5:$C$1004=$A7)*(YEAR('עסקאות'!$A$5:$A$1004)=DivYear)*(MONTH('עסקאות'!$A$5:$A$1004)=9)*'עסקאות'!$F$5:$F$1004)) | K7: =IF($A7="",0,SUMPRODUCT(('עסקאות'!$B$5:$B$1004="דיבידנד")*('עסקאות'!$C$5:$C$1004=$A7)*(YEAR('עסקאות'!$A$5:$A$1004)=DivYear)*(MONTH('עסקאות'!$A$5:$A$1004)=10)*'עסקאות'!$F$5:$F$1004)) | L7: =IF($A7="",0,SUMPRODUCT(('עסקאות'!$B$5:$B$1004="דיבידנד")*('עסקאות'!$C$5:$C$1004=$A7)*(YEAR('עסקאות'!$A$5:$A$1004)=DivYear)*(MONTH('עסקאות'!$A$5:$A$1004)=11)*'עסקאות'!$F$5:$F$1004)) | M7: =IF($A7="",0,SUMPRODUCT(('עסקאות'!$B$5:$B$1004="דיבידנד")*('עסקאות'!$C$5:$C$1004=$A7)*(YEAR('עסקאות'!$A$5:$A$1004)=DivYear)*(MONTH('עסקאות'!$A$5:$A$1004)=12)*'עסקאות'!$F$5:$F$1004)) | N7: =SUM(B7:M7) | O7: =IF(OR(A7="",'תיק'!I7=0),"",N7/'תיק'!I7)
