Workbook

Sheet הוראות
A1: 📖 תבנית ניהול תקציב שנתי – איך מתחילים?
A2: טבלת תקציב בעברית מלאה • עובדת ישירות ב-Google Sheets • בלי התקנות ובלי ניסיון קודם
B4: ⚙️ שלב 1 – הגדרות | C4: בלשונית 'הגדרות' בחרו את שנת התקציב, ורשמו את הקטגוריות שלכם בכל אחד מ-5 הסוגים: הכנסות, תוכניות חיסכון, חשבונות ומנויים, הוצאות משתנות וחובות. לכל קטגוריה הזינו סכום ותדירות – חודשי, דו-שבועי, שבועי, דו-חודשי או שנתי – והתקציב החודשי יחושב אוטומטית.
B5: 📝 שלב 2 – יומן תנועות | C5: בכל פעם שנכנס או יוצא כסף, הוסיפו שורה בלשונית 'תנועות': תאריך, קטגוריה מהרשימה, תיאור (לא חובה) וסכום חיובי. הסוג והחודש מתמלאים לבד. זה המקום היחיד שבו מזינים נתונים שוטפים.
B6: 🗓️ שלב 3 – לשוניות החודשים | C6: 12 לשוניות (ינואר–דצמבר) מציגות לכל חודש: כרטיסי סיכום, תקציב מול בפועל לכל קטגוריה, מעקב שבועי להוצאות המשתנות וגרפים. רוצים תקציב שונה לחודש מסוים? פשוט הקלידו סכום בעמודת 'תקציב' באותו חודש.
B7: 📊 שלב 4 – לוח שנתי | C7: תמונה מלאה של כל השנה: הכנסות מול יציאות לפי חודש, תקציב שנתי מול בפועל, פירוט לכל קטגוריה וגרפים שמראים בדיוק לאן הכסף הולך.
B8: 🐷 שלב 5 – חיסכון | C8: הזינו לכל תוכנית יעד, יתרת פתיחה ותאריך יעד. ההפקדות נמשכות מהתנועות, ותראו כמה כבר נחסך, כמה נשאר וכמה צריך להפקיד כל חודש.
B9: 💳 שלב 6 – חובות | C9: הזינו סכום מקורי, יתרה בתחילת השנה וריבית. ההחזרים נמשכים מהתנועות, ותראו כמה נפרע, כמה נשאר ומתי תהיו חופשיים מחובות.
B11: 🎨 מקרא צבעים
C12: תא צהוב = תא למילוי (כל השאר מחושב אוטומטית – לא לגעת)
C13: הכנסות
C14: תוכניות חיסכון
C15: חשבונות ומנויים
C16: הוצאות משתנות
C17: חובות
C18: אדום = חריגה מהתקציב
B20: ⚠️ חשוב לדעת
B21: • שמות הקטגוריות בהגדרות צריכים להיות ייחודיים. שינוי שם בהגדרות מעדכן את כל הלשוניות; תנועות ישנות עם השם הקודם לא ייספרו.
B22: • שמות תוכניות החיסכון והחובות נלקחים מההגדרות – הפקדה לחיסכון או החזר חוב פשוט נרשמים כתנועה עם אותה קטגוריה.
B23: • הסכומים תמיד חיוביים – הסוג (הכנסה / הוצאה) נקבע לפי הקטגוריה.
B24: • לשנה חדשה: שכפלו את הקובץ, שנו את השנה בהגדרות ומחקו את התנועות.

Sheet לוח שנתי
A1: ="📊 לוח שנתי – סיכום "&הגדרות!$C$3 -> 📊 לוח שנתי – סיכום 2026
A2: סקירה מלאה של ההכנסות וההוצאות לאורך כל השנה • מתעדכן אוטומטית
A4: 💵 הכנסות השנה | C4: 💸 יציאות השנה | E4: 🏦 נשאר בעו"ש | G4: 🐷 שיעור חיסכון
A5: =B20 -> 0 | C5: =G20 -> 0 | E5: =H20 -> 0 | G5: =IF(B20=0,"–",C20/B20) -> –
A7: חודש | B7: הכנסות | C7: תוכניות חיסכון | D7: חשבונות ומנויים | E7: הוצאות משתנות | F7: חובות | G7: סה"כ יציאות | H7: נשאר בעו"ש
A8: ינואר | B8: =ינואר!$C$8 -> 0 | C8: =ינואר!$C$9 -> 0 | D8: =ינואר!$C$10 -> 0 | E8: =ינואר!$C$11 -> 0 | F8: =ינואר!$C$12 -> 0 | G8: =SUM(C8:F8) -> 0 | H8: =B8-G8 -> 0
A9: פברואר | B9: =פברואר!$C$8 -> 0 | C9: =פברואר!$C$9 -> 0 | D9: =פברואר!$C$10 -> 0 | E9: =פברואר!$C$11 -> 0 | F9: =פברואר!$C$12 -> 0 | G9: =SUM(C9:F9) -> 0 | H9: =B9-G9 -> 0
A10: מרץ | B10: =מרץ!$C$8 -> 0 | C10: =מרץ!$C$9 -> 0 | D10: =מרץ!$C$10 -> 0 | E10: =מרץ!$C$11 -> 0 | F10: =מרץ!$C$12 -> 0 | G10: =SUM(C10:F10) -> 0 | H10: =B10-G10 -> 0
A11: אפריל | B11: =אפריל!$C$8 -> 0 | C11: =אפריל!$C$9 -> 0 | D11: =אפריל!$C$10 -> 0 | E11: =אפריל!$C$11 -> 0 | F11: =אפריל!$C$12 -> 0 | G11: =SUM(C11:F11) -> 0 | H11: =B11-G11 -> 0
A12: מאי | B12: =מאי!$C$8 -> 0 | C12: =מאי!$C$9 -> 0 | D12: =מאי!$C$10 -> 0 | E12: =מאי!$C$11 -> 0 | F12: =מאי!$C$12 -> 0 | G12: =SUM(C12:F12) -> 0 | H12: =B12-G12 -> 0
A13: יוני | B13: =יוני!$C$8 -> 0 | C13: =יוני!$C$9 -> 0 | D13: =יוני!$C$10 -> 0 | E13: =יוני!$C$11 -> 0 | F13: =יוני!$C$12 -> 0 | G13: =SUM(C13:F13) -> 0 | H13: =B13-G13 -> 0
A14: יולי | B14: =יולי!$C$8 -> 0 | C14: =יולי!$C$9 -> 0 | D14: =יולי!$C$10 -> 0 | E14: =יולי!$C$11 -> 0 | F14: =יולי!$C$12 -> 0 | G14: =SUM(C14:F14) -> 0 | H14: =B14-G14 -> 0
A15: אוגוסט | B15: =אוגוסט!$C$8 -> 0 | C15: =אוגוסט!$C$9 -> 0 | D15: =אוגוסט!$C$10 -> 0 | E15: =אוגוסט!$C$11 -> 0 | F15: =אוגוסט!$C$12 -> 0 | G15: =SUM(C15:F15) -> 0 | H15: =B15-G15 -> 0
A16: ספטמבר | B16: =ספטמבר!$C$8 -> 0 | C16: =ספטמבר!$C$9 -> 0 | D16: =ספטמבר!$C$10 -> 0 | E16: =ספטמבר!$C$11 -> 0 | F16: =ספטמבר!$C$12 -> 0 | G16: =SUM(C16:F16) -> 0 | H16: =B16-G16 -> 0
A17: אוקטובר | B17: =אוקטובר!$C$8 -> 0 | C17: =אוקטובר!$C$9 -> 0 | D17: =אוקטובר!$C$10 -> 0 | E17: =אוקטובר!$C$11 -> 0 | F17: =אוקטובר!$C$12 -> 0 | G17: =SUM(C17:F17) -> 0 | H17: =B17-G17 -> 0
A18: נובמבר | B18: =נובמבר!$C$8 -> 0 | C18: =נובמבר!$C$9 -> 0 | D18: =נובמבר!$C$10 -> 0 | E18: =נובמבר!$C$11 -> 0 | F18: =נובמבר!$C$12 -> 0 | G18: =SUM(C18:F18) -> 0 | H18: =B18-G18 -> 0
A19: דצמבר | B19: =דצמבר!$C$8 -> 0 | C19: =דצמבר!$C$9 -> 0 | D19: =דצמבר!$C$10 -> 0 | E19: =דצמבר!$C$11 -> 0 | F19: =דצמבר!$C$12 -> 0 | G19: =SUM(C19:F19) -> 0 | H19: =B19-G19 -> 0
A20: סה"כ בפועל | B20: =SUM(B8:B19) -> 0 | C20: =SUM(C8:C19) -> 0 | D20: =SUM(D8:D19) -> 0 | E20: =SUM(E8:E19) -> 0 | F20: =SUM(F8:F19) -> 0 | G20: =SUM(G8:G19) -> 0 | H20: =SUM(H8:H19) -> 0
A21: תקציב שנתי | B21: =ינואר!$B$8+פברואר!$B$8+מרץ!$B$8+אפריל!$B$8+מאי!$B$8+יוני!$B$8+יולי!$B$8+אוגוסט!$B$8+ספטמבר!$B$8+אוקטובר!$B$8+נובמבר!$B$8+דצמבר!$B$8 -> 303840 | C21: =ינואר!$B$9+פברואר!$B$9+מרץ!$B$9+אפריל!$B$9+מאי!$B$9+יוני!$B$9+יולי!$B$9+אוגוסט!$B$9+ספטמבר!$B$9+אוקטובר!$B$9+נובמבר!$B$9+דצמבר!$B$9 -> 64800 | D21: =ינואר!$B$10+פברואר!$B$10+מרץ!$B$10+אפריל!$B$10+מאי!$B$10+יוני!$B$10+יולי!$B$10+אוגוסט!$B$10+ספטמבר!$B$10+אוקטובר!$B$10+נובמבר!$B$10+דצמבר!$B$10 -> 95100 | E21: =ינואר!$B$11+פברואר!$B$11+מרץ!$B$11+אפריל!$B$11+מאי!$B$11+יוני!$B$11+יולי!$B$11+אוגוסט!$B$11+ספטמבר!$B$11+אוקטובר!$B$11+נובמבר!$B$11+דצמבר!$B$11 -> 88800 | F21: =ינואר!$B$12+פברואר!$B$12+מרץ!$B$12+אפריל!$B$12+מאי!$B$12+יוני!$B$12+יולי!$B$12+אוגוסט!$B$12+ספטמבר!$B$12+אוקטובר!$B$12+נובמבר!$B$12+דצמבר!$B$12 -> 27600 | G21: =SUM(C21:F21) -> 276300 | H21: =B21-G21 -> 27540
A22: ממוצע חודשי | B22: =B20/12 -> 0 | C22: =C20/12 -> 0 | D22: =D20/12 -> 0 | E22: =E20/12 -> 0 | F22: =F20/12 -> 0 | G22: =G20/12 -> 0 | H22: =H20/12 -> 0
A25: 📋 פירוט שנתי לפי קטגוריה
A26: קטגוריה | B26: סוג | C26: תקציב שנתי | D26: בפועל | E26: הפרש | F26: % ניצול
A27: =IF(הגדרות!$B$8="","",הגדרות!$B$8) -> משכורת 1 | B27: =IF(A27="","","הכנסות") -> הכנסות | C27: =IF(A27="","",N(ינואר!B26)+N(פברואר!B26)+N(מרץ!B26)+N(אפריל!B26)+N(מאי!B26)+N(יוני!B26)+N(יולי!B26)+N(אוגוסט!B26)+N(ספטמבר!B26)+N(אוקטובר!B26)+N(נובמבר!B26)+N(דצמבר!B26)) -> 168000 | D27: =IF(A27="","",SUMIFS(תנועות!$E$6:$E$2005,תנועות!$B$6:$B$2005,A27,תנועות!$A$6:$A$2005,">="&DATE(הגדרות!$C$3,1,1),תנועות!$A$6:$A$2005,"<"&DATE(הגדרות!$C$3+1,1,1))) -> 0 | E27: =IF(A27="","",D27-C27) -> -168000 | F27: =IF(OR(A27="",N(C27)=0),"",D27/C27) -> 0
A28: =IF(הגדרות!$B$9="","",הגדרות!$B$9) -> משכורת 2 | B28: =IF(A28="","","הכנסות") -> הכנסות | C28: =IF(A28="","",N(ינואר!B27)+N(פברואר!B27)+N(מרץ!B27)+N(אפריל!B27)+N(מאי!B27)+N(יוני!B27)+N(יולי!B27)+N(אוגוסט!B27)+N(ספטמבר!B27)+N(אוקטובר!B27)+N(נובמבר!B27)+N(דצמבר!B27)) -> 114000 | D28: =IF(A28="","",SUMIFS(תנועות!$E$6:$E$2005,תנועות!$B$6:$B$2005,A28,תנועות!$A$6:$A$2005,">="&DATE(הגדרות!$C$3,1,1),תנועות!$A$6:$A$2005,"<"&DATE(הגדרות!$C$3+1,1,1))) -> 0 | E28: =IF(A28="","",D28-C28) -> -114000 | F28: =IF(OR(A28="",N(C28)=0),"",D28/C28) -> 0
A29: =IF(הגדרות!$B$10="","",הגדרות!$B$10) -> עבודה נוספת | B29: =IF(A29="","","הכנסות") -> הכנסות | C29: =IF(A29="","",N(ינואר!B28)+N(פברואר!B28)+N(מרץ!B28)+N(אפריל!B28)+N(מאי!B28)+N(יוני!B28)+N(יולי!B28)+N(אוגוסט!B28)+N(ספטמבר!B28)+N(אוקטובר!B28)+N(נובמבר!B28)+N(דצמבר!B28)) -> 18000 | D29: =IF(A29="","",SUMIFS(תנועות!$E$6:$E$2005,תנועות!$B$6:$B$2005,A29,תנועות!$A$6:$A$2005,">="&DATE(הגדרות!$C$3,1,1),תנועות!$A$6:$A$2005,"<"&DATE(הגדרות!$C$3+1,1,1))) -> 0 | E29: =IF(A29="","",D29-C29) -> -18000 | F29: =IF(OR(A29="",N(C29)=0),"",D29/C29) -> 0
A30: =IF(הגדרות!$B$11="","",הגדרות!$B$11) -> קצבת ילדים | B30: =IF(A30="","","הכנסות") -> הכנסות | C30: =IF(A30="","",N(ינואר!B29)+N(פברואר!B29)+N(מרץ!B29)+N(אפריל!B29)+N(מאי!B29)+N(יוני!B29)+N(יולי!B29)+N(אוגוסט!B29)+N(ספטמבר!B29)+N(אוקטובר!B29)+N(נובמבר!B29)+N(דצמבר!B29)) -> 3840 | D30: =IF(A30="","",SUMIFS(תנועות!$E$6:$E$2005,תנועות!$B$6:$B$2005,A30,תנועות!$A$6:$A$2005,">="&DATE(הגדרות!$C$3,1,1),תנועות!$A$6:$A$2005,"<"&DATE(הגדרות!$C$3+1,1,1))) -> 0 | E30: =IF(A30="","",D30-C30) -> -3840 | F30: =IF(OR(A30="",N(C30)=0),"",D30/C30) -> 0
A31: =IF(הגדרות!$B$12="","",הגדרות!$B$12) -> החזרים והכנסות אחרות | B31: =IF(A31="","","הכנסות") -> הכנסות | C31: =IF(A31="","",N(ינואר!B30)+N(פברואר!B30)+N(מרץ!B30)+N(אפריל!B30)+N(מאי!B30)+N(יוני!B30)+N(יולי!B30)+N(אוגוסט!B30)+N(ספטמבר!B30)+N(אוקטובר!B30)+N(נובמבר!B30)+N(דצמבר!B30)) -> 0 | D31: =IF(A31="","",SUMIFS(תנועות!$E$6:$E$2005,תנועות!$B$6:$B$2005,A31,תנועות!$A$6:$A$2005,">="&DATE(הגדרות!$C$3,1,1),תנועות!$A$6:$A$2005,"<"&DATE(הגדרות!$C$3+1,1,1))) -> 0 | E31: =IF(A31="","",D31-C31) -> 0 | F31: =IF(OR(A31="",N(C31)=0),"",D31/C31)
A32: =IF(הגדרות!$B$13="","",הגדרות!$B$13) | B32: =IF(A32="","","הכנסות") | C32: =IF(A32="","",N(ינואר!B31)+N(פברואר!B31)+N(מרץ!B31)+N(אפריל!B31)+N(מאי!B31)+N(יוני!B31)+N(יולי!B31)+N(אוגוסט!B31)+N(ספטמבר!B31)+N(אוקטובר!B31)+N(נובמבר!B31)+N(דצמבר!B31)) | D32: =IF(A32="","",SUMIFS(תנועות!$E$6:$E$2005,תנועות!$B$6:$B$2005,A32,תנועות!$A$6:$A$2005,">="&DATE(הגדרות!$C$3,1,1),תנועות!$A$6:$A$2005,"<"&DATE(הגדרות!$C$3+1,1,1))) | E32: =IF(A32="","",D32-C32) | F32: =IF(OR(A32="",N(C32)=0),"",D32/C32)
A33: =IF(הגדרות!$B$14="","",הגדרות!$B$14) | B33: =IF(A33="","","הכנסות") | C33: =IF(A33="","",N(ינואר!B32)+N(פברואר!B32)+N(מרץ!B32)+N(אפריל!B32)+N(מאי!B32)+N(יוני!B32)+N(יולי!B32)+N(אוגוסט!B32)+N(ספטמבר!B32)+N(אוקטובר!B32)+N(נובמבר!B32)+N(דצמבר!B32)) | D33: =IF(A33="","",SUMIFS(תנועות!$E$6:$E$2005,תנועות!$B$6:$B$2005,A33,תנועות!$A$6:$A$2005,">="&DATE(הגדרות!$C$3,1,1),תנועות!$A$6:$A$2005,"<"&DATE(הגדרות!$C$3+1,1,1))) | E33: =IF(A33="","",D33-C33) | F33: =IF(OR(A33="",N(C33)=0),"",D33/C33)
A34: =IF(הגדרות!$B$15="","",הגדרות!$B$15) | B34: =IF(A34="","","הכנסות") | C34: =IF(A34="","",N(ינואר!B33)+N(פברואר!B33)+N(מרץ!B33)+N(אפריל!B33)+N(מאי!B33)+N(יוני!B33)+N(יולי!B33)+N(אוגוסט!B33)+N(ספטמבר!B33)+N(אוקטובר!B33)+N(נובמבר!B33)+N(דצמבר!B33)) | D34: =IF(A34="","",SUMIFS(תנועות!$E$6:$E$2005,תנועות!$B$6:$B$2005,A34,תנועות!$A$6:$A$2005,">="&DATE(הגדרות!$C$3,1,1),תנועות!$A$6:$A$2005,"<"&DATE(הגדרות!$C$3+1,1,1))) | E34: =IF(A34="","",D34-C34) | F34: =IF(OR(A34="",N(C34)=0),"",D34/C34)
A35: =IF(הגדרות!$B$16="","",הגדרות!$B$16) -> קרן חירום | B35: =IF(A35="","","תוכניות חיסכון") -> תוכניות חיסכון | C35: =IF(A35="","",N(ינואר!G26)+N(פברואר!G26)+N(מרץ!G26)+N(אפריל!G26)+N(מאי!G26)+N(יוני!G26)+N(יולי!G26)+N(אוגוסט!G26)+N(ספטמבר!G26)+N(אוקטובר!G26)+N(נובמבר!G26)+N(דצמבר!G26)) -> 18000 | D35: =IF(A35="","",SUMIFS(תנועות!$E$6:$E$2005,תנועות!$B$6:$B$2005,A35,תנועות!$A$6:$A$2005,">="&DATE(הגדרות!$C$3,1,1),תנועות!$A$6:$A$2005,"<"&DATE(הגדרות!$C$3+1,1,1))) -> 0 | E35: =IF(A35="","",C35-D35) -> 18000 | F35: =IF(OR(A35="",N(C35)=0),"",D35/C35) -> 0
A36: =IF(הגדרות!$B$17="","",הגדרות!$B$17) -> חופשה משפחתית | B36: =IF(A36="","","תוכניות חיסכון") -> תוכניות חיסכון | C36: =IF(A36="","",N(ינואר!G27)+N(פברואר!G27)+N(מרץ!G27)+N(אפריל!G27)+N(מאי!G27)+N(יוני!G27)+N(יולי!G27)+N(אוגוסט!G27)+N(ספטמבר!G27)+N(אוקטובר!G27)+N(נובמבר!G27)+N(דצמבר!G27)) -> 7200 | D36: =IF(A36="","",SUMIFS(תנועות!$E$6:$E$2005,תנועות!$B$6:$B$2005,A36,תנועות!$A$6:$A$2005,">="&DATE(הגדרות!$C$3,1,1),תנועות!$A$6:$A$2005,"<"&DATE(הגדרות!$C$3+1,1,1))) -> 0 | E36: =IF(A36="","",C36-D36) -> 7200 | F36: =IF(OR(A36="",N(C36)=0),"",D36/C36) -> 0
A37: =IF(הגדרות!$B$18="","",הגדרות!$B$18) -> רכב חדש | B37: =IF(A37="","","תוכניות חיסכון") -> תוכניות חיסכון | C37: =IF(A37="","",N(ינואר!G28)+N(פברואר!G28)+N(מרץ!G28)+N(אפריל!G28)+N(מאי!G28)+N(יוני!G28)+N(יולי!G28)+N(אוגוסט!G28)+N(ספטמבר!G28)+N(אוקטובר!G28)+N(נובמבר!G28)+N(דצמבר!G28)) -> 9600 | D37: =IF(A37="","",SUMIFS(תנועות!$E$6:$E$2005,תנועות!$B$6:$B$2005,A37,תנועות!$A$6:$A$2005,">="&DATE(הגדרות!$C$3,1,1),תנועות!$A$6:$A$2005,"<"&DATE(הגדרות!$C$3+1,1,1))) -> 0 | E37: =IF(A37="","",C37-D37) -> 9600 | F37: =IF(OR(A37="",N(C37)=0),"",D37/C37) -> 0
A38: =IF(הגדרות!$B$19="","",הגדרות!$B$19) -> דירה | B38: =IF(A38="","","תוכניות חיסכון") -> תוכניות חיסכון | C38: =IF(A38="","",N(ינואר!G29)+N(פברואר!G29)+N(מרץ!G29)+N(אפריל!G29)+N(מאי!G29)+N(יוני!G29)+N(יולי!G29)+N(אוגוסט!G29)+N(ספטמבר!G29)+N(אוקטובר!G29)+N(נובמבר!G29)+N(דצמבר!G29)) -> 18000 | D38: =IF(A38="","",SUMIFS(תנועות!$E$6:$E$2005,תנועות!$B$6:$B$2005,A38,תנועות!$A$6:$A$2005,">="&DATE(הגדרות!$C$3,1,1),תנועות!$A$6:$A$2005,"<"&DATE(הגדרות!$C$3+1,1,1))) -> 0 | E38: =IF(A38="","",C38-D38) -> 18000 | F38: =IF(OR(A38="",N(C38)=0),"",D38/C38) -> 0
A39: =IF(הגדרות!$B$20="","",הגדרות!$B$20) -> השקעות | B39: =IF(A39="","","תוכניות חיסכון") -> תוכניות חיסכון | C39: =IF(A39="","",N(ינואר!G30)+N(פברואר!G30)+N(מרץ!G30)+N(אפריל!G30)+N(מאי!G30)+N(יוני!G30)+N(יולי!G30)+N(אוגוסט!G30)+N(ספטמבר!G30)+N(אוקטובר!G30)+N(נובמבר!G30)+N(דצמבר!G30)) -> 12000 | D39: =IF(A39="","",SUMIFS(תנועות!$E$6:$E$2005,תנועות!$B$6:$B$2005,A39,תנועות!$A$6:$A$2005,">="&DATE(הגדרות!$C$3,1,1),תנועות!$A$6:$A$2005,"<"&DATE(הגדרות!$C$3+1,1,1))) -> 0 | E39: =IF(A39="","",C39-D39) -> 12000 | F39: =IF(OR(A39="",N(C39)=0),"",D39/C39) -> 0
A40: =IF(הגדרות!$B$21="","",הגדרות!$B$21) -> שכר דירה / משכנתא | B40: =IF(A40="","","חשבונות ומנויים") -> חשבונות ומנויים | C40: =IF(A40="","",N(ינואר!L26)+N(פברואר!L26)+N(מרץ!L26)+N(אפריל!L26)+N(מאי!L26)+N(יוני!L26)+N(יולי!L26)+N(אוגוסט!L26)+N(ספטמבר!L26)+N(אוקטובר!L26)+N(נובמבר!L26)+N(דצמבר!L26)) -> 62400 | D40: =IF(A40="","",SUMIFS(תנועות!$E$6:$E$2005,תנועות!$B$6:$B$2005,A40,תנועות!$A$6:$A$2005,">="&DATE(הגדרות!$C$3,1,1),תנועות!$A$6:$A$2005,"<"&DATE(הגדרות!$C$3+1,1,1))) -> 0 | E40: =IF(A40="","",C40-D40) -> 62400 | F40: =IF(OR(A40="",N(C40)=0),"",D40/C40) -> 0
A41: =IF(הגדרות!$B$22="","",הגדרות!$B$22) -> ארנונה | B41: =IF(A41="","","חשבונות ומנויים") -> חשבונות ומנויים | C41: =IF(A41="","",N(ינואר!L27)+N(פברואר!L27)+N(מרץ!L27)+N(אפריל!L27)+N(מאי!L27)+N(יוני!L27)+N(יולי!L27)+N(אוגוסט!L27)+N(ספטמבר!L27)+N(אוקטובר!L27)+N(נובמבר!L27)+N(דצמבר!L27)) -> 5400 | D41: =IF(A41="","",SUMIFS(תנועות!$E$6:$E$2005,תנועות!$B$6:$B$2005,A41,תנועות!$A$6:$A$2005,">="&DATE(הגדרות!$C$3,1,1),תנועות!$A$6:$A$2005,"<"&DATE(הגדרות!$C$3+1,1,1))) -> 0 | E41: =IF(A41="","",C41-D41) -> 5400 | F41: =IF(OR(A41="",N(C41)=0),"",D41/C41) -> 0
A42: =IF(הגדרות!$B$23="","",הגדרות!$B$23) -> חשמל | B42: =IF(A42="","","חשבונות ומנויים") -> חשבונות ומנויים | C42: =IF(A42="","",N(ינואר!L28)+N(פברואר!L28)+N(מרץ!L28)+N(אפריל!L28)+N(מאי!L28)+N(יוני!L28)+N(יולי!L28)+N(אוגוסט!L28)+N(ספטמבר!L28)+N(אוקטובר!L28)+N(נובמבר!L28)+N(דצמבר!L28)) -> 4200 | D42: =IF(A42="","",SUMIFS(תנועות!$E$6:$E$2005,תנועות!$B$6:$B$2005,A42,תנועות!$A$6:$A$2005,">="&DATE(הגדרות!$C$3,1,1),תנועות!$A$6:$A$2005,"<"&DATE(הגדרות!$C$3+1,1,1))) -> 0 | E42: =IF(A42="","",C42-D42) -> 4200 | F42: =IF(OR(A42="",N(C42)=0),"",D42/C42) -> 0
A43: =IF(הגדרות!$B$24="","",הגדרות!$B$24) -> מים | B43: =IF(A43="","","חשבונות ומנויים") -> חשבונות ומנויים | C43: =IF(A43="","",N(ינואר!L29)+N(פברואר!L29)+N(מרץ!L29)+N(אפריל!L29)+N(מאי!L29)+N(יוני!L29)+N(יולי!L29)+N(אוגוסט!L29)+N(ספטמבר!L29)+N(אוקטובר!L29)+N(נובמבר!L29)+N(דצמבר!L29)) -> 1500 | D43: =IF(A43="","",SUMIFS(תנועות!$E$6:$E$2005,תנועות!$B$6:$B$2005,A43,תנועות!$A$6:$A$2005,">="&DATE(הגדרות!$C$3,1,1),תנועות!$A$6:$A$2005,"<"&DATE(הגדרות!$C$3+1,1,1))) -> 0 | E43: =IF(A43="","",C43-D43) -> 1500 | F43: =IF(OR(A43="",N(C43)=0),"",D43/C43) -> 0
A44: =IF(הגדרות!$B$25="","",הגדרות!$B$25) -> גז | B44: =IF(A44="","","חשבונות ומנויים") -> חשבונות ומנויים | C44: =IF(A44="","",N(ינואר!L30)+N(פברואר!L30)+N(מרץ!L30)+N(אפריל!L30)+N(מאי!L30)+N(יוני!L30)+N(יולי!L30)+N(אוגוסט!L30)+N(ספטמבר!L30)+N(אוקטובר!L30)+N(נובמבר!L30)+N(דצמבר!L30)) -> 720 | D44: =IF(A44="","",SUMIFS(תנועות!$E$6:$E$2005,תנועות!$B$6:$B$2005,A44,תנועות!$A$6:$A$2005,">="&DATE(הגדרות!$C$3,1,1),תנועות!$A$6:$A$2005,"<"&DATE(הגדרות!$C$3+1,1,1))) -> 0 | E44: =IF(A44="","",C44-D44) -> 720 | F44: =IF(OR(A44="",N(C44)=0),"",D44/C44) -> 0
...

Sheet תנועות
A1: 📝 יומן תנועות – כל הכנסה והוצאה במקום אחד
A2: הזן תאריך, בחר קטגוריה מהרשימה וסכום חיובי. הסוג והחודש מתמלאים לבד, וכל הלשוניות (חודשים, לוח שנתי, חיסכון וחובות) מתעדכנות אוטומטית.
A5: תאריך | B5: קטגוריה | C5: סוג (אוטומטי) | D5: תיאור / הערה | E5: סכום | F5: חודש | H5: סיכום השנה לפי סוג | I5: סכום
C6: =IF(B6="","",IFERROR(INDEX(הגדרות!$A$8:$A$53,MATCH(B6,הגדרות!$B$8:$B$53,0)),"⚠ לא בהגדרות")) | F6: =IF(A6="","",INDEX(הגדרות!$H$16:$H$27,MONTH(A6))) | H6: הכנסות | I6: =SUMIFS(תנועות!$E$6:$E$2005,תנועות!$C$6:$C$2005,H6,תנועות!$A$6:$A$2005,">="&DATE(הגדרות!$C$3,1,1),תנועות!$A$6:$A$2005,"<"&DATE(הגדרות!$C$3+1,1,1)) -> 0
C7: =IF(B7="","",IFERROR(INDEX(הגדרות!$A$8:$A$53,MATCH(B7,הגדרות!$B$8:$B$53,0)),"⚠ לא בהגדרות")) | F7: =IF(A7="","",INDEX(הגדרות!$H$16:$H$27,MONTH(A7))) | H7: תוכניות חיסכון | I7: =SUMIFS(תנועות!$E$6:$E$2005,תנועות!$C$6:$C$2005,H7,תנועות!$A$6:$A$2005,">="&DATE(הגדרות!$C$3,1,1),תנועות!$A$6:$A$2005,"<"&DATE(הגדרות!$C$3+1,1,1)) -> 0
C8: =IF(B8="","",IFERROR(INDEX(הגדרות!$A$8:$A$53,MATCH(B8,הגדרות!$B$8:$B$53,0)),"⚠ לא בהגדרות")) | F8: =IF(A8="","",INDEX(הגדרות!$H$16:$H$27,MONTH(A8))) | H8: חשבונות ומנויים | I8: =SUMIFS(תנועות!$E$6:$E$2005,תנועות!$C$6:$C$2005,H8,תנועות!$A$6:$A$2005,">="&DATE(הגדרות!$C$3,1,1),תנועות!$A$6:$A$2005,"<"&DATE(הגדרות!$C$3+1,1,1)) -> 0
C9: =IF(B9="","",IFERROR(INDEX(הגדרות!$A$8:$A$53,MATCH(B9,הגדרות!$B$8:$B$53,0)),"⚠ לא בהגדרות")) | F9: =IF(A9="","",INDEX(הגדרות!$H$16:$H$27,MONTH(A9))) | H9: הוצאות משתנות | I9: =SUMIFS(תנועות!$E$6:$E$2005,תנועות!$C$6:$C$2005,H9,תנועות!$A$6:$A$2005,">="&DATE(הגדרות!$C$3,1,1),תנועות!$A$6:$A$2005,"<"&DATE(הגדרות!$C$3+1,1,1)) -> 0
C10: =IF(B10="","",IFERROR(INDEX(הגדרות!$A$8:$A$53,MATCH(B10,הגדרות!$B$8:$B$53,0)),"⚠ לא בהגדרות")) | F10: =IF(A10="","",INDEX(הגדרות!$H$16:$H$27,MONTH(A10))) | H10: חובות | I10: =SUMIFS(תנועות!$E$6:$E$2005,תנועות!$C$6:$C$2005,H10,תנועות!$A$6:$A$2005,">="&DATE(הגדרות!$C$3,1,1),תנועות!$A$6:$A$2005,"<"&DATE(הגדרות!$C$3+1,1,1)) -> 0
C11: =IF(B11="","",IFERROR(INDEX(הגדרות!$A$8:$A$53,MATCH(B11,הגדרות!$B$8:$B$53,0)),"⚠ לא בהגדרות")) | F11: =IF(A11="","",INDEX(הגדרות!$H$16:$H$27,MONTH(A11))) | H11: תנועות שהוזנו | I11: =COUNT(E6:E2005) -> 0
C12: =IF(B12="","",IFERROR(INDEX(הגדרות!$A$8:$A$53,MATCH(B12,הגדרות!$B$8:$B$53,0)),"⚠ לא בהגדרות")) | F12: =IF(A12="","",INDEX(הגדרות!$H$16:$H$27,MONTH(A12)))
C13: =IF(B13="","",IFERROR(INDEX(הגדרות!$A$8:$A$53,MATCH(B13,הגדרות!$B$8:$B$53,0)),"⚠ לא בהגדרות")) | F13: =IF(A13="","",INDEX(הגדרות!$H$16:$H$27,MONTH(A13)))
C14: =IF(B14="","",IFERROR(INDEX(הגדרות!$A$8:$A$53,MATCH(B14,הגדרות!$B$8:$B$53,0)),"⚠ לא בהגדרות")) | F14: =IF(A14="","",INDEX(הגדרות!$H$16:$H$27,MONTH(A14)))
C15: =IF(B15="","",IFERROR(INDEX(הגדרות!$A$8:$A$53,MATCH(B15,הגדרות!$B$8:$B$53,0)),"⚠ לא בהגדרות")) | F15: =IF(A15="","",INDEX(הגדרות!$H$16:$H$27,MONTH(A15)))
C16: =IF(B16="","",IFERROR(INDEX(הגדרות!$A$8:$A$53,MATCH(B16,הגדרות!$B$8:$B$53,0)),"⚠ לא בהגדרות")) | F16: =IF(A16="","",INDEX(הגדרות!$H$16:$H$27,MONTH(A16)))
C17: =IF(B17="","",IFERROR(INDEX(הגדרות!$A$8:$A$53,MATCH(B17,הגדרות!$B$8:$B$53,0)),"⚠ לא בהגדרות")) | F17: =IF(A17="","",INDEX(הגדרות!$H$16:$H$27,MONTH(A17)))
C18: =IF(B18="","",IFERROR(INDEX(הגדרות!$A$8:$A$53,MATCH(B18,הגדרות!$B$8:$B$53,0)),"⚠ לא בהגדרות")) | F18: =IF(A18="","",INDEX(הגדרות!$H$16:$H$27,MONTH(A18)))
C19: =IF(B19="","",IFERROR(INDEX(הגדרות!$A$8:$A$53,MATCH(B19,הגדרות!$B$8:$B$53,0)),"⚠ לא בהגדרות")) | F19: =IF(A19="","",INDEX(הגדרות!$H$16:$H$27,MONTH(A19)))
C20: =IF(B20="","",IFERROR(INDEX(הגדרות!$A$8:$A$53,MATCH(B20,הגדרות!$B$8:$B$53,0)),"⚠ לא בהגדרות")) | F20: =IF(A20="","",INDEX(הגדרות!$H$16:$H$27,MONTH(A20)))
C21: =IF(B21="","",IFERROR(INDEX(הגדרות!$A$8:$A$53,MATCH(B21,הגדרות!$B$8:$B$53,0)),"⚠ לא בהגדרות")) | F21: =IF(A21="","",INDEX(הגדרות!$H$16:$H$27,MONTH(A21)))
C22: =IF(B22="","",IFERROR(INDEX(הגדרות!$A$8:$A$53,MATCH(B22,הגדרות!$B$8:$B$53,0)),"⚠ לא בהגדרות")) | F22: =IF(A22="","",INDEX(הגדרות!$H$16:$H$27,MONTH(A22)))
C23: =IF(B23="","",IFERROR(INDEX(הגדרות!$A$8:$A$53,MATCH(B23,הגדרות!$B$8:$B$53,0)),"⚠ לא בהגדרות")) | F23: =IF(A23="","",INDEX(הגדרות!$H$16:$H$27,MONTH(A23)))
... C2005: =IF(B2005="","",IFERROR(INDEX(הגדרות!$A$8:$A$53,MATCH(B2005,הגדרות!$B$8:$B$53,0)),"⚠ לא בהגדרות")) | F2005: =IF(A2005="","",INDEX(הגדרות!$H$16:$H$27,MONTH(A2005)))

Sheet ינואר
A1: =" 🗓️ "&"ינואר"&" "&הגדרות!$C$3&" – תקציב חודשי" -> 🗓️ ינואר 2026 – תקציב חודשי | Z1: =DATE(הגדרות!$C$3,1,1) -> 46023
A2: התקציב נמשך מלשונית ההגדרות (אפשר לשנות ידנית כאן לחודש הזה בלבד) • הבפועל נמשך מיומן התנועות | Z2: =DATE(הגדרות!$C$3,2,1) -> 46054
Z3: =Z2-Z1 -> 31
A4: 💵 הכנסות החודש | F4: 💸 סה"כ יציאות | K4: 🏦 נשאר בעו"ש | P4: 🐷 שיעור חיסכון | U4: 🛒 ניצול תקציב משתנות
A5: =C8 -> 0 | F5: =SUM(C9:C12) -> 0 | K5: =C13 -> 0 | P5: =IF(C8=0,"–",C9/C8) -> – | U5: =IF(B11=0,"–",C11/B11) -> 0
A7: סיכום החודש | B7: תקציב | C7: בפועל | D7: הפרש | F7: שבוע (משתנות) | G7: תקציב | H7: בפועל | I7: נותר
A8: הכנסות | B8: =B41 -> 25320 | C8: =C41 -> 0 | D8: =C8-B8 -> -25320 | F8: ימים 1–7 | G8: =$B$11*7/$Z$3 -> 1670.9677 | H8: =SUMIFS(תנועות!$E$6:$E$2005,תנועות!$C$6:$C$2005,"הוצאות משתנות",תנועות!$A$6:$A$2005,">="&($Z$1+0),תנועות!$A$6:$A$2005,"<"&$Z$1+7) -> 0 | I8: =G8-H8 -> 1670.9677
A9: תוכניות חיסכון | B9: =G41 -> 5400 | C9: =H41 -> 0 | D9: =B9-C9 -> 5400 | F9: ימים 8–14 | G9: =$B$11*7/$Z$3 -> 1670.9677 | H9: =SUMIFS(תנועות!$E$6:$E$2005,תנועות!$C$6:$C$2005,"הוצאות משתנות",תנועות!$A$6:$A$2005,">="&($Z$1+7),תנועות!$A$6:$A$2005,"<"&$Z$1+14) -> 0 | I9: =G9-H9 -> 1670.9677
A10: חשבונות ומנויים | B10: =L41 -> 7925 | C10: =M41 -> 0 | D10: =B10-C10 -> 7925 | F10: ימים 15–21 | G10: =$B$11*7/$Z$3 -> 1670.9677 | H10: =SUMIFS(תנועות!$E$6:$E$2005,תנועות!$C$6:$C$2005,"הוצאות משתנות",תנועות!$A$6:$A$2005,">="&($Z$1+14),תנועות!$A$6:$A$2005,"<"&$Z$1+21) -> 0 | I10: =G10-H10 -> 1670.9677
A11: הוצאות משתנות | B11: =Q41 -> 7400 | C11: =R41 -> 0 | D11: =B11-C11 -> 7400 | F11: ימים 22–28 | G11: =$B$11*7/$Z$3 -> 1670.9677 | H11: =SUMIFS(תנועות!$E$6:$E$2005,תנועות!$C$6:$C$2005,"הוצאות משתנות",תנועות!$A$6:$A$2005,">="&($Z$1+21),תנועות!$A$6:$A$2005,"<"&$Z$1+28) -> 0 | I11: =G11-H11 -> 1670.9677
A12: חובות | B12: =V41 -> 2300 | C12: =W41 -> 0 | D12: =B12-C12 -> 2300 | F12: ימים 29–סוף | G12: =$B$11*($Z$3-28)/$Z$3 -> 716.12903 | H12: =SUMIFS(תנועות!$E$6:$E$2005,תנועות!$C$6:$C$2005,"הוצאות משתנות",תנועות!$A$6:$A$2005,">="&($Z$1+28),תנועות!$A$6:$A$2005,"<"&$Z$2) -> 0 | I12: =G12-H12 -> 716.12903
A13: נשאר בעו"ש | B13: =B8-SUM(B9:B12) -> 2295 | C13: =C8-SUM(C9:C12) -> 0 | D13: =C13-B13 -> -2295 | F13: סה"כ | G13: =SUM(G8:G12) -> 7400 | H13: =SUM(H8:H12) -> 0 | I13: =SUM(I8:I12) -> 7400
A15: 💡 תקציב שבועי להוצאות משתנות = התקציב החודשי מחולק לפי מספר הימים בכל שבוע. אדום = חריגה מהתקציב.
A24: הכנסות | F24: תוכניות חיסכון | K24: חשבונות ומנויים | P24: הוצאות משתנות | U24: חובות
A25: קטגוריה | B25: תקציב | C25: בפועל | D25: הפרש | F25: קטגוריה | G25: תקציב | H25: בפועל | I25: נותר | K25: קטגוריה | L25: תקציב | M25: בפועל | N25: נותר | P25: קטגוריה | Q25: תקציב | R25: בפועל | S25: נותר | U25: קטגוריה | V25: תקציב | W25: בפועל | X25: נותר
A26: =IF(הגדרות!$B$8="","",הגדרות!$B$8) -> משכורת 1 | B26: =IF(A26="","",הגדרות!$E$8) -> 14000 | C26: =IF(A26="","",SUMIFS(תנועות!$E$6:$E$2005,תנועות!$B$6:$B$2005,A26,תנועות!$A$6:$A$2005,">="&$Z$1,תנועות!$A$6:$A$2005,"<"&$Z$2)) -> 0 | D26: =IF(A26="","",N(C26)-N(B26)) -> -14000 | F26: =IF(הגדרות!$B$16="","",הגדרות!$B$16) -> קרן חירום | G26: =IF(F26="","",הגדרות!$E$16) -> 1500 | H26: =IF(F26="","",SUMIFS(תנועות!$E$6:$E$2005,תנועות!$B$6:$B$2005,F26,תנועות!$A$6:$A$2005,">="&$Z$1,תנועות!$A$6:$A$2005,"<"&$Z$2)) -> 0 | I26: =IF(F26="","",N(G26)-N(H26)) -> 1500 | K26: =IF(הגדרות!$B$21="","",הגדרות!$B$21) -> שכר דירה / משכנתא | L26: =IF(K26="","",הגדרות!$E$21) -> 5200 | M26: =IF(K26="","",SUMIFS(תנועות!$E$6:$E$2005,תנועות!$B$6:$B$2005,K26,תנועות!$A$6:$A$2005,">="&$Z$1,תנועות!$A$6:$A$2005,"<"&$Z$2)) -> 0 | N26: =IF(K26="","",N(L26)-N(M26)) -> 5200 | P26: =IF(הגדרות!$B$33="","",הגדרות!$B$33) -> סופרמרקט | Q26: =IF(P26="","",הגדרות!$E$33) -> 2816.6667 | R26: =IF(P26="","",SUMIFS(תנועות!$E$6:$E$2005,תנועות!$B$6:$B$2005,P26,תנועות!$A$6:$A$2005,">="&$Z$1,תנועות!$A$6:$A$2005,"<"&$Z$2)) -> 0 | S26: =IF(P26="","",N(Q26)-N(R26)) -> 2816.6667 | U26: =IF(הגדרות!$B$48="","",הגדרות!$B$48) -> הלוואת רכב | V26: =IF(U26="","",הגדרות!$E$48) -> 1100 | W26: =IF(U26="","",SUMIFS(תנועות!$E$6:$E$2005,תנועות!$B$6:$B$2005,U26,תנועות!$A$6:$A$2005,">="&$Z$1,תנועות!$A$6:$A$2005,"<"&$Z$2)) -> 0 | X26: =IF(U26="","",N(V26)-N(W26)) -> 1100
A27: =IF(הגדרות!$B$9="","",הגדרות!$B$9) -> משכורת 2 | B27: =IF(A27="","",הגדרות!$E$9) -> 9500 | C27: =IF(A27="","",SUMIFS(תנועות!$E$6:$E$2005,תנועות!$B$6:$B$2005,A27,תנועות!$A$6:$A$2005,">="&$Z$1,תנועות!$A$6:$A$2005,"<"&$Z$2)) -> 0 | D27: =IF(A27="","",N(C27)-N(B27)) -> -9500 | F27: =IF(הגדרות!$B$17="","",הגדרות!$B$17) -> חופשה משפחתית | G27: =IF(F27="","",הגדרות!$E$17) -> 600 | H27: =IF(F27="","",SUMIFS(תנועות!$E$6:$E$2005,תנועות!$B$6:$B$2005,F27,תנועות!$A$6:$A$2005,">="&$Z$1,תנועות!$A$6:$A$2005,"<"&$Z$2)) -> 0 | I27: =IF(F27="","",N(G27)-N(H27)) -> 600 | K27: =IF(הגדרות!$B$22="","",הגדרות!$B$22) -> ארנונה | L27: =IF(K27="","",הגדרות!$E$22) -> 450 | M27: =IF(K27="","",SUMIFS(תנועות!$E$6:$E$2005,תנועות!$B$6:$B$2005,K27,תנועות!$A$6:$A$2005,">="&$Z$1,תנועות!$A$6:$A$2005,"<"&$Z$2)) -> 0 | N27: =IF(K27="","",N(L27)-N(M27)) -> 450 | P27: =IF(הגדרות!$B$34="","",הגדרות!$B$34) -> דלק | Q27: =IF(P27="","",הגדרות!$E$34) -> 600 | R27: =IF(P27="","",SUMIFS(תנועות!$E$6:$E$2005,תנועות!$B$6:$B$2005,P27,תנועות!$A$6:$A$2005,">="&$Z$1,תנועות!$A$6:$A$2005,"<"&$Z$2)) -> 0 | S27: =IF(P27="","",N(Q27)-N(R27)) -> 600 | U27: =IF(הגדרות!$B$49="","",הגדרות!$B$49) -> הלוואה בנקאית | V27: =IF(U27="","",הגדרות!$E$49) -> 800 | W27: =IF(U27="","",SUMIFS(תנועות!$E$6:$E$2005,תנועות!$B$6:$B$2005,U27,תנועות!$A$6:$A$2005,">="&$Z$1,תנועות!$A$6:$A$2005,"<"&$Z$2)) -> 0 | X27: =IF(U27="","",N(V27)-N(W27)) -> 800
A28: =IF(הגדרות!$B$10="","",הגדרות!$B$10) -> עבודה נוספת | B28: =IF(A28="","",הגדרות!$E$10) -> 1500 | C28: =IF(A28="","",SUMIFS(תנועות!$E$6:$E$2005,תנועות!$B$6:$B$2005,A28,תנועות!$A$6:$A$2005,">="&$Z$1,תנועות!$A$6:$A$2005,"<"&$Z$2)) -> 0 | D28: =IF(A28="","",N(C28)-N(B28)) -> -1500 | F28: =IF(הגדרות!$B$18="","",הגדרות!$B$18) -> רכב חדש | G28: =IF(F28="","",הגדרות!$E$18) -> 800 | H28: =IF(F28="","",SUMIFS(תנועות!$E$6:$E$2005,תנועות!$B$6:$B$2005,F28,תנועות!$A$6:$A$2005,">="&$Z$1,תנועות!$A$6:$A$2005,"<"&$Z$2)) -> 0 | I28: =IF(F28="","",N(G28)-N(H28)) -> 800 | K28: =IF(הגדרות!$B$23="","",הגדרות!$B$23) -> חשמל | L28: =IF(K28="","",הגדרות!$E$23) -> 350 | M28: =IF(K28="","",SUMIFS(תנועות!$E$6:$E$2005,תנועות!$B$6:$B$2005,K28,תנועות!$A$6:$A$2005,">="&$Z$1,תנועות!$A$6:$A$2005,"<"&$Z$2)) -> 0 | N28: =IF(K28="","",N(L28)-N(M28)) -> 350 | P28: =IF(הגדרות!$B$35="","",הגדרות!$B$35) -> תחבורה ציבורית וחניה | Q28: =IF(P28="","",הגדרות!$E$35) -> 150 | R28: =IF(P28="","",SUMIFS(תנועות!$E$6:$E$2005,תנועות!$B$6:$B$2005,P28,תנועות!$A$6:$A$2005,">="&$Z$1,תנועות!$A$6:$A$2005,"<"&$Z$2)) -> 0 | S28: =IF(P28="","",N(Q28)-N(R28)) -> 150 | U28: =IF(הגדרות!$B$50="","",הגדרות!$B$50) -> כרטיס אשראי – פריסה | V28: =IF(U28="","",הגדרות!$E$50) -> 400 | W28: =IF(U28="","",SUMIFS(תנועות!$E$6:$E$2005,תנועות!$B$6:$B$2005,U28,תנועות!$A$6:$A$2005,">="&$Z$1,תנועות!$A$6:$A$2005,"<"&$Z$2)) -> 0 | X28: =IF(U28="","",N(V28)-N(W28)) -> 400
A29: =IF(הגדרות!$B$11="","",הגדרות!$B$11) -> קצבת ילדים | B29: =IF(A29="","",הגדרות!$E$11) -> 320 | C29: =IF(A29="","",SUMIFS(תנועות!$E$6:$E$2005,תנועות!$B$6:$B$2005,A29,תנועות!$A$6:$A$2005,">="&$Z$1,תנועות!$A$6:$A$2005,"<"&$Z$2)) -> 0 | D29: =IF(A29="","",N(C29)-N(B29)) -> -320 | F29: =IF(הגדרות!$B$19="","",הגדרות!$B$19) -> דירה | G29: =IF(F29="","",הגדרות!$E$19) -> 1500 | H29: =IF(F29="","",SUMIFS(תנועות!$E$6:$E$2005,תנועות!$B$6:$B$2005,F29,תנועות!$A$6:$A$2005,">="&$Z$1,תנועות!$A$6:$A$2005,"<"&$Z$2)) -> 0 | I29: =IF(F29="","",N(G29)-N(H29)) -> 1500 | K29: =IF(הגדרות!$B$24="","",הגדרות!$B$24) -> מים | L29: =IF(K29="","",הגדרות!$E$24) -> 125 | M29: =IF(K29="","",SUMIFS(תנועות!$E$6:$E$2005,תנועות!$B$6:$B$2005,K29,תנועות!$A$6:$A$2005,">="&$Z$1,תנועות!$A$6:$A$2005,"<"&$Z$2)) -> 0 | N29: =IF(K29="","",N(L29)-N(M29)) -> 125 | P29: =IF(הגדרות!$B$36="","",הגדרות!$B$36) -> מסעדות ובילויים | Q29: =IF(P29="","",הגדרות!$E$36) -> 1083.3333 | R29: =IF(P29="","",SUMIFS(תנועות!$E$6:$E$2005,תנועות!$B$6:$B$2005,P29,תנועות!$A$6:$A$2005,">="&$Z$1,תנועות!$A$6:$A$2005,"<"&$Z$2)) -> 0 | S29: =IF(P29="","",N(Q29)-N(R29)) -> 1083.3333 | U29: =IF(הגדרות!$B$51="","",הגדרות!$B$51) | V29: =IF(U29="","",הגדרות!$E$51) | W29: =IF(U29="","",SUMIFS(תנועות!$E$6:$E$2005,תנועות!$B$6:$B$2005,U29,תנועות!$A$6:$A$2005,">="&$Z$1,תנועות!$A$6:$A$2005,"<"&$Z$2)) | X29: =IF(U29="","",N(V29)-N(W29))
A30: =IF(הגדרות!$B$12="","",הגדרות!$B$12) -> החזרים והכנסות אחרות | B30: =IF(A30="","",הגדרות!$E$12) -> 0 | C30: =IF(A30="","",SUMIFS(תנועות!$E$6:$E$2005,תנועות!$B$6:$B$2005,A30,תנועות!$A$6:$A$2005,">="&$Z$1,תנועות!$A$6:$A$2005,"<"&$Z$2)) -> 0 | D30: =IF(A30="","",N(C30)-N(B30)) -> 0 | F30: =IF(הגדרות!$B$20="","",הגדרות!$B$20) -> השקעות | G30: =IF(F30="","",הגדרות!$E$20) -> 1000 | H30: =IF(F30="","",SUMIFS(תנועות!$E$6:$E$2005,תנועות!$B$6:$B$2005,F30,תנועות!$A$6:$A$2005,">="&$Z$1,תנועות!$A$6:$A$2005,"<"&$Z$2)) -> 0 | I30: =IF(F30="","",N(G30)-N(H30)) -> 1000 | K30: =IF(הגדרות!$B$25="","",הגדרות!$B$25) -> גז | L30: =IF(K30="","",הגדרות!$E$25) -> 60 | M30: =IF(K30="","",SUMIFS(תנועות!$E$6:$E$2005,תנועות!$B$6:$B$2005,K30,תנועות!$A$6:$A$2005,">="&$Z$1,תנועות!$A$6:$A$2005,"<"&$Z$2)) -> 0 | N30: =IF(K30="","",N(L30)-N(M30)) -> 60 | P30: =IF(הגדרות!$B$37="","",הגדרות!$B$37) -> ביגוד והנעלה | Q30: =IF(P30="","",הגדרות!$E$37) -> 400 | R30: =IF(P30="","",SUMIFS(תנועות!$E$6:$E$2005,תנועות!$B$6:$B$2005,P30,תנועות!$A$6:$A$2005,">="&$Z$1,תנועות!$A$6:$A$2005,"<"&$Z$2)) -> 0 | S30: =IF(P30="","",N(Q30)-N(R30)) -> 400 | U30: =IF(הגדרות!$B$52="","",הגדרות!$B$52) | V30: =IF(U30="","",הגדרות!$E$52) | W30: =IF(U30="","",SUMIFS(תנועות!$E$6:$E$2005,תנועות!$B$6:$B$2005,U30,תנועות!$A$6:$A$2005,">="&$Z$1,תנועות!$A$6:$A$2005,"<"&$Z$2)) | X30: =IF(U30="","",N(V30)-N(W30))
A31: =IF(הגדרות!$B$13="","",הגדרות!$B$13) | B31: =IF(A31="","",הגדרות!$E$13) | C31: =IF(A31="","",SUMIFS(תנועות!$E$6:$E$2005,תנועות!$B$6:$B$2005,A31,תנועות!$A$6:$A$2005,">="&$Z$1,תנועות!$A$6:$A$2005,"<"&$Z$2)) | D31: =IF(A31="","",N(C31)-N(B31)) | K31: =IF(הגדרות!$B$26="","",הגדרות!$B$26) -> ועד בית | L31: =IF(K31="","",הגדרות!$E$26) -> 250 | M31: =IF(K31="","",SUMIFS(תנועות!$E$6:$E$2005,תנועות!$B$6:$B$2005,K31,תנועות!$A$6:$A$2005,">="&$Z$1,תנועות!$A$6:$A$2005,"<"&$Z$2)) -> 0 | N31: =IF(K31="","",N(L31)-N(M31)) -> 250 | P31: =IF(הגדרות!$B$38="","",הגדרות!$B$38) -> בריאות ותרופות | Q31: =IF(P31="","",הגדרות!$E$38) -> 200 | R31: =IF(P31="","",SUMIFS(תנועות!$E$6:$E$2005,תנועות!$B$6:$B$2005,P31,תנועות!$A$6:$A$2005,">="&$Z$1,תנועות!$A$6:$A$2005,"<"&$Z$2)) -> 0 | S31: =IF(P31="","",N(Q31)-N(R31)) -> 200 | U31: =IF(הגדרות!$B$53="","",הגדרות!$B$53) | V31: =IF(U31="","",הגדרות!$E$53) | W31: =IF(U31="","",SUMIFS(תנועות!$E$6:$E$2005,תנועות!$B$6:$B$2005,U31,תנועות!$A$6:$A$2005,">="&$Z$1,תנועות!$A$6:$A$2005,"<"&$Z$2)) | X31: =IF(U31="","",N(V31)-N(W31))
A32: =IF(הגדרות!$B$14="","",הגדרות!$B$14) | B32: =IF(A32="","",הגדרות!$E$14) | C32: =IF(A32="","",SUMIFS(תנועות!$E$6:$E$2005,תנועות!$B$6:$B$2005,A32,תנועות!$A$6:$A$2005,">="&$Z$1,תנועות!$A$6:$A$2005,"<"&$Z$2)) | D32: =IF(A32="","",N(C32)-N(B32)) | K32: =IF(הגדרות!$B$27="","",הגדרות!$B$27) -> אינטרנט וטלוויזיה | L32: =IF(K32="","",הגדרות!$E$27) -> 180 | M32: =IF(K32="","",SUMIFS(תנועות!$E$6:$E$2005,תנועות!$B$6:$B$2005,K32,תנועות!$A$6:$A$2005,">="&$Z$1,תנועות!$A$6:$A$2005,"<"&$Z$2)) -> 0 | N32: =IF(K32="","",N(L32)-N(M32)) -> 180 | P32: =IF(הגדרות!$B$39="","",הגדרות!$B$39) -> ילדים וחינוך | Q32: =IF(P32="","",הגדרות!$E$39) -> 900 | R32: =IF(P32="","",SUMIFS(תנועות!$E$6:$E$2005,תנועות!$B$6:$B$2005,P32,תנועות!$A$6:$A$2005,">="&$Z$1,תנועות!$A$6:$A$2005,"<"&$Z$2)) -> 0 | S32: =IF(P32="","",N(Q32)-N(R32)) -> 900
A33: =IF(הגדרות!$B$15="","",הגדרות!$B$15) | B33: =IF(A33="","",הגדרות!$E$15) | C33: =IF(A33="","",SUMIFS(תנועות!$E$6:$E$2005,תנועות!$B$6:$B$2005,A33,תנועות!$A$6:$A$2005,">="&$Z$1,תנועות!$A$6:$A$2005,"<"&$Z$2)) | D33: =IF(A33="","",N(C33)-N(B33)) | K33: =IF(הגדרות!$B$28="","",הגדרות!$B$28) -> סלולר | L33: =IF(K33="","",הגדרות!$E$28) -> 120 | M33: =IF(K33="","",SUMIFS(תנועות!$E$6:$E$2005,תנועות!$B$6:$B$2005,K33,תנועות!$A$6:$A$2005,">="&$Z$1,תנועות!$A$6:$A$2005,"<"&$Z$2)) -> 0 | N33: =IF(K33="","",N(L33)-N(M33)) -> 120 | P33: =IF(הגדרות!$B$40="","",הגדרות!$B$40) -> מתנות ואירועים | Q33: =IF(P33="","",הגדרות!$E$40) -> 300 | R33: =IF(P33="","",SUMIFS(תנועות!$E$6:$E$2005,תנועות!$B$6:$B$2005,P33,תנועות!$A$6:$A$2005,">="&$Z$1,תנועות!$A$6:$A$2005,"<"&$Z$2)) -> 0 | S33: =IF(P33="","",N(Q33)-N(R33)) -> 300
K34: =IF(הגדרות!$B$29="","",הגדרות!$B$29) -> ביטוחי בריאות וחיים | L34: =IF(K34="","",הגדרות!$E$29) -> 450 | M34: =IF(K34="","",SUMIFS(תנועות!$E$6:$E$2005,תנועות!$B$6:$B$2005,K34,תנועות!$A$6:$A$2005,">="&$Z$1,תנועות!$A$6:$A$2005,"<"&$Z$2)) -> 0 | N34: =IF(K34="","",N(L34)-N(M34)) -> 450 | P34: =IF(הגדרות!$B$41="","",הגדרות!$B$41) -> טיפוח | Q34: =IF(P34="","",הגדרות!$E$41) -> 200 | R34: =IF(P34="","",SUMIFS(תנועות!$E$6:$E$2005,תנועות!$B$6:$B$2005,P34,תנועות!$A$6:$A$2005,">="&$Z$1,תנועות!$A$6:$A$2005,"<"&$Z$2)) -> 0 | S34: =IF(P34="","",N(Q34)-N(R34)) -> 200
K35: =IF(הגדרות!$B$30="","",הגדרות!$B$30) -> ביטוח רכב | L35: =IF(K35="","",הגדרות!$E$30) -> 400 | M35: =IF(K35="","",SUMIFS(תנועות!$E$6:$E$2005,תנועות!$B$6:$B$2005,K35,תנועות!$A$6:$A$2005,">="&$Z$1,תנועות!$A$6:$A$2005,"<"&$Z$2)) -> 0 | N35: =IF(K35="","",N(L35)-N(M35)) -> 400 | P35: =IF(הגדרות!$B$42="","",הגדרות!$B$42) -> בית ותחזוקה | Q35: =IF(P35="","",הגדרות!$E$42) -> 300 | R35: =IF(P35="","",SUMIFS(תנועות!$E$6:$E$2005,תנועות!$B$6:$B$2005,P35,תנועות!$A$6:$A$2005,">="&$Z$1,תנועות!$A$6:$A$2005,"<"&$Z$2)) -> 0 | S35: =IF(P35="","",N(Q35)-N(R35)) -> 300
K36: =IF(הגדרות!$B$31="","",הגדרות!$B$31) -> סטרימינג ומנויים | L36: =IF(K36="","",הגדרות!$E$31) -> 90 | M36: =IF(K36="","",SUMIFS(תנועות!$E$6:$E$2005,תנועות!$B$6:$B$2005,K36,תנועות!$A$6:$A$2005,">="&$Z$1,תנועות!$A$6:$A$2005,"<"&$Z$2)) -> 0 | N36: =IF(K36="","",N(L36)-N(M36)) -> 90 | P36: =IF(הגדרות!$B$43="","",הגדרות!$B$43) -> חיות מחמד | Q36: =IF(P36="","",הגדרות!$E$43) -> 150 | R36: =IF(P36="","",SUMIFS(תנועות!$E$6:$E$2005,תנועות!$B$6:$B$2005,P36,תנועות!$A$6:$A$2005,">="&$Z$1,תנועות!$A$6:$A$2005,"<"&$Z$2)) -> 0 | S36: =IF(P36="","",N(Q36)-N(R36)) -> 150
K37: =IF(הגדרות!$B$32="","",הגדרות!$B$32) -> חדר כושר | L37: =IF(K37="","",הגדרות!$E$32) -> 250 | M37: =IF(K37="","",SUMIFS(תנועות!$E$6:$E$2005,תנועות!$B$6:$B$2005,K37,תנועות!$A$6:$A$2005,">="&$Z$1,תנועות!$A$6:$A$2005,"<"&$Z$2)) -> 0 | N37: =IF(K37="","",N(L37)-N(M37)) -> 250 | P37: =IF(הגדרות!$B$44="","",הגדרות!$B$44) -> שונות | Q37: =IF(P37="","",הגדרות!$E$44) -> 300 | R37: =IF(P37="","",SUMIFS(תנועות!$E$6:$E$2005,תנועות!$B$6:$B$2005,P37,תנועות!$A$6:$A$2005,">="&$Z$1,תנועות!$A$6:$A$2005,"<"&$Z$2)) -> 0 | S37: =IF(P37="","",N(Q37)-N(R37)) -> 300
P38: =IF(הגדרות!$B$45="","",הגדרות!$B$45) | Q38: =IF(P38="","",הגדרות!$E$45) | R38: =IF(P38="","",SUMIFS(תנועות!$E$6:$E$2005,תנועות!$B$6:$B$2005,P38,תנועות!$A$6:$A$2005,">="&$Z$1,תנועות!$A$6:$A$2005,"<"&$Z$2)) | S38: =IF(P38="","",N(Q38)-N(R38))
P39: =IF(הגדרות!$B$46="","",הגדרות!$B$46) | Q39: =IF(P39="","",הגדרות!$E$46) | R39: =IF(P39="","",SUMIFS(תנועות!$E$6:$E$2005,תנועות!$B$6:$B$2005,P39,תנועות!$A$6:$A$2005,">="&$Z$1,תנועות!$A$6:$A$2005,"<"&$Z$2)) | S39: =IF(P39="","",N(Q39)-N(R39))
P40: =IF(הגדרות!$B$47="","",הגדרות!$B$47) | Q40: =IF(P40="","",הגדרות!$E$47) | R40: =IF(P40="","",SUMIFS(תנועות!$E$6:$E$2005,תנועות!$B$6:$B$2005,P40,תנועות!$A$6:$A$2005,">="&$Z$1,תנועות!$A$6:$A$2005,"<"&$Z$2)) | S40: =IF(P40="","",N(Q40)-N(R40))
A41: סה"כ | B41: =SUM(B26:B40) -> 25320 | C41: =SUM(C26:C40) -> 0 | D41: =SUM(D26:D40) -> -25320 | F41: סה"כ | G41: =SUM(G26:G40) -> 5400 | H41: =SUM(H26:H40) -> 0 | I41: =SUM(I26:I40) -> 5400 | K41: סה"כ | L41: =SUM(L26:L40) -> 7925 | M41: =SUM(M26:M40) -> 0 | N41: =SUM(N26:N40) -> 7925 | P41: סה"כ | Q41: =SUM(Q26:Q40) -> 7400 | R41: =SUM(R26:R40) -> 0 | S41: =SUM(S26:S40) -> 7400 | U41: סה"כ | V41: =SUM(V26:V40) -> 2300 | W41: =SUM(W26:W40) -> 0 | X41: =SUM(X26:X40) -> 2300

Sheet פברואר
A1: =" 🗓️ "&"פברואר"&" "&הגדרות!$C$3&" – תקציב חודשי" -> 🗓️ פברואר 2026 – תקציב חודשי | Z1: =DATE(הגדרות!$C$3,2,1) -> 46054
A2: התקציב נמשך מלשונית ההגדרות (אפשר לשנות ידנית כאן לחודש הזה בלבד) • הבפועל נמשך מיומן התנועות | Z2: =DATE(הגדרות!$C$3,3,1) -> 46082
Z3: =Z2-Z1 -> 28
A4: 💵 הכנסות החודש | F4: 💸 סה"כ יציאות | K4: 🏦 נשאר בעו"ש | P4: 🐷 שיעור חיסכון | U4: 🛒 ניצול תקציב משתנות
A5: =C8 -> 0 | F5: =SUM(C9:C12) -> 0 | K5: =C13 -> 0 | P5: =IF(C8=0,"–",C9/C8) -> – | U5: =IF(B11=0,"–",C11/B11) -> 0
A7: סיכום החודש | B7: תקציב | C7: בפועל | D7: הפרש | F7: שבוע (משתנות) | G7: תקציב | H7: בפועל | I7: נותר
A8: הכנסות | B8: =B41 -> 25320 | C8: =C41 -> 0 | D8: =C8-B8 -> -25320 | F8: ימים 1–7 | G8: =$B$11*7/$Z$3 -> 1850 | H8: =SUMIFS(תנועות!$E$6:$E$2005,תנועות!$C$6:$C$2005,"הוצאות משתנות",תנועות!$A$6:$A$2005,">="&($Z$1+0),תנועות!$A$6:$A$2005,"<"&$Z$1+7) -> 0 | I8: =G8-H8 -> 1850
A9: תוכניות חיסכון | B9: =G41 -> 5400 | C9: =H41 -> 0 | D9: =B9-C9 -> 5400 | F9: ימים 8–14 | G9: =$B$11*7/$Z$3 -> 1850 | H9: =SUMIFS(תנועות!$E$6:$E$2005,תנועות!$C$6:$C$2005,"הוצאות משתנות",תנועות!$A$6:$A$2005,">="&($Z$1+7),תנועות!$A$6:$A$2005,"<"&$Z$1+14) -> 0 | I9: =G9-H9 -> 1850
A10: חשבונות ומנויים | B10: =L41 -> 7925 | C10: =M41 -> 0 | D10: =B10-C10 -> 7925 | F10: ימים 15–21 | G10: =$B$11*7/$Z$3 -> 1850 | H10: =SUMIFS(תנועות!$E$6:$E$2005,תנועות!$C$6:$C$2005,"הוצאות משתנות",תנועות!$A$6:$A$2005,">="&($Z$1+14),תנועות!$A$6:$A$2005,"<"&$Z$1+21) -> 0 | I10: =G10-H10 -> 1850
A11: הוצאות משתנות | B11: =Q41 -> 7400 | C11: =R41 -> 0 | D11: =B11-C11 -> 7400 | F11: ימים 22–28 | G11: =$B$11*7/$Z$3 -> 1850 | H11: =SUMIFS(תנועות!$E$6:$E$2005,תנועות!$C$6:$C$2005,"הוצאות משתנות",תנועות!$A$6:$A$2005,">="&($Z$1+21),תנועות!$A$6:$A$2005,"<"&$Z$1+28) -> 0 | I11: =G11-H11 -> 1850
A12: חובות | B12: =V41 -> 2300 | C12: =W41 -> 0 | D12: =B12-C12 -> 2300 | F12: ימים 29–סוף | G12: =$B$11*($Z$3-28)/$Z$3 -> 0 | H12: =SUMIFS(תנועות!$E$6:$E$2005,תנועות!$C$6:$C$2005,"הוצאות משתנות",תנועות!$A$6:$A$2005,">="&($Z$1+28),תנועות!$A$6:$A$2005,"<"&$Z$2) -> 0 | I12: =G12-H12 -> 0
A13: נשאר בעו"ש | B13: =B8-SUM(B9:B12) -> 2295 | C13: =C8-SUM(C9:C12) -> 0 | D13: =C13-B13 -> -2295 | F13: סה"כ | G13: =SUM(G8:G12) -> 7400 | H13: =SUM(H8:H12) -> 0 | I13: =SUM(I8:I12) -> 7400
A15: 💡 תקציב שבועי להוצאות משתנות = התקציב החודשי מחולק לפי מספר הימים בכל שבוע. אדום = חריגה מהתקציב.
A24: הכנסות | F24: תוכניות חיסכון | K24: חשבונות ומנויים | P24: הוצאות משתנות | U24: חובות
A25: קטגוריה | B25: תקציב | C25: בפועל | D25: הפרש | F25: קטגוריה | G25: תקציב | H25: בפועל | I25: נותר | K25: קטגוריה | L25: תקציב | M25: בפועל | N25: נותר | P25: קטגוריה | Q25: תקציב | R25: בפועל | S25: נותר | U25: קטגוריה | V25: תקציב | W25: בפועל | X25: נותר
A26: =IF(הגדרות!$B$8="","",הגדרות!$B$8) -> משכורת 1 | B26: =IF(A26="","",הגדרות!$E$8) -> 14000 | C26: =IF(A26="","",SUMIFS(תנועות!$E$6:$E$2005,תנועות!$B$6:$B$2005,A26,תנועות!$A$6:$A$2005,">="&$Z$1,תנועות!$A$6:$A$2005,"<"&$Z$2)) -> 0 | D26: =IF(A26="","",N(C26)-N(B26)) -> -14000 | F26: =IF(הגדרות!$B$16="","",הגדרות!$B$16) -> קרן חירום | G26: =IF(F26="","",הגדרות!$E$16) -> 1500 | H26: =IF(F26="","",SUMIFS(תנועות!$E$6:$E$2005,תנועות!$B$6:$B$2005,F26,תנועות!$A$6:$A$2005,">="&$Z$1,תנועות!$A$6:$A$2005,"<"&$Z$2)) -> 0 | I26: =IF(F26="","",N(G26)-N(H26)) -> 1500 | K26: =IF(הגדרות!$B$21="","",הגדרות!$B$21) -> שכר דירה / משכנתא | L26: =IF(K26="","",הגדרות!$E$21) -> 5200 | M26: =IF(K26="","",SUMIFS(תנועות!$E$6:$E$2005,תנועות!$B$6:$B$2005,K26,תנועות!$A$6:$A$2005,">="&$Z$1,תנועות!$A$6:$A$2005,"<"&$Z$2)) -> 0 | N26: =IF(K26="","",N(L26)-N(M26)) -> 5200 | P26: =IF(הגדרות!$B$33="","",הגדרות!$B$33) -> סופרמרקט | Q26: =IF(P26="","",הגדרות!$E$33) -> 2816.6667 | R26: =IF(P26="","",SUMIFS(תנועות!$E$6:$E$2005,תנועות!$B$6:$B$2005,P26,תנועות!$A$6:$A$2005,">="&$Z$1,תנועות!$A$6:$A$2005,"<"&$Z$2)) -> 0 | S26: =IF(P26="","",N(Q26)-N(R26)) -> 2816.6667 | U26: =IF(הגדרות!$B$48="","",הגדרות!$B$48) -> הלוואת רכב | V26: =IF(U26="","",הגדרות!$E$48) -> 1100 | W26: =IF(U26="","",SUMIFS(תנועות!$E$6:$E$2005,תנועות!$B$6:$B$2005,U26,תנועות!$A$6:$A$2005,">="&$Z$1,תנועות!$A$6:$A$2005,"<"&$Z$2)) -> 0 | X26: =IF(U26="","",N(V26)-N(W26)) -> 1100
A27: =IF(הגדרות!$B$9="","",הגדרות!$B$9) -> משכורת 2 | B27: =IF(A27="","",הגדרות!$E$9) -> 9500 | C27: =IF(A27="","",SUMIFS(תנועות!$E$6:$E$2005,תנועות!$B$6:$B$2005,A27,תנועות!$A$6:$A$2005,">="&$Z$1,תנועות!$A$6:$A$2005,"<"&$Z$2)) -> 0 | D27: =IF(A27="","",N(C27)-N(B27)) -> -9500 | F27: =IF(הגדרות!$B$17="","",הגדרות!$B$17) -> חופשה משפחתית | G27: =IF(F27="","",הגדרות!$E$17) -> 600 | H27: =IF(F27="","",SUMIFS(תנועות!$E$6:$E$2005,תנועות!$B$6:$B$2005,F27,תנועות!$A$6:$A$2005,">="&$Z$1,תנועות!$A$6:$A$2005,"<"&$Z$2)) -> 0 | I27: =IF(F27="","",N(G27)-N(H27)) -> 600 | K27: =IF(הגדרות!$B$22="","",הגדרות!$B$22) -> ארנונה | L27: =IF(K27="","",הגדרות!$E$22) -> 450 | M27: =IF(K27="","",SUMIFS(תנועות!$E$6:$E$2005,תנועות!$B$6:$B$2005,K27,תנועות!$A$6:$A$2005,">="&$Z$1,תנועות!$A$6:$A$2005,"<"&$Z$2)) -> 0 | N27: =IF(K27="","",N(L27)-N(M27)) -> 450 | P27: =IF(הגדרות!$B$34="","",הגדרות!$B$34) -> דלק | Q27: =IF(P27="","",הגדרות!$E$34) -> 600 | R27: =IF(P27="","",SUMIFS(תנועות!$E$6:$E$2005,תנועות!$B$6:$B$2005,P27,תנועות!$A$6:$A$2005,">="&$Z$1,תנועות!$A$6:$A$2005,"<"&$Z$2)) -> 0 | S27: =IF(P27="","",N(Q27)-N(R27)) -> 600 | U27: =IF(הגדרות!$B$49="","",הגדרות!$B$49) -> הלוואה בנקאית | V27: =IF(U27="","",הגדרות!$E$49) -> 800 | W27: =IF(U27="","",SUMIFS(תנועות!$E$6:$E$2005,תנועות!$B$6:$B$2005,U27,תנועות!$A$6:$A$2005,">="&$Z$1,תנועות!$A$6:$A$2005,"<"&$Z$2)) -> 0 | X27: =IF(U27="","",N(V27)-N(W27)) -> 800
A28: =IF(הגדרות!$B$10="","",הגדרות!$B$10) -> עבודה נוספת | B28: =IF(A28="","",הגדרות!$E$10) -> 1500 | C28: =IF(A28="","",SUMIFS(תנועות!$E$6:$E$2005,תנועות!$B$6:$B$2005,A28,תנועות!$A$6:$A$2005,">="&$Z$1,תנועות!$A$6:$A$2005,"<"&$Z$2)) -> 0 | D28: =IF(A28="","",N(C28)-N(B28)) -> -1500 | F28: =IF(הגדרות!$B$18="","",הגדרות!$B$18) -> רכב חדש | G28: =IF(F28="","",הגדרות!$E$18) -> 800 | H28: =IF(F28="","",SUMIFS(תנועות!$E$6:$E$2005,תנועות!$B$6:$B$2005,F28,תנועות!$A$6:$A$2005,">="&$Z$1,תנועות!$A$6:$A$2005,"<"&$Z$2)) -> 0 | I28: =IF(F28="","",N(G28)-N(H28)) -> 800 | K28: =IF(הגדרות!$B$23="","",הגדרות!$B$23) -> חשמל | L28: =IF(K28="","",הגדרות!$E$23) -> 350 | M28: =IF(K28="","",SUMIFS(תנועות!$E$6:$E$2005,תנועות!$B$6:$B$2005,K28,תנועות!$A$6:$A$2005,">="&$Z$1,תנועות!$A$6:$A$2005,"<"&$Z$2)) -> 0 | N28: =IF(K28="","",N(L28)-N(M28)) -> 350 | P28: =IF(הגדרות!$B$35="","",הגדרות!$B$35) -> תחבורה ציבורית וחניה | Q28: =IF(P28="","",הגדרות!$E$35) -> 150 | R28: =IF(P28="","",SUMIFS(תנועות!$E$6:$E$2005,תנועות!$B$6:$B$2005,P28,תנועות!$A$6:$A$2005,">="&$Z$1,תנועות!$A$6:$A$2005,"<"&$Z$2)) -> 0 | S28: =IF(P28="","",N(Q28)-N(R28)) -> 150 | U28: =IF(הגדרות!$B$50="","",הגדרות!$B$50) -> כרטיס אשראי – פריסה | V28: =IF(U28="","",הגדרות!$E$50) -> 400 | W28: =IF(U28="","",SUMIFS(תנועות!$E$6:$E$2005,תנועות!$B$6:$B$2005,U28,תנועות!$A$6:$A$2005,">="&$Z$1,תנועות!$A$6:$A$2005,"<"&$Z$2)) -> 0 | X28: =IF(U28="","",N(V28)-N(W28)) -> 400
A29: =IF(הגדרות!$B$11="","",הגדרות!$B$11) -> קצבת ילדים | B29: =IF(A29="","",הגדרות!$E$11) -> 320 | C29: =IF(A29="","",SUMIFS(תנועות!$E$6:$E$2005,תנועות!$B$6:$B$2005,A29,תנועות!$A$6:$A$2005,">="&$Z$1,תנועות!$A$6:$A$2005,"<"&$Z$2)) -> 0 | D29: =IF(A29="","",N(C29)-N(B29)) -> -320 | F29: =IF(הגדרות!$B$19="","",הגדרות!$B$19) -> דירה | G29: =IF(F29="","",הגדרות!$E$19) -> 1500 | H29: =IF(F29="","",SUMIFS(תנועות!$E$6:$E$2005,תנועות!$B$6:$B$2005,F29,תנועות!$A$6:$A$2005,">="&$Z$1,תנועות!$A$6:$A$2005,"<"&$Z$2)) -> 0 | I29: =IF(F29="","",N(G29)-N(H29)) -> 1500 | K29: =IF(הגדרות!$B$24="","",הגדרות!$B$24) -> מים | L29: =IF(K29="","",הגדרות!$E$24) -> 125 | M29: =IF(K29="","",SUMIFS(תנועות!$E$6:$E$2005,תנועות!$B$6:$B$2005,K29,תנועות!$A$6:$A$2005,">="&$Z$1,תנועות!$A$6:$A$2005,"<"&$Z$2)) -> 0 | N29: =IF(K29="","",N(L29)-N(M29)) -> 125 | P29: =IF(הגדרות!$B$36="","",הגדרות!$B$36) -> מסעדות ובילויים | Q29: =IF(P29="","",הגדרות!$E$36) -> 1083.3333 | R29: =IF(P29="","",SUMIFS(תנועות!$E$6:$E$2005,תנועות!$B$6:$B$2005,P29,תנועות!$A$6:$A$2005,">="&$Z$1,תנועות!$A$6:$A$2005,"<"&$Z$2)) -> 0 | S29: =IF(P29="","",N(Q29)-N(R29)) -> 1083.3333 | U29: =IF(הגדרות!$B$51="","",הגדרות!$B$51) | V29: =IF(U29="","",הגדרות!$E$51) | W29: =IF(U29="","",SUMIFS(תנועות!$E$6:$E$2005,תנועות!$B$6:$B$2005,U29,תנועות!$A$6:$A$2005,">="&$Z$1,תנועות!$A$6:$A$2005,"<"&$Z$2)) | X29: =IF(U29="","",N(V29)-N(W29))
A30: =IF(הגדרות!$B$12="","",הגדרות!$B$12) -> החזרים והכנסות אחרות | B30: =IF(A30="","",הגדרות!$E$12) -> 0 | C30: =IF(A30="","",SUMIFS(תנועות!$E$6:$E$2005,תנועות!$B$6:$B$2005,A30,תנועות!$A$6:$A$2005,">="&$Z$1,תנועות!$A$6:$A$2005,"<"&$Z$2)) -> 0 | D30: =IF(A30="","",N(C30)-N(B30)) -> 0 | F30: =IF(הגדרות!$B$20="","",הגדרות!$B$20) -> השקעות | G30: =IF(F30="","",הגדרות!$E$20) -> 1000 | H30: =IF(F30="","",SUMIFS(תנועות!$E$6:$E$2005,תנועות!$B$6:$B$2005,F30,תנועות!$A$6:$A$2005,">="&$Z$1,תנועות!$A$6:$A$2005,"<"&$Z$2)) -> 0 | I30: =IF(F30="","",N(G30)-N(H30)) -> 1000 | K30: =IF(הגדרות!$B$25="","",הגדרות!$B$25) -> גז | L30: =IF(K30="","",הגדרות!$E$25) -> 60 | M30: =IF(K30="","",SUMIFS(תנועות!$E$6:$E$2005,תנועות!$B$6:$B$2005,K30,תנועות!$A$6:$A$2005,">="&$Z$1,תנועות!$A$6:$A$2005,"<"&$Z$2)) -> 0 | N30: =IF(K30="","",N(L30)-N(M30)) -> 60 | P30: =IF(הגדרות!$B$37="","",הגדרות!$B$37) -> ביגוד והנעלה | Q30: =IF(P30="","",הגדרות!$E$37) -> 400 | R30: =IF(P30="","",SUMIFS(תנועות!$E$6:$E$2005,תנועות!$B$6:$B$2005,P30,תנועות!$A$6:$A$2005,">="&$Z$1,תנועות!$A$6:$A$2005,"<"&$Z$2)) -> 0 | S30: =IF(P30="","",N(Q30)-N(R30)) -> 400 | U30: =IF(הגדרות!$B$52="","",הגדרות!$B$52) | V30: =IF(U30="","",הגדרות!$E$52) | W30: =IF(U30="","",SUMIFS(תנועות!$E$6:$E$2005,תנועות!$B$6:$B$2005,U30,תנועות!$A$6:$A$2005,">="&$Z$1,תנועות!$A$6:$A$2005,"<"&$Z$2)) | X30: =IF(U30="","",N(V30)-N(W30))
A31: =IF(הגדרות!$B$13="","",הגדרות!$B$13) | B31: =IF(A31="","",הגדרות!$E$13) | C31: =IF(A31="","",SUMIFS(תנועות!$E$6:$E$2005,תנועות!$B$6:$B$2005,A31,תנועות!$A$6:$A$2005,">="&$Z$1,תנועות!$A$6:$A$2005,"<"&$Z$2)) | D31: =IF(A31="","",N(C31)-N(B31)) | K31: =IF(הגדרות!$B$26="","",הגדרות!$B$26) -> ועד בית | L31: =IF(K31="","",הגדרות!$E$26) -> 250 | M31: =IF(K31="","",SUMIFS(תנועות!$E$6:$E$2005,תנועות!$B$6:$B$2005,K31,תנועות!$A$6:$A$2005,">="&$Z$1,תנועות!$A$6:$A$2005,"<"&$Z$2)) -> 0 | N31: =IF(K31="","",N(L31)-N(M31)) -> 250 | P31: =IF(הגדרות!$B$38="","",הגדרות!$B$38) -> בריאות ותרופות | Q31: =IF(P31="","",הגדרות!$E$38) -> 200 | R31: =IF(P31="","",SUMIFS(תנועות!$E$6:$E$2005,תנועות!$B$6:$B$2005,P31,תנועות!$A$6:$A$2005,">="&$Z$1,תנועות!$A$6:$A$2005,"<"&$Z$2)) -> 0 | S31: =IF(P31="","",N(Q31)-N(R31)) -> 200 | U31: =IF(הגדרות!$B$53="","",הגדרות!$B$53) | V31: =IF(U31="","",הגדרות!$E$53) | W31: =IF(U31="","",SUMIFS(תנועות!$E$6:$E$2005,תנועות!$B$6:$B$2005,U31,תנועות!$A$6:$A$2005,">="&$Z$1,תנועות!$A$6:$A$2005,"<"&$Z$2)) | X31: =IF(U31="","",N(V31)-N(W31))
A32: =IF(הגדרות!$B$14="","",הגדרות!$B$14) | B32: =IF(A32="","",הגדרות!$E$14) | C32: =IF(A32="","",SUMIFS(תנועות!$E$6:$E$2005,תנועות!$B$6:$B$2005,A32,תנועות!$A$6:$A$2005,">="&$Z$1,תנועות!$A$6:$A$2005,"<"&$Z$2)) | D32: =IF(A32="","",N(C32)-N(B32)) | K32: =IF(הגדרות!$B$27="","",הגדרות!$B$27) -> אינטרנט וטלוויזיה | L32: =IF(K32="","",הגדרות!$E$27) -> 180 | M32: =IF(K32="","",SUMIFS(תנועות!$E$6:$E$2005,תנועות!$B$6:$B$2005,K32,תנועות!$A$6:$A$2005,">="&$Z$1,תנועות!$A$6:$A$2005,"<"&$Z$2)) -> 0 | N32: =IF(K32="","",N(L32)-N(M32)) -> 180 | P32: =IF(הגדרות!$B$39="","",הגדרות!$B$39) -> ילדים וחינוך | Q32: =IF(P32="","",הגדרות!$E$39) -> 900 | R32: =IF(P32="","",SUMIFS(תנועות!$E$6:$E$2005,תנועות!$B$6:$B$2005,P32,תנועות!$A$6:$A$2005,">="&$Z$1,תנועות!$A$6:$A$2005,"<"&$Z$2)) -> 0 | S32: =IF(P32="","",N(Q32)-N(R32)) -> 900
A33: =IF(הגדרות!$B$15="","",הגדרות!$B$15) | B33: =IF(A33="","",הגדרות!$E$15) | C33: =IF(A33="","",SUMIFS(תנועות!$E$6:$E$2005,תנועות!$B$6:$B$2005,A33,תנועות!$A$6:$A$2005,">="&$Z$1,תנועות!$A$6:$A$2005,"<"&$Z$2)) | D33: =IF(A33="","",N(C33)-N(B33)) | K33: =IF(הגדרות!$B$28="","",הגדרות!$B$28) -> סלולר | L33: =IF(K33="","",הגדרות!$E$28) -> 120 | M33: =IF(K33="","",SUMIFS(תנועות!$E$6:$E$2005,תנועות!$B$6:$B$2005,K33,תנועות!$A$6:$A$2005,">="&$Z$1,תנועות!$A$6:$A$2005,"<"&$Z$2)) -> 0 | N33: =IF(K33="","",N(L33)-N(M33)) -> 120 | P33: =IF(הגדרות!$B$40="","",הגדרות!$B$40) -> מתנות ואירועים | Q33: =IF(P33="","",הגדרות!$E$40) -> 300 | R33: =IF(P33="","",SUMIFS(תנועות!$E$6:$E$2005,תנועות!$B$6:$B$2005,P33,תנועות!$A$6:$A$2005,">="&$Z$1,תנועות!$A$6:$A$2005,"<"&$Z$2)) -> 0 | S33: =IF(P33="","",N(Q33)-N(R33)) -> 300
K34: =IF(הגדרות!$B$29="","",הגדרות!$B$29) -> ביטוחי בריאות וחיים | L34: =IF(K34="","",הגדרות!$E$29) -> 450 | M34: =IF(K34="","",SUMIFS(תנועות!$E$6:$E$2005,תנועות!$B$6:$B$2005,K34,תנועות!$A$6:$A$2005,">="&$Z$1,תנועות!$A$6:$A$2005,"<"&$Z$2)) -> 0 | N34: =IF(K34="","",N(L34)-N(M34)) -> 450 | P34: =IF(הגדרות!$B$41="","",הגדרות!$B$41) -> טיפוח | Q34: =IF(P34="","",הגדרות!$E$41) -> 200 | R34: =IF(P34="","",SUMIFS(תנועות!$E$6:$E$2005,תנועות!$B$6:$B$2005,P34,תנועות!$A$6:$A$2005,">="&$Z$1,תנועות!$A$6:$A$2005,"<"&$Z$2)) -> 0 | S34: =IF(P34="","",N(Q34)-N(R34)) -> 200
K35: =IF(הגדרות!$B$30="","",הגדרות!$B$30) -> ביטוח רכב | L35: =IF(K35="","",הגדרות!$E$30) -> 400 | M35: =IF(K35="","",SUMIFS(תנועות!$E$6:$E$2005,תנועות!$B$6:$B$2005,K35,תנועות!$A$6:$A$2005,">="&$Z$1,תנועות!$A$6:$A$2005,"<"&$Z$2)) -> 0 | N35: =IF(K35="","",N(L35)-N(M35)) -> 400 | P35: =IF(הגדרות!$B$42="","",הגדרות!$B$42) -> בית ותחזוקה | Q35: =IF(P35="","",הגדרות!$E$42) -> 300 | R35: =IF(P35="","",SUMIFS(תנועות!$E$6:$E$2005,תנועות!$B$6:$B$2005,P35,תנועות!$A$6:$A$2005,">="&$Z$1,תנועות!$A$6:$A$2005,"<"&$Z$2)) -> 0 | S35: =IF(P35="","",N(Q35)-N(R35)) -> 300
K36: =IF(הגדרות!$B$31="","",הגדרות!$B$31) -> סטרימינג ומנויים | L36: =IF(K36="","",הגדרות!$E$31) -> 90 | M36: =IF(K36="","",SUMIFS(תנועות!$E$6:$E$2005,תנועות!$B$6:$B$2005,K36,תנועות!$A$6:$A$2005,">="&$Z$1,תנועות!$A$6:$A$2005,"<"&$Z$2)) -> 0 | N36: =IF(K36="","",N(L36)-N(M36)) -> 90 | P36: =IF(הגדרות!$B$43="","",הגדרות!$B$43) -> חיות מחמד | Q36: =IF(P36="","",הגדרות!$E$43) -> 150 | R36: =IF(P36="","",SUMIFS(תנועות!$E$6:$E$2005,תנועות!$B$6:$B$2005,P36,תנועות!$A$6:$A$2005,">="&$Z$1,תנועות!$A$6:$A$2005,"<"&$Z$2)) -> 0 | S36: =IF(P36="","",N(Q36)-N(R36)) -> 150
K37: =IF(הגדרות!$B$32="","",הגדרות!$B$32) -> חדר כושר | L37: =IF(K37="","",הגדרות!$E$32) -> 250 | M37: =IF(K37="","",SUMIFS(תנועות!$E$6:$E$2005,תנועות!$B$6:$B$2005,K37,תנועות!$A$6:$A$2005,">="&$Z$1,תנועות!$A$6:$A$2005,"<"&$Z$2)) -> 0 | N37: =IF(K37="","",N(L37)-N(M37)) -> 250 | P37: =IF(הגדרות!$B$44="","",הגדרות!$B$44) -> שונות | Q37: =IF(P37="","",הגדרות!$E$44) -> 300 | R37: =IF(P37="","",SUMIFS(תנועות!$E$6:$E$2005,תנועות!$B$6:$B$2005,P37,תנועות!$A$6:$A$2005,">="&$Z$1,תנועות!$A$6:$A$2005,"<"&$Z$2)) -> 0 | S37: =IF(P37="","",N(Q37)-N(R37)) -> 300
P38: =IF(הגדרות!$B$45="","",הגדרות!$B$45) | Q38: =IF(P38="","",הגדרות!$E$45) | R38: =IF(P38="","",SUMIFS(תנועות!$E$6:$E$2005,תנועות!$B$6:$B$2005,P38,תנועות!$A$6:$A$2005,">="&$Z$1,תנועות!$A$6:$A$2005,"<"&$Z$2)) | S38: =IF(P38="","",N(Q38)-N(R38))
P39: =IF(הגדרות!$B$46="","",הגדרות!$B$46) | Q39: =IF(P39="","",הגדרות!$E$46) | R39: =IF(P39="","",SUMIFS(תנועות!$E$6:$E$2005,תנועות!$B$6:$B$2005,P39,תנועות!$A$6:$A$2005,">="&$Z$1,תנועות!$A$6:$A$2005,"<"&$Z$2)) | S39: =IF(P39="","",N(Q39)-N(R39))
P40: =IF(הגדרות!$B$47="","",הגדרות!$B$47) | Q40: =IF(P40="","",הגדרות!$E$47) | R40: =IF(P40="","",SUMIFS(תנועות!$E$6:$E$2005,תנועות!$B$6:$B$2005,P40,תנועות!$A$6:$A$2005,">="&$Z$1,תנועות!$A$6:$A$2005,"<"&$Z$2)) | S40: =IF(P40="","",N(Q40)-N(R40))
A41: סה"כ | B41: =SUM(B26:B40) -> 25320 | C41: =SUM(C26:C40) -> 0 | D41: =SUM(D26:D40) -> -25320 | F41: סה"כ | G41: =SUM(G26:G40) -> 5400 | H41: =SUM(H26:H40) -> 0 | I41: =SUM(I26:I40) -> 5400 | K41: סה"כ | L41: =SUM(L26:L40) -> 7925 | M41: =SUM(M26:M40) -> 0 | N41: =SUM(N26:N40) -> 7925 | P41: סה"כ | Q41: =SUM(Q26:Q40) -> 7400 | R41: =SUM(R26:R40) -> 0 | S41: =SUM(S26:S40) -> 7400 | U41: סה"כ | V41: =SUM(V26:V40) -> 2300 | W41: =SUM(W26:W40) -> 0 | X41: =SUM(X26:X40) -> 2300

Sheet מרץ
A1: =" 🗓️ "&"מרץ"&" "&הגדרות!$C$3&" – תקציב חודשי" -> 🗓️ מרץ 2026 – תקציב חודשי | Z1: =DATE(הגדרות!$C$3,3,1) -> 46082
A2: התקציב נמשך מלשונית ההגדרות (אפשר לשנות ידנית כאן לחודש הזה בלבד) • הבפועל נמשך מיומן התנועות | Z2: =DATE(הגדרות!$C$3,4,1) -> 46113
Z3: =Z2-Z1 -> 31
A4: 💵 הכנסות החודש | F4: 💸 סה"כ יציאות | K4: 🏦 נשאר בעו"ש | P4: 🐷 שיעור חיסכון | U4: 🛒 ניצול תקציב משתנות
A5: =C8 -> 0 | F5: =SUM(C9:C12) -> 0 | K5: =C13 -> 0 | P5: =IF(C8=0,"–",C9/C8) -> – | U5: =IF(B11=0,"–",C11/B11) -> 0
A7: סיכום החודש | B7: תקציב | C7: בפועל | D7: הפרש | F7: שבוע (משתנות) | G7: תקציב | H7: בפועל | I7: נותר
A8: הכנסות | B8: =B41 -> 25320 | C8: =C41 -> 0 | D8: =C8-B8 -> -25320 | F8: ימים 1–7 | G8: =$B$11*7/$Z$3 -> 1670.9677 | H8: =SUMIFS(תנועות!$E$6:$E$2005,תנועות!$C$6:$C$2005,"הוצאות משתנות",תנועות!$A$6:$A$2005,">="&($Z$1+0),תנועות!$A$6:$A$2005,"<"&$Z$1+7) -> 0 | I8: =G8-H8 -> 1670.9677
A9: תוכניות חיסכון | B9: =G41 -> 5400 | C9: =H41 -> 0 | D9: =B9-C9 -> 5400 | F9: ימים 8–14 | G9: =$B$11*7/$Z$3 -> 1670.9677 | H9: =SUMIFS(תנועות!$E$6:$E$2005,תנועות!$C$6:$C$2005,"הוצאות משתנות",תנועות!$A$6:$A$2005,">="&($Z$1+7),תנועות!$A$6:$A$2005,"<"&$Z$1+14) -> 0 | I9: =G9-H9 -> 1670.9677
A10: חשבונות ומנויים | B10: =L41 -> 7925 | C10: =M41 -> 0 | D10: =B10-C10 -> 7925 | F10: ימים 15–21 | G10: =$B$11*7/$Z$3 -> 1670.9677 | H10: =SUMIFS(תנועות!$E$6:$E$2005,תנועות!$C$6:$C$2005,"הוצאות משתנות",תנועות!$A$6:$A$2005,">="&($Z$1+14),תנועות!$A$6:$A$2005,"<"&$Z$1+21) -> 0 | I10: =G10-H10 -> 1670.9677
A11: הוצאות משתנות | B11: =Q41 -> 7400 | C11: =R41 -> 0 | D11: =B11-C11 -> 7400 | F11: ימים 22–28 | G11: =$B$11*7/$Z$3 -> 1670.9677 | H11: =SUMIFS(תנועות!$E$6:$E$2005,תנועות!$C$6:$C$2005,"הוצאות משתנות",תנועות!$A$6:$A$2005,">="&($Z$1+21),תנועות!$A$6:$A$2005,"<"&$Z$1+28) -> 0 | I11: =G11-H11 -> 1670.9677
A12: חובות | B12: =V41 -> 2300 | C12: =W41 -> 0 | D12: =B12-C12 -> 2300 | F12: ימים 29–סוף | G12: =$B$11*($Z$3-28)/$Z$3 -> 716.12903 | H12: =SUMIFS(תנועות!$E$6:$E$2005,תנועות!$C$6:$C$2005,"הוצאות משתנות",תנועות!$A$6:$A$2005,">="&($Z$1+28),תנועות!$A$6:$A$2005,"<"&$Z$2) -> 0 | I12: =G12-H12 -> 716.12903
A13: נשאר בעו"ש | B13: =B8-SUM(B9:B12) -> 2295 | C13: =C8-SUM(C9:C12) -> 0 | D13: =C13-B13 -> -2295 | F13: סה"כ | G13: =SUM(G8:G12) -> 7400 | H13: =SUM(H8:H12) -> 0 | I13: =SUM(I8:I12) -> 7400
A15: 💡 תקציב שבועי להוצאות משתנות = התקציב החודשי מחולק לפי מספר הימים בכל שבוע. אדום = חריגה מהתקציב.
A24: הכנסות | F24: תוכניות חיסכון | K24: חשבונות ומנויים | P24: הוצאות משתנות | U24: חובות
A25: קטגוריה | B25: תקציב | C25: בפועל | D25: הפרש | F25: קטגוריה | G25: תקציב | H25: בפועל | I25: נותר | K25: קטגוריה | L25: תקציב | M25: בפועל | N25: נותר | P25: קטגוריה | Q25: תקציב | R25: בפועל | S25: נותר | U25: קטגוריה | V25: תקציב | W25: בפועל | X25: נותר
A26: =IF(הגדרות!$B$8="","",הגדרות!$B$8) -> משכורת 1 | B26: =IF(A26="","",הגדרות!$E$8) -> 14000 | C26: =IF(A26="","",SUMIFS(תנועות!$E$6:$E$2005,תנועות!$B$6:$B$2005,A26,תנועות!$A$6:$A$2005,">="&$Z$1,תנועות!$A$6:$A$2005,"<"&$Z$2)) -> 0 | D26: =IF(A26="","",N(C26)-N(B26)) -> -14000 | F26: =IF(הגדרות!$B$16="","",הגדרות!$B$16) -> קרן חירום | G26: =IF(F26="","",הגדרות!$E$16) -> 1500 | H26: =IF(F26="","",SUMIFS(תנועות!$E$6:$E$2005,תנועות!$B$6:$B$2005,F26,תנועות!$A$6:$A$2005,">="&$Z$1,תנועות!$A$6:$A$2005,"<"&$Z$2)) -> 0 | I26: =IF(F26="","",N(G26)-N(H26)) -> 1500 | K26: =IF(הגדרות!$B$21="","",הגדרות!$B$21) -> שכר דירה / משכנתא | L26: =IF(K26="","",הגדרות!$E$21) -> 5200 | M26: =IF(K26="","",SUMIFS(תנועות!$E$6:$E$2005,תנועות!$B$6:$B$2005,K26,תנועות!$A$6:$A$2005,">="&$Z$1,תנועות!$A$6:$A$2005,"<"&$Z$2)) -> 0 | N26: =IF(K26="","",N(L26)-N(M26)) -> 5200 | P26: =IF(הגדרות!$B$33="","",הגדרות!$B$33) -> סופרמרקט | Q26: =IF(P26="","",הגדרות!$E$33) -> 2816.6667 | R26: =IF(P26="","",SUMIFS(תנועות!$E$6:$E$2005,תנועות!$B$6:$B$2005,P26,תנועות!$A$6:$A$2005,">="&$Z$1,תנועות!$A$6:$A$2005,"<"&$Z$2)) -> 0 | S26: =IF(P26="","",N(Q26)-N(R26)) -> 2816.6667 | U26: =IF(הגדרות!$B$48="","",הגדרות!$B$48) -> הלוואת רכב | V26: =IF(U26="","",הגדרות!$E$48) -> 1100 | W26: =IF(U26="","",SUMIFS(תנועות!$E$6:$E$2005,תנועות!$B$6:$B$2005,U26,תנועות!$A$6:$A$2005,">="&$Z$1,תנועות!$A$6:$A$2005,"<"&$Z$2)) -> 0 | X26: =IF(U26="","",N(V26)-N(W26)) -> 1100
A27: =IF(הגדרות!$B$9="","",הגדרות!$B$9) -> משכורת 2 | B27: =IF(A27="","",הגדרות!$E$9) -> 9500 | C27: =IF(A27="","",SUMIFS(תנועות!$E$6:$E$2005,תנועות!$B$6:$B$2005,A27,תנועות!$A$6:$A$2005,">="&$Z$1,תנועות!$A$6:$A$2005,"<"&$Z$2)) -> 0 | D27: =IF(A27="","",N(C27)-N(B27)) -> -9500 | F27: =IF(הגדרות!$B$17="","",הגדרות!$B$17) -> חופשה משפחתית | G27: =IF(F27="","",הגדרות!$E$17) -> 600 | H27: =IF(F27="","",SUMIFS(תנועות!$E$6:$E$2005,תנועות!$B$6:$B$2005,F27,תנועות!$A$6:$A$2005,">="&$Z$1,תנועות!$A$6:$A$2005,"<"&$Z$2)) -> 0 | I27: =IF(F27="","",N(G27)-N(H27)) -> 600 | K27: =IF(הגדרות!$B$22="","",הגדרות!$B$22) -> ארנונה | L27: =IF(K27="","",הגדרות!$E$22) -> 450 | M27: =IF(K27="","",SUMIFS(תנועות!$E$6:$E$2005,תנועות!$B$6:$B$2005,K27,תנועות!$A$6:$A$2005,">="&$Z$1,תנועות!$A$6:$A$2005,"<"&$Z$2)) -> 0 | N27: =IF(K27="","",N(L27)-N(M27)) -> 450 | P27: =IF(הגדרות!$B$34="","",הגדרות!$B$34) -> דלק | Q27: =IF(P27="","",הגדרות!$E$34) -> 600 | R27: =IF(P27="","",SUMIFS(תנועות!$E$6:$E$2005,תנועות!$B$6:$B$2005,P27,תנועות!$A$6:$A$2005,">="&$Z$1,תנועות!$A$6:$A$2005,"<"&$Z$2)) -> 0 | S27: =IF(P27="","",N(Q27)-N(R27)) -> 600 | U27: =IF(הגדרות!$B$49="","",הגדרות!$B$49) -> הלוואה בנקאית | V27: =IF(U27="","",הגדרות!$E$49) -> 800 | W27: =IF(U27="","",SUMIFS(תנועות!$E$6:$E$2005,תנועות!$B$6:$B$2005,U27,תנועות!$A$6:$A$2005,">="&$Z$1,תנועות!$A$6:$A$2005,"<"&$Z$2)) -> 0 | X27: =IF(U27="","",N(V27)-N(W27)) -> 800
A28: =IF(הגדרות!$B$10="","",הגדרות!$B$10) -> עבודה נוספת | B28: =IF(A28="","",הגדרות!$E$10) -> 1500 | C28: =IF(A28="","",SUMIFS(תנועות!$E$6:$E$2005,תנועות!$B$6:$B$2005,A28,תנועות!$A$6:$A$2005,">="&$Z$1,תנועות!$A$6:$A$2005,"<"&$Z$2)) -> 0 | D28: =IF(A28="","",N(C28)-N(B28)) -> -1500 | F28: =IF(הגדרות!$B$18="","",הגדרות!$B$18) -> רכב חדש | G28: =IF(F28="","",הגדרות!$E$18) -> 800 | H28: =IF(F28="","",SUMIFS(תנועות!$E$6:$E$2005,תנועות!$B$6:$B$2005,F28,תנועות!$A$6:$A$2005,">="&$Z$1,תנועות!$A$6:$A$2005,"<"&$Z$2)) -> 0 | I28: =IF(F28="","",N(G28)-N(H28)) -> 800 | K28: =IF(הגדרות!$B$23="","",הגדרות!$B$23) -> חשמל | L28: =IF(K28="","",הגדרות!$E$23) -> 350 | M28: =IF(K28="","",SUMIFS(תנועות!$E$6:$E$2005,תנועות!$B$6:$B$2005,K28,תנועות!$A$6:$A$2005,">="&$Z$1,תנועות!$A$6:$A$2005,"<"&$Z$2)) -> 0 | N28: =IF(K28="","",N(L28)-N(M28)) -> 350 | P28: =IF(הגדרות!$B$35="","",הגדרות!$B$35) -> תחבורה ציבורית וחניה | Q28: =IF(P28="","",הגדרות!$E$35) -> 150 | R28: =IF(P28="","",SUMIFS(תנועות!$E$6:$E$2005,תנועות!$B$6:$B$2005,P28,תנועות!$A$6:$A$2005,">="&$Z$1,תנועות!$A$6:$A$2005,"<"&$Z$2)) -> 0 | S28: =IF(P28="","",N(Q28)-N(R28)) -> 150 | U28: =IF(הגדרות!$B$50="","",הגדרות!$B$50) -> כרטיס אשראי – פריסה | V28: =IF(U28="","",הגדרות!$E$50) -> 400 | W28: =IF(U28="","",SUMIFS(תנועות!$E$6:$E$2005,תנועות!$B$6:$B$2005,U28,תנועות!$A$6:$A$2005,">="&$Z$1,תנועות!$A$6:$A$2005,"<"&$Z$2)) -> 0 | X28: =IF(U28="","",N(V28)-N(W28)) -> 400
A29: =IF(הגדרות!$B$11="","",הגדרות!$B$11) -> קצבת ילדים | B29: =IF(A29="","",הגדרות!$E$11) -> 320 | C29: =IF(A29="","",SUMIFS(תנועות!$E$6:$E$2005,תנועות!$B$6:$B$2005,A29,תנועות!$A$6:$A$2005,">="&$Z$1,תנועות!$A$6:$A$2005,"<"&$Z$2)) -> 0 | D29: =IF(A29="","",N(C29)-N(B29)) -> -320 | F29: =IF(הגדרות!$B$19="","",הגדרות!$B$19) -> דירה | G29: =IF(F29="","",הגדרות!$E$19) -> 1500 | H29: =IF(F29="","",SUMIFS(תנועות!$E$6:$E$2005,תנועות!$B$6:$B$2005,F29,תנועות!$A$6:$A$2005,">="&$Z$1,תנועות!$A$6:$A$2005,"<"&$Z$2)) -> 0 | I29: =IF(F29="","",N(G29)-N(H29)) -> 1500 | K29: =IF(הגדרות!$B$24="","",הגדרות!$B$24) -> מים | L29: =IF(K29="","",הגדרות!$E$24) -> 125 | M29: =IF(K29="","",SUMIFS(תנועות!$E$6:$E$2005,תנועות!$B$6:$B$2005,K29,תנועות!$A$6:$A$2005,">="&$Z$1,תנועות!$A$6:$A$2005,"<"&$Z$2)) -> 0 | N29: =IF(K29="","",N(L29)-N(M29)) -> 125 | P29: =IF(הגדרות!$B$36="","",הגדרות!$B$36) -> מסעדות ובילויים | Q29: =IF(P29="","",הגדרות!$E$36) -> 1083.3333 | R29: =IF(P29="","",SUMIFS(תנועות!$E$6:$E$2005,תנועות!$B$6:$B$2005,P29,תנועות!$A$6:$A$2005,">="&$Z$1,תנועות!$A$6:$A$2005,"<"&$Z$2)) -> 0 | S29: =IF(P29="","",N(Q29)-N(R29)) -> 1083.3333 | U29: =IF(הגדרות!$B$51="","",הגדרות!$B$51) | V29: =IF(U29="","",הגדרות!$E$51) | W29: =IF(U29="","",SUMIFS(תנועות!$E$6:$E$2005,תנועות!$B$6:$B$2005,U29,תנועות!$A$6:$A$2005,">="&$Z$1,תנועות!$A$6:$A$2005,"<"&$Z$2)) | X29: =IF(U29="","",N(V29)-N(W29))
