Workbook

Sheet 📊 תמונת מצב
Y1: =IF(OR($C$5="",$C$5="אוטומטי – החודש האחרון שמולא"),MAX(1,Y2),IFERROR(MATCH($C$5,$X$3:$X$14,0),MAX(1,Y2)))
B2: 📊 תמונת מצב פיננסית | Y2: =MAX('📥 הזנה חודשית'!$C$58:$N$58)
B3: =IF($Y$2=0,"👋 ברוכים הבאים! מלאו את החודש הראשון בלשונית '📥 הזנה חודשית' והלוח יתעורר לחיים","מציג את "&$Y$3&" "&'📥 הזנה חודשית'!$B$3&" • מולאו "&COUNTIF('📥 הזנה חודשית'!$C$58:$N$58,">0")&" מתוך 12 חודשים") | X3: ינואר | Y3: =INDEX($X$3:$X$14,$Y$1)
X4: פברואר | Y4: =IF($Y$1=1,"",INDEX($X$3:$X$14,$Y$1-1))
B5: 📅 חודש לתצוגה | C5: אוטומטי – החודש האחרון שמולא | F5: ← לחצו כדי לבחור חודש. במצב 'אוטומטי' הלוח מציג תמיד את החודש האחרון שמילאתם. | X5: מרץ
X6: אפריל
B7: 💰 הכנסות החודש | E7: 🧾 הוצאות החודש | H7: 🐷 הופקד לחיסכון | K7: 🏦 נשאר בעו"ש | X7: מאי
B8: =INDEX('📥 הזנה חודשית'!$C$53:$N$53,$Y$1) | E8: =INDEX('📥 הזנה חודשית'!$C$54:$N$54,$Y$1) | H8: =INDEX('📥 הזנה חודשית'!$C$55:$N$55,$Y$1) | K8: =INDEX('📥 הזנה חודשית'!$C$56:$N$56,$Y$1) | X8: יוני
B9: =IF($Y$2=0,"—",IF('📥 הזנה חודשית'!$B$53=0,"",IF(INDEX('📥 הזנה חודשית'!$C$53:$N$53,$Y$1)>='📥 הזנה חודשית'!$B$53,"✅ ","⏳ ")&"תכנון: "&"₪"&TEXT('📥 הזנה חודשית'!$B$53,"#,##0"))) | E9: =IF($Y$2=0,"—",IF('📥 הזנה חודשית'!$B$54=0,"",IF(INDEX('📥 הזנה חודשית'!$C$54:$N$54,$Y$1)<='📥 הזנה חודשית'!$B$54,"✅ "&"₪"&TEXT('📥 הזנה חודשית'!$B$54-INDEX('📥 הזנה חודשית'!$C$54:$N$54,$Y$1),"#,##0")&" מתחת לתקציב","⚠️ "&"₪"&TEXT(INDEX('📥 הזנה חודשית'!$C$54:$N$54,$Y$1)-'📥 הזנה חודשית'!$B$54,"#,##0")&" מעל התקציב"))) | H9: =IF($Y$2=0,"—",IF('📥 הזנה חודשית'!$B$55=0,"",IF(INDEX('📥 הזנה חודשית'!$C$55:$N$55,$Y$1)>='📥 הזנה חודשית'!$B$55,"✅ עמדת ביעד ","⏳ יעד: ")&"₪"&TEXT('📥 הזנה חודשית'!$B$55,"#,##0"))) | K9: =IF($Y$2=0,"—",IF($Y$1=1,"החודש הראשון בשנה",IF(INDEX('📥 הזנה חודשית'!$C$56:$N$56,$Y$1)>=IF($Y$1=1,0,INDEX('📥 הזנה חודשית'!$C$56:$N$56,$Y$1-1)),"▲ ","▼ ")&"₪"&TEXT(ABS(INDEX('📥 הזנה חודשית'!$C$56:$N$56,$Y$1)-IF($Y$1=1,0,INDEX('📥 הזנה חודשית'!$C$56:$N$56,$Y$1-1))),"#,##0")&" לעומת "&$Y$4)) | X9: יולי
X10: אוגוסט | Z10: =SUMPRODUCT(('📥 הזנה חודשית'!$C$4:$N$4<=$Y$1)*'📥 הזנה חודשית'!$C$53:$N$53)
B11: 📅 הכנסות מתחילת השנה | E11: 📅 הוצאות מתחילת השנה | H11: 📅 נחסך מתחילת השנה | K11: 🎯 שיעור חיסכון שנתי | X11: ספטמבר | Z11: =SUMPRODUCT(('📥 הזנה חודשית'!$C$4:$N$4<=$Y$1)*'📥 הזנה חודשית'!$C$54:$N$54)
B12: =$Z$10 | E12: =$Z$11 | H12: =$Z$12 | K12: =IF($Z$10=0,0,$Z$12/$Z$10) | X12: אוקטובר | Z12: =SUMPRODUCT(('📥 הזנה חודשית'!$C$4:$N$4<=$Y$1)*'📥 הזנה חודשית'!$C$55:$N$55)
B13: =IF($Y$2=0,"—","ממוצע לחודש: "&"₪"&TEXT($Z$10/$Y$1,"#,##0")) | E13: =IF($Y$2=0,"—","ממוצע לחודש: "&"₪"&TEXT($Z$11/$Y$1,"#,##0")) | H13: =IF($Y$2=0,"—","בקצב הזה: כ-"&"₪"&TEXT($Z$12/$Y$1*12,"#,##0")&" עד סוף השנה") | K13: =IF($Y$2=0,"—",IF($Z$10=0,"",IF($Z$12/$Z$10>=0.2,"מצוין! מעל היעד המומלץ (20%) 🎉",IF($Z$12/$Z$10>=0.1,"טוב – היעד המומלץ הוא 20%","כדאי לשאוף ל-10%–20% מההכנסה")))) | X13: נובמבר | Z13: =SUMPRODUCT(('📥 הזנה חודשית'!$C$4:$N$4<=$Y$1)*'📥 הזנה חודשית'!$C$56:$N$56)
X14: דצמבר
B15: ⚖️ תקציב מול בפועל – החודש | H15: 💡 תובנות אוטומטיות
B16: סעיף | C16: תקציב | D16: בפועל | E16: הפרש | F16: ניצול | G16: סטטוס | H16: מה המספרים אומרים החודש
B17: הכנסות | C17: ='📥 הזנה חודשית'!$B$6 | D17: =INDEX('📥 הזנה חודשית'!$C$6:$N$6,$Y$1) | E17: =IF($Y$2=0,"",D17-C17) | F17: =IF(C17=0,"",REPT("█",ROUND(MAX(0,MIN(1,D17/C17))*8,0))&REPT("░",8-ROUND(MAX(0,MIN(1,D17/C17))*8,0))) | G17: =IF($Y$2=0,"",IF(C17=0,"",IF(D17>=C17,"✅ הושג",TEXT(D17/C17,"0%")&" מהיעד"))) | H17: =IF($Y$2=0,"👋 עוד לא הוזנו נתונים – פתחו את '📥 הזנה חודשית' ומלאו את העמודה של החודש.",IF(INDEX('📥 הזנה חודשית'!$C$53:$N$53,$Y$1)=0,"ℹ️ לא הוזנו הכנסות בחודש הזה.","🐷 החודש חסכתם "&TEXT(INDEX('📥 הזנה חודשית'!$C$55:$N$55,$Y$1)/INDEX('📥 הזנה חודשית'!$C$53:$N$53,$Y$1),"0%")&" מההכנסה"&IF(INDEX('📥 הזנה חודשית'!$C$55:$N$55,$Y$1)/INDEX('📥 הזנה חודשית'!$C$53:$N$53,$Y$1)>=0.2," – מצוין! 🎉",IF(INDEX('📥 הזנה חודשית'!$C$55:$N$55,$Y$1)/INDEX('📥 הזנה חודשית'!$C$53:$N$53,$Y$1)>=0.1," – יפה, היעד המומלץ הוא 20% 👍"," – נסו להגדיל לפחות ל-10%"))))
B18: חיסכון | C18: ='📥 הזנה חודשית'!$B$14 | D18: =INDEX('📥 הזנה חודשית'!$C$14:$N$14,$Y$1) | E18: =IF($Y$2=0,"",D18-C18) | F18: =IF(C18=0,"",REPT("█",ROUND(MAX(0,MIN(1,D18/C18))*8,0))&REPT("░",8-ROUND(MAX(0,MIN(1,D18/C18))*8,0))) | G18: =IF($Y$2=0,"",IF(C18=0,"",IF(D18>=C18,"✅ הושג",TEXT(D18/C18,"0%")&" מהיעד"))) | H18: =IF($Y$2=0,"",IF(SUMPRODUCT(($AB$20:$AB$44>$AA$20:$AA$44)*($AA$20:$AA$44>0))=0,"✅ כל קטגוריות ההוצאה עמדו בתקציב החודש – כל הכבוד!","⚠️ "&SUMPRODUCT(($AB$20:$AB$44>$AA$20:$AA$44)*($AA$20:$AA$44>0))&" קטגוריות חרגו מהתקציב החודש (מסומנות באדום בלשונית ההזנה)"))
B19: חשבונות ומנויים | C19: ='📥 הזנה חודשית'!$B$21 | D19: =INDEX('📥 הזנה חודשית'!$C$21:$N$21,$Y$1) | E19: =IF($Y$2=0,"",C19-D19) | F19: =IF(C19=0,"",REPT("█",ROUND(MAX(0,MIN(1,D19/C19))*8,0))&REPT("░",8-ROUND(MAX(0,MIN(1,D19/C19))*8,0))) | G19: =IF($Y$2=0,"",IF(C19=0,"",IF(D19<=C19,"✅ בתקציב","🔴 חריגה"))) | H19: =IF(C27="","","💸 ההוצאה הגדולה ביותר: "&C27&" – "&"₪"&TEXT(E27,"#,##0")&" ("&TEXT(F27,"0%")&" מכלל ההוצאות)")
B20: הוצאות משתנות | C20: ='📥 הזנה חודשית'!$B$33 | D20: =INDEX('📥 הזנה חודשית'!$C$33:$N$33,$Y$1) | E20: =IF($Y$2=0,"",C20-D20) | F20: =IF(C20=0,"",REPT("█",ROUND(MAX(0,MIN(1,D20/C20))*8,0))&REPT("░",8-ROUND(MAX(0,MIN(1,D20/C20))*8,0))) | G20: =IF($Y$2=0,"",IF(C20=0,"",IF(D20<=C20,"✅ בתקציב","🔴 חריגה"))) | H20: =IF(OR($Y$1=1,$Y$2=0,IF($Y$1=1,0,INDEX('📥 הזנה חודשית'!$C$54:$N$54,$Y$1-1))=0),"",IF(INDEX('📥 הזנה חודשית'!$C$54:$N$54,$Y$1)>IF($Y$1=1,0,INDEX('📥 הזנה חודשית'!$C$54:$N$54,$Y$1-1)),"📈 ההוצאות עלו ב-","📉 ההוצאות ירדו ב-")&TEXT(ABS(INDEX('📥 הזנה חודשית'!$C$54:$N$54,$Y$1)/IF($Y$1=1,0,INDEX('📥 הזנה חודשית'!$C$54:$N$54,$Y$1-1))-1),"0%")&" לעומת "&$Y$4) | Z20: ='📥 הזנה חודשית'!$A$22&"" | AA20: =N('📥 הזנה חודשית'!$B$22) | AB20: =N(INDEX('📥 הזנה חודשית'!$C$22:$N$22,$Y$1)) | AC20: =IF(AND(Z20<>"",AB20>0),AB20+ROW()/1000000,0)
B21: חובות | C21: ='📥 הזנה חודשית'!$B$46 | D21: =INDEX('📥 הזנה חודשית'!$C$46:$N$46,$Y$1) | E21: =IF($Y$2=0,"",C21-D21) | F21: =IF(C21=0,"",REPT("█",ROUND(MAX(0,MIN(1,D21/C21))*8,0))&REPT("░",8-ROUND(MAX(0,MIN(1,D21/C21))*8,0))) | G21: =IF($Y$2=0,"",IF(C21=0,"",IF(D21<=C21,"✅ בתקציב","🔴 חריגה"))) | H21: =IF($Y$2=0,"","🔮 תחזית לסוף השנה (לפי הקצב עד עכשיו): הכנסות "&"₪"&TEXT($Z$10/$Y$1*12,"#,##0")&" • חיסכון "&"₪"&TEXT($Z$12/$Y$1*12,"#,##0")) | Z21: ='📥 הזנה חודשית'!$A$23&"" | AA21: =N('📥 הזנה חודשית'!$B$23) | AB21: =N(INDEX('📥 הזנה חודשית'!$C$23:$N$23,$Y$1)) | AC21: =IF(AND(Z21<>"",AB21>0),AB21+ROW()/1000000,0)
B22: 🏦 נשאר בעו"ש | C22: ='📥 הזנה חודשית'!$B$56 | D22: =INDEX('📥 הזנה חודשית'!$C$56:$N$56,$Y$1) | E22: =D22-C22 | Z22: ='📥 הזנה חודשית'!$A$24&"" | AA22: =N('📥 הזנה חודשית'!$B$24) | AB22: =N(INDEX('📥 הזנה חודשית'!$C$24:$N$24,$Y$1)) | AC22: =IF(AND(Z22<>"",AB22>0),AB22+ROW()/1000000,0)
Z23: ='📥 הזנה חודשית'!$A$25&"" | AA23: =N('📥 הזנה חודשית'!$B$25) | AB23: =N(INDEX('📥 הזנה חודשית'!$C$25:$N$25,$Y$1)) | AC23: =IF(AND(Z23<>"",AB23>0),AB23+ROW()/1000000,0)
Z24: ='📥 הזנה חודשית'!$A$26&"" | AA24: =N('📥 הזנה חודשית'!$B$26) | AB24: =N(INDEX('📥 הזנה חודשית'!$C$26:$N$26,$Y$1)) | AC24: =IF(AND(Z24<>"",AB24>0),AB24+ROW()/1000000,0)
B25: 🏆 5 ההוצאות הגדולות של החודש | Z25: ='📥 הזנה חודשית'!$A$27&"" | AA25: =N('📥 הזנה חודשית'!$B$27) | AB25: =N(INDEX('📥 הזנה חודשית'!$C$27:$N$27,$Y$1)) | AC25: =IF(AND(Z25<>"",AB25>0),AB25+ROW()/1000000,0)
B26: # | C26: קטגוריה | E26: סכום | F26: % מההוצאות | G26: מול תקציב | Z26: ='📥 הזנה חודשית'!$A$28&"" | AA26: =N('📥 הזנה חודשית'!$B$28) | AB26: =N(INDEX('📥 הזנה חודשית'!$C$28:$N$28,$Y$1)) | AC26: =IF(AND(Z26<>"",AB26>0),AB26+ROW()/1000000,0)
B27: 🥇 | C27: =IF(LARGE($AC$20:$AC$44,1)<=0,"",INDEX($Z$20:$Z$44,MATCH(LARGE($AC$20:$AC$44,1),$AC$20:$AC$44,0))) | E27: =IF(LARGE($AC$20:$AC$44,1)<=0,"",INDEX($AB$20:$AB$44,MATCH(LARGE($AC$20:$AC$44,1),$AC$20:$AC$44,0))) | F27: =IF(OR(E27="",N(D19)+N(D20)+N(D21)=0),"",E27/(D19+D20+D21)) | G27: =IF(E27="","",IF(INDEX($AA$20:$AA$44,MATCH(LARGE($AC$20:$AC$44,1),$AC$20:$AC$44,0))=0,"—",IF(E27<=INDEX($AA$20:$AA$44,MATCH(LARGE($AC$20:$AC$44,1),$AC$20:$AC$44,0)),"✅ בתקציב","🔴 +"&TEXT(E27-INDEX($AA$20:$AA$44,MATCH(LARGE($AC$20:$AC$44,1),$AC$20:$AC$44,0)),"#,##0")))) | Z27: ='📥 הזנה חודשית'!$A$29&"" | AA27: =N('📥 הזנה חודשית'!$B$29) | AB27: =N(INDEX('📥 הזנה חודשית'!$C$29:$N$29,$Y$1)) | AC27: =IF(AND(Z27<>"",AB27>0),AB27+ROW()/1000000,0)
B28: 🥈 | C28: =IF(LARGE($AC$20:$AC$44,2)<=0,"",INDEX($Z$20:$Z$44,MATCH(LARGE($AC$20:$AC$44,2),$AC$20:$AC$44,0))) | E28: =IF(LARGE($AC$20:$AC$44,2)<=0,"",INDEX($AB$20:$AB$44,MATCH(LARGE($AC$20:$AC$44,2),$AC$20:$AC$44,0))) | F28: =IF(OR(E28="",N(D19)+N(D20)+N(D21)=0),"",E28/(D19+D20+D21)) | G28: =IF(E28="","",IF(INDEX($AA$20:$AA$44,MATCH(LARGE($AC$20:$AC$44,2),$AC$20:$AC$44,0))=0,"—",IF(E28<=INDEX($AA$20:$AA$44,MATCH(LARGE($AC$20:$AC$44,2),$AC$20:$AC$44,0)),"✅ בתקציב","🔴 +"&TEXT(E28-INDEX($AA$20:$AA$44,MATCH(LARGE($AC$20:$AC$44,2),$AC$20:$AC$44,0)),"#,##0")))) | Z28: ='📥 הזנה חודשית'!$A$30&"" | AA28: =N('📥 הזנה חודשית'!$B$30) | AB28: =N(INDEX('📥 הזנה חודשית'!$C$30:$N$30,$Y$1)) | AC28: =IF(AND(Z28<>"",AB28>0),AB28+ROW()/1000000,0)
B29: 🥉 | C29: =IF(LARGE($AC$20:$AC$44,3)<=0,"",INDEX($Z$20:$Z$44,MATCH(LARGE($AC$20:$AC$44,3),$AC$20:$AC$44,0))) | E29: =IF(LARGE($AC$20:$AC$44,3)<=0,"",INDEX($AB$20:$AB$44,MATCH(LARGE($AC$20:$AC$44,3),$AC$20:$AC$44,0))) | F29: =IF(OR(E29="",N(D19)+N(D20)+N(D21)=0),"",E29/(D19+D20+D21)) | G29: =IF(E29="","",IF(INDEX($AA$20:$AA$44,MATCH(LARGE($AC$20:$AC$44,3),$AC$20:$AC$44,0))=0,"—",IF(E29<=INDEX($AA$20:$AA$44,MATCH(LARGE($AC$20:$AC$44,3),$AC$20:$AC$44,0)),"✅ בתקציב","🔴 +"&TEXT(E29-INDEX($AA$20:$AA$44,MATCH(LARGE($AC$20:$AC$44,3),$AC$20:$AC$44,0)),"#,##0")))) | Z29: ='📥 הזנה חודשית'!$A$31&"" | AA29: =N('📥 הזנה חודשית'!$B$31) | AB29: =N(INDEX('📥 הזנה חודשית'!$C$31:$N$31,$Y$1)) | AC29: =IF(AND(Z29<>"",AB29>0),AB29+ROW()/1000000,0)
B30: 4 | C30: =IF(LARGE($AC$20:$AC$44,4)<=0,"",INDEX($Z$20:$Z$44,MATCH(LARGE($AC$20:$AC$44,4),$AC$20:$AC$44,0))) | E30: =IF(LARGE($AC$20:$AC$44,4)<=0,"",INDEX($AB$20:$AB$44,MATCH(LARGE($AC$20:$AC$44,4),$AC$20:$AC$44,0))) | F30: =IF(OR(E30="",N(D19)+N(D20)+N(D21)=0),"",E30/(D19+D20+D21)) | G30: =IF(E30="","",IF(INDEX($AA$20:$AA$44,MATCH(LARGE($AC$20:$AC$44,4),$AC$20:$AC$44,0))=0,"—",IF(E30<=INDEX($AA$20:$AA$44,MATCH(LARGE($AC$20:$AC$44,4),$AC$20:$AC$44,0)),"✅ בתקציב","🔴 +"&TEXT(E30-INDEX($AA$20:$AA$44,MATCH(LARGE($AC$20:$AC$44,4),$AC$20:$AC$44,0)),"#,##0")))) | Z30: ='📥 הזנה חודשית'!$A$34&"" | AA30: =N('📥 הזנה חודשית'!$B$34) | AB30: =N(INDEX('📥 הזנה חודשית'!$C$34:$N$34,$Y$1)) | AC30: =IF(AND(Z30<>"",AB30>0),AB30+ROW()/1000000,0)
B31: 5 | C31: =IF(LARGE($AC$20:$AC$44,5)<=0,"",INDEX($Z$20:$Z$44,MATCH(LARGE($AC$20:$AC$44,5),$AC$20:$AC$44,0))) | E31: =IF(LARGE($AC$20:$AC$44,5)<=0,"",INDEX($AB$20:$AB$44,MATCH(LARGE($AC$20:$AC$44,5),$AC$20:$AC$44,0))) | F31: =IF(OR(E31="",N(D19)+N(D20)+N(D21)=0),"",E31/(D19+D20+D21)) | G31: =IF(E31="","",IF(INDEX($AA$20:$AA$44,MATCH(LARGE($AC$20:$AC$44,5),$AC$20:$AC$44,0))=0,"—",IF(E31<=INDEX($AA$20:$AA$44,MATCH(LARGE($AC$20:$AC$44,5),$AC$20:$AC$44,0)),"✅ בתקציב","🔴 +"&TEXT(E31-INDEX($AA$20:$AA$44,MATCH(LARGE($AC$20:$AC$44,5),$AC$20:$AC$44,0)),"#,##0")))) | Z31: ='📥 הזנה חודשית'!$A$35&"" | AA31: =N('📥 הזנה חודשית'!$B$35) | AB31: =N(INDEX('📥 הזנה חודשית'!$C$35:$N$35,$Y$1)) | AC31: =IF(AND(Z31<>"",AB31>0),AB31+ROW()/1000000,0)
Z32: ='📥 הזנה חודשית'!$A$36&"" | AA32: =N('📥 הזנה חודשית'!$B$36) | AB32: =N(INDEX('📥 הזנה חודשית'!$C$36:$N$36,$Y$1)) | AC32: =IF(AND(Z32<>"",AB32>0),AB32+ROW()/1000000,0)
Z33: ='📥 הזנה חודשית'!$A$37&"" | AA33: =N('📥 הזנה חודשית'!$B$37) | AB33: =N(INDEX('📥 הזנה חודשית'!$C$37:$N$37,$Y$1)) | AC33: =IF(AND(Z33<>"",AB33>0),AB33+ROW()/1000000,0)
Z34: ='📥 הזנה חודשית'!$A$38&"" | AA34: =N('📥 הזנה חודשית'!$B$38) | AB34: =N(INDEX('📥 הזנה חודשית'!$C$38:$N$38,$Y$1)) | AC34: =IF(AND(Z34<>"",AB34>0),AB34+ROW()/1000000,0)
Z35: ='📥 הזנה חודשית'!$A$39&"" | AA35: =N('📥 הזנה חודשית'!$B$39) | AB35: =N(INDEX('📥 הזנה חודשית'!$C$39:$N$39,$Y$1)) | AC35: =IF(AND(Z35<>"",AB35>0),AB35+ROW()/1000000,0)
Z36: ='📥 הזנה חודשית'!$A$40&"" | AA36: =N('📥 הזנה חודשית'!$B$40) | AB36: =N(INDEX('📥 הזנה חודשית'!$C$40:$N$40,$Y$1)) | AC36: =IF(AND(Z36<>"",AB36>0),AB36+ROW()/1000000,0)
Z37: ='📥 הזנה חודשית'!$A$41&"" | AA37: =N('📥 הזנה חודשית'!$B$41) | AB37: =N(INDEX('📥 הזנה חודשית'!$C$41:$N$41,$Y$1)) | AC37: =IF(AND(Z37<>"",AB37>0),AB37+ROW()/1000000,0)
Z38: ='📥 הזנה חודשית'!$A$42&"" | AA38: =N('📥 הזנה חודשית'!$B$42) | AB38: =N(INDEX('📥 הזנה חודשית'!$C$42:$N$42,$Y$1)) | AC38: =IF(AND(Z38<>"",AB38>0),AB38+ROW()/1000000,0)
Z39: ='📥 הזנה חודשית'!$A$43&"" | AA39: =N('📥 הזנה חודשית'!$B$43) | AB39: =N(INDEX('📥 הזנה חודשית'!$C$43:$N$43,$Y$1)) | AC39: =IF(AND(Z39<>"",AB39>0),AB39+ROW()/1000000,0)
Z40: ='📥 הזנה חודשית'!$A$44&"" | AA40: =N('📥 הזנה חודשית'!$B$44) | AB40: =N(INDEX('📥 הזנה חודשית'!$C$44:$N$44,$Y$1)) | AC40: =IF(AND(Z40<>"",AB40>0),AB40+ROW()/1000000,0)
...

Sheet 📥 הזנה חודשית
A1: 📥 הזנה חודשית
A2: פעם בחודש: ממלאים את העמודה של החודש עם הסכומים מדף הבנק ומפירוט האשראי. כל השאר מתעדכן לבד ✨
A3: שנת התקציב | B3: 2026 | D3: 💡 תאים בצבע שמנת = להזנה. אפשר לשנות שמות קטגוריות ולמלא שורות ריקות – הכל מתעדכן אוטומטית.
C4: 1 | D4: 2 | E4: 3 | F4: 4 | G4: 5 | H4: 6 | I4: 7 | J4: 8 | K4: 9 | L4: 10 | M4: 11 | N4: 12
A5: קטגוריה | B5: תקציב חודשי | C5: ינואר | D5: פברואר | E5: מרץ | F5: אפריל | G5: מאי | H5: יוני | I5: יולי | J5: אוגוסט | K5: ספטמבר | L5: אוקטובר | M5: נובמבר | N5: דצמבר | O5: סה"כ שנתי | P5: ממוצע לחודש
A6: 💰 הכנסות | B6: =SUM(B7:B12) | C6: =SUM(C7:C12) | D6: =SUM(D7:D12) | E6: =SUM(E7:E12) | F6: =SUM(F7:F12) | G6: =SUM(G7:G12) | H6: =SUM(H7:H12) | I6: =SUM(I7:I12) | ... P6: =SUM(P7:P12)
A7: משכורת 1 | B7: 14000 | C7: 14000 | D7: 14000 | E7: 14000 | F7: 14000 | G7: 14000 | H7: 14000 | I7: 14000 | J7: 14000 | K7: 14000 | O7: =SUM(C7:N7) | P7: =IF(COUNT(C7:N7)=0,0,AVERAGE(C7:N7))
A8: משכורת 2 | B8: 9500 | C8: 9500 | D8: 9500 | E8: 9500 | F8: 9500 | G8: 9500 | H8: 9500 | I8: 9500 | J8: 9500 | K8: 9500 | O8: =SUM(C8:N8) | P8: =IF(COUNT(C8:N8)=0,0,AVERAGE(C8:N8))
A9: עבודה נוספת / בונוסים | B9: 1000 | C9: 780 | D9: 470 | E9: 1370 | F9: 2830 | G9: 1160 | H9: 860 | I9: 300 | J9: 1110 | K9: 270 | O9: =SUM(C9:N9) | P9: =IF(COUNT(C9:N9)=0,0,AVERAGE(C9:N9))
A10: קצבאות | B10: 320 | C10: 320 | D10: 320 | E10: 320 | F10: 320 | G10: 320 | H10: 320 | I10: 320 | J10: 320 | K10: 320 | O10: =SUM(C10:N10) | P10: =IF(COUNT(C10:N10)=0,0,AVERAGE(C10:N10))
A11: הכנסות אחרות | B11: 0 | C11: 130 | D11: 20 | E11: 30 | F11: 130 | G11: 250 | H11: 40 | I11: 70 | J11: 190 | K11: 280 | O11: =SUM(C11:N11) | P11: =IF(COUNT(C11:N11)=0,0,AVERAGE(C11:N11))
O12: =SUM(C12:N12) | P12: =IF(COUNT(C12:N12)=0,0,AVERAGE(C12:N12))
A14: 🐷 חיסכון | B14: =SUM(B15:B19) | C14: =SUM(C15:C19) | D14: =SUM(D15:D19) | E14: =SUM(E15:E19) | F14: =SUM(F15:F19) | G14: =SUM(G15:G19) | H14: =SUM(H15:H19) | I14: =SUM(I15:I19) | ... P14: =SUM(P15:P19)
A15: קרן חירום | B15: 1500 | C15: 1500 | D15: 1500 | E15: 1500 | F15: 1500 | G15: 1500 | H15: 1500 | I15: 1500 | J15: 1500 | K15: 1500 | O15: =SUM(C15:N15) | P15: =IF(COUNT(C15:N15)=0,0,AVERAGE(C15:N15))
A16: חופשה משפחתית | B16: 600 | C16: 600 | D16: 600 | E16: 600 | F16: 600 | G16: 600 | H16: 600 | I16: 600 | J16: 600 | K16: 600 | O16: =SUM(C16:N16) | P16: =IF(COUNT(C16:N16)=0,0,AVERAGE(C16:N16))
A17: רכב חדש | B17: 800 | C17: 770 | D17: 720 | E17: 890 | F17: 610 | G17: 860 | H17: 690 | I17: 640 | J17: 640 | K17: 690 | O17: =SUM(C17:N17) | P17: =IF(COUNT(C17:N17)=0,0,AVERAGE(C17:N17))
A18: דירה | B18: 1500 | C18: 1500 | D18: 1500 | E18: 1500 | F18: 1500 | G18: 1500 | H18: 1500 | I18: 1500 | J18: 1500 | K18: 1500 | O18: =SUM(C18:N18) | P18: =IF(COUNT(C18:N18)=0,0,AVERAGE(C18:N18))
A19: השקעות | B19: 1000 | C19: 1190 | D19: 810 | E19: 1050 | F19: 1080 | G19: 920 | H19: 1030 | I19: 740 | J19: 740 | K19: 820 | O19: =SUM(C19:N19) | P19: =IF(COUNT(C19:N19)=0,0,AVERAGE(C19:N19))
A21: 🧾 חשבונות ומנויים | B21: =SUM(B22:B31) | C21: =SUM(C22:C31) | D21: =SUM(D22:D31) | E21: =SUM(E22:E31) | F21: =SUM(F22:F31) | G21: =SUM(G22:G31) | H21: =SUM(H22:H31) | I21: =SUM(I22:I31) | ... P21: =SUM(P22:P31)
A22: שכר דירה / משכנתא | B22: 5200 | C22: 5200 | D22: 5200 | E22: 5200 | F22: 5200 | G22: 5200 | H22: 5200 | I22: 5200 | J22: 5200 | K22: 5200 | O22: =SUM(C22:N22) | P22: =IF(COUNT(C22:N22)=0,0,AVERAGE(C22:N22))
A23: ארנונה | B23: 450 | C23: 450 | D23: 450 | E23: 450 | F23: 450 | G23: 450 | H23: 450 | I23: 450 | J23: 450 | K23: 450 | O23: =SUM(C23:N23) | P23: =IF(COUNT(C23:N23)=0,0,AVERAGE(C23:N23))
A24: חשמל | B24: 380 | C24: 420 | D24: 360 | E24: 340 | F24: 400 | G24: 370 | H24: 330 | I24: 450 | J24: 430 | K24: 320 | O24: =SUM(C24:N24) | P24: =IF(COUNT(C24:N24)=0,0,AVERAGE(C24:N24))
A25: מים וגז | B25: 180 | C25: 190 | D25: 180 | E25: 210 | F25: 200 | G25: 160 | H25: 220 | I25: 150 | J25: 170 | K25: 200 | O25: =SUM(C25:N25) | P25: =IF(COUNT(C25:N25)=0,0,AVERAGE(C25:N25))
A26: ועד בית | B26: 250 | C26: 250 | D26: 250 | E26: 250 | F26: 250 | G26: 250 | H26: 250 | I26: 250 | J26: 250 | K26: 250 | O26: =SUM(C26:N26) | P26: =IF(COUNT(C26:N26)=0,0,AVERAGE(C26:N26))
A27: תקשורת (אינטרנט + סלולר) | B27: 300 | C27: 300 | D27: 300 | E27: 300 | F27: 300 | G27: 300 | H27: 300 | I27: 300 | J27: 300 | K27: 300 | O27: =SUM(C27:N27) | P27: =IF(COUNT(C27:N27)=0,0,AVERAGE(C27:N27))
A28: ביטוחים | B28: 850 | C28: 850 | D28: 850 | E28: 850 | F28: 850 | G28: 850 | H28: 850 | I28: 850 | J28: 850 | K28: 850 | O28: =SUM(C28:N28) | P28: =IF(COUNT(C28:N28)=0,0,AVERAGE(C28:N28))
A29: מנויים וסטרימינג | B29: 140 | C29: 140 | D29: 140 | E29: 140 | F29: 140 | G29: 140 | H29: 140 | I29: 140 | J29: 140 | K29: 140 | O29: =SUM(C29:N29) | P29: =IF(COUNT(C29:N29)=0,0,AVERAGE(C29:N29))
A30: חינוך וחוגים | B30: 900 | C30: 860 | D30: 920 | E30: 850 | F30: 950 | G30: 960 | H30: 930 | I30: 980 | J30: 890 | K30: 950 | O30: =SUM(C30:N30) | P30: =IF(COUNT(C30:N30)=0,0,AVERAGE(C30:N30))
O31: =SUM(C31:N31) | P31: =IF(COUNT(C31:N31)=0,0,AVERAGE(C31:N31))
A33: 🛒 הוצאות משתנות | B33: =SUM(B34:B44) | C33: =SUM(C34:C44) | D33: =SUM(D34:D44) | E33: =SUM(E34:E44) | F33: =SUM(F34:F44) | G33: =SUM(G34:G44) | H33: =SUM(H34:H44) | I33: =SUM(I34:I44) | ... P33: =SUM(P34:P44)
A34: סופרמרקט | B34: 2800 | C34: 2970 | D34: 2960 | E34: 2870 | F34: 3140 | G34: 3210 | H34: 2880 | I34: 3010 | J34: 2590 | K34: 3040 | O34: =SUM(C34:N34) | P34: =IF(COUNT(C34:N34)=0,0,AVERAGE(C34:N34))
A35: דלק ותחבורה | B35: 750 | C35: 800 | D35: 910 | E35: 860 | F35: 700 | G35: 730 | H35: 810 | I35: 620 | J35: 750 | K35: 660 | O35: =SUM(C35:N35) | P35: =IF(COUNT(C35:N35)=0,0,AVERAGE(C35:N35))
A36: מסעדות ובילויים | B36: 900 | C36: 720 | D36: 690 | E36: 1110 | F36: 730 | G36: 800 | H36: 880 | I36: 1170 | J36: 700 | K36: 920 | O36: =SUM(C36:N36) | P36: =IF(COUNT(C36:N36)=0,0,AVERAGE(C36:N36))
A37: ביגוד והנעלה | B37: 400 | C37: 410 | D37: 610 | E37: 570 | F37: 600 | G37: 250 | H37: 330 | I37: 300 | J37: 610 | K37: 650 | O37: =SUM(C37:N37) | P37: =IF(COUNT(C37:N37)=0,0,AVERAGE(C37:N37))
A38: בריאות ותרופות | B38: 200 | C38: 100 | D38: 100 | E38: 120 | F38: 120 | G38: 180 | H38: 200 | I38: 120 | J38: 60 | K38: 160 | O38: =SUM(C38:N38) | P38: =IF(COUNT(C38:N38)=0,0,AVERAGE(C38:N38))
A39: טיפוח | B39: 200 | C39: 170 | D39: 200 | E39: 260 | F39: 220 | G39: 190 | H39: 210 | I39: 220 | J39: 120 | K39: 250 | O39: =SUM(C39:N39) | P39: =IF(COUNT(C39:N39)=0,0,AVERAGE(C39:N39))
A40: מתנות ואירועים | B40: 300 | C40: 470 | D40: 520 | E40: 480 | F40: 720 | G40: 280 | H40: 130 | I40: 1030 | J40: 110 | K40: 110 | O40: =SUM(C40:N40) | P40: =IF(COUNT(C40:N40)=0,0,AVERAGE(C40:N40))
A41: בית ותחזוקה | B41: 300 | C41: 150 | D41: 130 | E41: 210 | F41: 80 | G41: 60 | H41: 130 | I41: 100 | J41: 220 | K41: 70 | O41: =SUM(C41:N41) | P41: =IF(COUNT(C41:N41)=0,0,AVERAGE(C41:N41))
A42: חופשות ופנאי | B42: 500 | C42: 820 | D42: 560 | E42: 100 | F42: 530 | G42: 300 | H42: 310 | I42: 190 | J42: 800 | K42: 940 | O42: =SUM(C42:N42) | P42: =IF(COUNT(C42:N42)=0,0,AVERAGE(C42:N42))
A43: שונות | B43: 300 | C43: 300 | D43: 310 | E43: 190 | F43: 190 | G43: 260 | H43: 240 | I43: 410 | J43: 210 | K43: 170 | O43: =SUM(C43:N43) | P43: =IF(COUNT(C43:N43)=0,0,AVERAGE(C43:N43))
...

Sheet 📈 מגמות
B2: 📈 מגמות לאורך השנה
B3: איך הכסף זז מחודש לחודש – הכנסות, הוצאות, חיסכון ומפת חום של כל קטגוריה
B5: 📅 סיכום לפי חודש
B6: חודש | C6: הכנסות | D6: חשבונות ומנויים | E6: הוצאות משתנות | F6: חובות | G6: סה"כ הוצאות | H6: חיסכון | I6: נשאר בעו"ש | J6: שיעור חיסכון | K6: חיסכון מצטבר
B7: ינואר | C7: =IF('📥 הזנה חודשית'!C$58=0,"",'📥 הזנה חודשית'!C53) | D7: =IF('📥 הזנה חודשית'!C$58=0,"",'📥 הזנה חודשית'!C21) | E7: =IF('📥 הזנה חודשית'!C$58=0,"",'📥 הזנה חודשית'!C33) | F7: =IF('📥 הזנה חודשית'!C$58=0,"",'📥 הזנה חודשית'!C46) | G7: =IF('📥 הזנה חודשית'!C$58=0,"",'📥 הזנה חודשית'!C54) | H7: =IF('📥 הזנה חודשית'!C$58=0,"",'📥 הזנה חודשית'!C55) | I7: =IF('📥 הזנה חודשית'!C$58=0,"",'📥 הזנה חודשית'!C56) | J7: =IF(OR(C7="",N(C7)=0),"",H7/C7) | K7: =IF(H7="","",SUM(H$7:H7))
B8: פברואר | C8: =IF('📥 הזנה חודשית'!D$58=0,"",'📥 הזנה חודשית'!D53) | D8: =IF('📥 הזנה חודשית'!D$58=0,"",'📥 הזנה חודשית'!D21) | E8: =IF('📥 הזנה חודשית'!D$58=0,"",'📥 הזנה חודשית'!D33) | F8: =IF('📥 הזנה חודשית'!D$58=0,"",'📥 הזנה חודשית'!D46) | G8: =IF('📥 הזנה חודשית'!D$58=0,"",'📥 הזנה חודשית'!D54) | H8: =IF('📥 הזנה חודשית'!D$58=0,"",'📥 הזנה חודשית'!D55) | I8: =IF('📥 הזנה חודשית'!D$58=0,"",'📥 הזנה חודשית'!D56) | J8: =IF(OR(C8="",N(C8)=0),"",H8/C8) | K8: =IF(H8="","",SUM(H$7:H8))
B9: מרץ | C9: =IF('📥 הזנה חודשית'!E$58=0,"",'📥 הזנה חודשית'!E53) | D9: =IF('📥 הזנה חודשית'!E$58=0,"",'📥 הזנה חודשית'!E21) | E9: =IF('📥 הזנה חודשית'!E$58=0,"",'📥 הזנה חודשית'!E33) | F9: =IF('📥 הזנה חודשית'!E$58=0,"",'📥 הזנה חודשית'!E46) | G9: =IF('📥 הזנה חודשית'!E$58=0,"",'📥 הזנה חודשית'!E54) | H9: =IF('📥 הזנה חודשית'!E$58=0,"",'📥 הזנה חודשית'!E55) | I9: =IF('📥 הזנה חודשית'!E$58=0,"",'📥 הזנה חודשית'!E56) | J9: =IF(OR(C9="",N(C9)=0),"",H9/C9) | K9: =IF(H9="","",SUM(H$7:H9))
B10: אפריל | C10: =IF('📥 הזנה חודשית'!F$58=0,"",'📥 הזנה חודשית'!F53) | D10: =IF('📥 הזנה חודשית'!F$58=0,"",'📥 הזנה חודשית'!F21) | E10: =IF('📥 הזנה חודשית'!F$58=0,"",'📥 הזנה חודשית'!F33) | F10: =IF('📥 הזנה חודשית'!F$58=0,"",'📥 הזנה חודשית'!F46) | G10: =IF('📥 הזנה חודשית'!F$58=0,"",'📥 הזנה חודשית'!F54) | H10: =IF('📥 הזנה חודשית'!F$58=0,"",'📥 הזנה חודשית'!F55) | I10: =IF('📥 הזנה חודשית'!F$58=0,"",'📥 הזנה חודשית'!F56) | J10: =IF(OR(C10="",N(C10)=0),"",H10/C10) | K10: =IF(H10="","",SUM(H$7:H10))
B11: מאי | C11: =IF('📥 הזנה חודשית'!G$58=0,"",'📥 הזנה חודשית'!G53) | D11: =IF('📥 הזנה חודשית'!G$58=0,"",'📥 הזנה חודשית'!G21) | E11: =IF('📥 הזנה חודשית'!G$58=0,"",'📥 הזנה חודשית'!G33) | F11: =IF('📥 הזנה חודשית'!G$58=0,"",'📥 הזנה חודשית'!G46) | G11: =IF('📥 הזנה חודשית'!G$58=0,"",'📥 הזנה חודשית'!G54) | H11: =IF('📥 הזנה חודשית'!G$58=0,"",'📥 הזנה חודשית'!G55) | I11: =IF('📥 הזנה חודשית'!G$58=0,"",'📥 הזנה חודשית'!G56) | J11: =IF(OR(C11="",N(C11)=0),"",H11/C11) | K11: =IF(H11="","",SUM(H$7:H11))
B12: יוני | C12: =IF('📥 הזנה חודשית'!H$58=0,"",'📥 הזנה חודשית'!H53) | D12: =IF('📥 הזנה חודשית'!H$58=0,"",'📥 הזנה חודשית'!H21) | E12: =IF('📥 הזנה חודשית'!H$58=0,"",'📥 הזנה חודשית'!H33) | F12: =IF('📥 הזנה חודשית'!H$58=0,"",'📥 הזנה חודשית'!H46) | G12: =IF('📥 הזנה חודשית'!H$58=0,"",'📥 הזנה חודשית'!H54) | H12: =IF('📥 הזנה חודשית'!H$58=0,"",'📥 הזנה חודשית'!H55) | I12: =IF('📥 הזנה חודשית'!H$58=0,"",'📥 הזנה חודשית'!H56) | J12: =IF(OR(C12="",N(C12)=0),"",H12/C12) | K12: =IF(H12="","",SUM(H$7:H12))
B13: יולי | C13: =IF('📥 הזנה חודשית'!I$58=0,"",'📥 הזנה חודשית'!I53) | D13: =IF('📥 הזנה חודשית'!I$58=0,"",'📥 הזנה חודשית'!I21) | E13: =IF('📥 הזנה חודשית'!I$58=0,"",'📥 הזנה חודשית'!I33) | F13: =IF('📥 הזנה חודשית'!I$58=0,"",'📥 הזנה חודשית'!I46) | G13: =IF('📥 הזנה חודשית'!I$58=0,"",'📥 הזנה חודשית'!I54) | H13: =IF('📥 הזנה חודשית'!I$58=0,"",'📥 הזנה חודשית'!I55) | I13: =IF('📥 הזנה חודשית'!I$58=0,"",'📥 הזנה חודשית'!I56) | J13: =IF(OR(C13="",N(C13)=0),"",H13/C13) | K13: =IF(H13="","",SUM(H$7:H13))
B14: אוגוסט | C14: =IF('📥 הזנה חודשית'!J$58=0,"",'📥 הזנה חודשית'!J53) | D14: =IF('📥 הזנה חודשית'!J$58=0,"",'📥 הזנה חודשית'!J21) | E14: =IF('📥 הזנה חודשית'!J$58=0,"",'📥 הזנה חודשית'!J33) | F14: =IF('📥 הזנה חודשית'!J$58=0,"",'📥 הזנה חודשית'!J46) | G14: =IF('📥 הזנה חודשית'!J$58=0,"",'📥 הזנה חודשית'!J54) | H14: =IF('📥 הזנה חודשית'!J$58=0,"",'📥 הזנה חודשית'!J55) | I14: =IF('📥 הזנה חודשית'!J$58=0,"",'📥 הזנה חודשית'!J56) | J14: =IF(OR(C14="",N(C14)=0),"",H14/C14) | K14: =IF(H14="","",SUM(H$7:H14))
B15: ספטמבר | C15: =IF('📥 הזנה חודשית'!K$58=0,"",'📥 הזנה חודשית'!K53) | D15: =IF('📥 הזנה חודשית'!K$58=0,"",'📥 הזנה חודשית'!K21) | E15: =IF('📥 הזנה חודשית'!K$58=0,"",'📥 הזנה חודשית'!K33) | F15: =IF('📥 הזנה חודשית'!K$58=0,"",'📥 הזנה חודשית'!K46) | G15: =IF('📥 הזנה חודשית'!K$58=0,"",'📥 הזנה חודשית'!K54) | H15: =IF('📥 הזנה חודשית'!K$58=0,"",'📥 הזנה חודשית'!K55) | I15: =IF('📥 הזנה חודשית'!K$58=0,"",'📥 הזנה חודשית'!K56) | J15: =IF(OR(C15="",N(C15)=0),"",H15/C15) | K15: =IF(H15="","",SUM(H$7:H15))
B16: אוקטובר | C16: =IF('📥 הזנה חודשית'!L$58=0,"",'📥 הזנה חודשית'!L53) | D16: =IF('📥 הזנה חודשית'!L$58=0,"",'📥 הזנה חודשית'!L21) | E16: =IF('📥 הזנה חודשית'!L$58=0,"",'📥 הזנה חודשית'!L33) | F16: =IF('📥 הזנה חודשית'!L$58=0,"",'📥 הזנה חודשית'!L46) | G16: =IF('📥 הזנה חודשית'!L$58=0,"",'📥 הזנה חודשית'!L54) | H16: =IF('📥 הזנה חודשית'!L$58=0,"",'📥 הזנה חודשית'!L55) | I16: =IF('📥 הזנה חודשית'!L$58=0,"",'📥 הזנה חודשית'!L56) | J16: =IF(OR(C16="",N(C16)=0),"",H16/C16) | K16: =IF(H16="","",SUM(H$7:H16))
B17: נובמבר | C17: =IF('📥 הזנה חודשית'!M$58=0,"",'📥 הזנה חודשית'!M53) | D17: =IF('📥 הזנה חודשית'!M$58=0,"",'📥 הזנה חודשית'!M21) | E17: =IF('📥 הזנה חודשית'!M$58=0,"",'📥 הזנה חודשית'!M33) | F17: =IF('📥 הזנה חודשית'!M$58=0,"",'📥 הזנה חודשית'!M46) | G17: =IF('📥 הזנה חודשית'!M$58=0,"",'📥 הזנה חודשית'!M54) | H17: =IF('📥 הזנה חודשית'!M$58=0,"",'📥 הזנה חודשית'!M55) | I17: =IF('📥 הזנה חודשית'!M$58=0,"",'📥 הזנה חודשית'!M56) | J17: =IF(OR(C17="",N(C17)=0),"",H17/C17) | K17: =IF(H17="","",SUM(H$7:H17))
B18: דצמבר | C18: =IF('📥 הזנה חודשית'!N$58=0,"",'📥 הזנה חודשית'!N53) | D18: =IF('📥 הזנה חודשית'!N$58=0,"",'📥 הזנה חודשית'!N21) | E18: =IF('📥 הזנה חודשית'!N$58=0,"",'📥 הזנה חודשית'!N33) | F18: =IF('📥 הזנה חודשית'!N$58=0,"",'📥 הזנה חודשית'!N46) | G18: =IF('📥 הזנה חודשית'!N$58=0,"",'📥 הזנה חודשית'!N54) | H18: =IF('📥 הזנה חודשית'!N$58=0,"",'📥 הזנה חודשית'!N55) | I18: =IF('📥 הזנה חודשית'!N$58=0,"",'📥 הזנה חודשית'!N56) | J18: =IF(OR(C18="",N(C18)=0),"",H18/C18) | K18: =IF(H18="","",SUM(H$7:H18))
B19: סה"כ | C19: =SUM(C7:C18) | D19: =SUM(D7:D18) | E19: =SUM(E7:E18) | F19: =SUM(F7:F18) | G19: =SUM(G7:G18) | H19: =SUM(H7:H18) | I19: =SUM(I7:I18) | J19: =IF(N(C19)=0,"",H19/C19) | K19: =MAX(K7:K18)
B20: ממוצע לחודש | C20: =IF(COUNT(C7:C18)=0,"",AVERAGE(C7:C18)) | D20: =IF(COUNT(D7:D18)=0,"",AVERAGE(D7:D18)) | E20: =IF(COUNT(E7:E18)=0,"",AVERAGE(E7:E18)) | F20: =IF(COUNT(F7:F18)=0,"",AVERAGE(F7:F18)) | G20: =IF(COUNT(G7:G18)=0,"",AVERAGE(G7:G18)) | H20: =IF(COUNT(H7:H18)=0,"",AVERAGE(H7:H18)) | I20: =IF(COUNT(I7:I18)=0,"",AVERAGE(I7:I18)) | J20: =IF(N(C20)=0,"",H20/C20)
B58: 🌡️ מפת חום – כמה הוצאתם בכל קטגוריה בכל חודש (כהה = יותר)
B59: קטגוריה | C59: ינואר | D59: פברואר | E59: מרץ | F59: אפריל | G59: מאי | H59: יוני | I59: יולי | J59: אוגוסט | K59: ספטמבר | L59: אוקטובר | M59: נובמבר | N59: דצמבר | O59: סה"כ
B60: 🧾 חשבונות ומנויים
B61: =IF('📥 הזנה חודשית'!$A$22="","",'📥 הזנה חודשית'!$A$22) | C61: =IF(OR('📥 הזנה חודשית'!$A$22="",'📥 הזנה חודשית'!$C$22=""),"",'📥 הזנה חודשית'!$C$22) | D61: =IF(OR('📥 הזנה חודשית'!$A$22="",'📥 הזנה חודשית'!$D$22=""),"",'📥 הזנה חודשית'!$D$22) | E61: =IF(OR('📥 הזנה חודשית'!$A$22="",'📥 הזנה חודשית'!$E$22=""),"",'📥 הזנה חודשית'!$E$22) | F61: =IF(OR('📥 הזנה חודשית'!$A$22="",'📥 הזנה חודשית'!$F$22=""),"",'📥 הזנה חודשית'!$F$22) | G61: =IF(OR('📥 הזנה חודשית'!$A$22="",'📥 הזנה חודשית'!$G$22=""),"",'📥 הזנה חודשית'!$G$22) | H61: =IF(OR('📥 הזנה חודשית'!$A$22="",'📥 הזנה חודשית'!$H$22=""),"",'📥 הזנה חודשית'!$H$22) | I61: =IF(OR('📥 הזנה חודשית'!$A$22="",'📥 הזנה חודשית'!$I$22=""),"",'📥 הזנה חודשית'!$I$22) | J61: =IF(OR('📥 הזנה חודשית'!$A$22="",'📥 הזנה חודשית'!$J$22=""),"",'📥 הזנה חודשית'!$J$22) | K61: =IF(OR('📥 הזנה חודשית'!$A$22="",'📥 הזנה חודשית'!$K$22=""),"",'📥 הזנה חודשית'!$K$22) | L61: =IF(OR('📥 הזנה חודשית'!$A$22="",'📥 הזנה חודשית'!$L$22=""),"",'📥 הזנה חודשית'!$L$22) | M61: =IF(OR('📥 הזנה חודשית'!$A$22="",'📥 הזנה חודשית'!$M$22=""),"",'📥 הזנה חודשית'!$M$22) | N61: =IF(OR('📥 הזנה חודשית'!$A$22="",'📥 הזנה חודשית'!$N$22=""),"",'📥 הזנה חודשית'!$N$22) | O61: =IF(B61="","",'📥 הזנה חודשית'!$O$22)
B62: =IF('📥 הזנה חודשית'!$A$23="","",'📥 הזנה חודשית'!$A$23) | C62: =IF(OR('📥 הזנה חודשית'!$A$23="",'📥 הזנה חודשית'!$C$23=""),"",'📥 הזנה חודשית'!$C$23) | D62: =IF(OR('📥 הזנה חודשית'!$A$23="",'📥 הזנה חודשית'!$D$23=""),"",'📥 הזנה חודשית'!$D$23) | E62: =IF(OR('📥 הזנה חודשית'!$A$23="",'📥 הזנה חודשית'!$E$23=""),"",'📥 הזנה חודשית'!$E$23) | F62: =IF(OR('📥 הזנה חודשית'!$A$23="",'📥 הזנה חודשית'!$F$23=""),"",'📥 הזנה חודשית'!$F$23) | G62: =IF(OR('📥 הזנה חודשית'!$A$23="",'📥 הזנה חודשית'!$G$23=""),"",'📥 הזנה חודשית'!$G$23) | H62: =IF(OR('📥 הזנה חודשית'!$A$23="",'📥 הזנה חודשית'!$H$23=""),"",'📥 הזנה חודשית'!$H$23) | I62: =IF(OR('📥 הזנה חודשית'!$A$23="",'📥 הזנה חודשית'!$I$23=""),"",'📥 הזנה חודשית'!$I$23) | J62: =IF(OR('📥 הזנה חודשית'!$A$23="",'📥 הזנה חודשית'!$J$23=""),"",'📥 הזנה חודשית'!$J$23) | K62: =IF(OR('📥 הזנה חודשית'!$A$23="",'📥 הזנה חודשית'!$K$23=""),"",'📥 הזנה חודשית'!$K$23) | L62: =IF(OR('📥 הזנה חודשית'!$A$23="",'📥 הזנה חודשית'!$L$23=""),"",'📥 הזנה חודשית'!$L$23) | M62: =IF(OR('📥 הזנה חודשית'!$A$23="",'📥 הזנה חודשית'!$M$23=""),"",'📥 הזנה חודשית'!$M$23) | N62: =IF(OR('📥 הזנה חודשית'!$A$23="",'📥 הזנה חודשית'!$N$23=""),"",'📥 הזנה חודשית'!$N$23) | O62: =IF(B62="","",'📥 הזנה חודשית'!$O$23)
B63: =IF('📥 הזנה חודשית'!$A$24="","",'📥 הזנה חודשית'!$A$24) | C63: =IF(OR('📥 הזנה חודשית'!$A$24="",'📥 הזנה חודשית'!$C$24=""),"",'📥 הזנה חודשית'!$C$24) | D63: =IF(OR('📥 הזנה חודשית'!$A$24="",'📥 הזנה חודשית'!$D$24=""),"",'📥 הזנה חודשית'!$D$24) | E63: =IF(OR('📥 הזנה חודשית'!$A$24="",'📥 הזנה חודשית'!$E$24=""),"",'📥 הזנה חודשית'!$E$24) | F63: =IF(OR('📥 הזנה חודשית'!$A$24="",'📥 הזנה חודשית'!$F$24=""),"",'📥 הזנה חודשית'!$F$24) | G63: =IF(OR('📥 הזנה חודשית'!$A$24="",'📥 הזנה חודשית'!$G$24=""),"",'📥 הזנה חודשית'!$G$24) | H63: =IF(OR('📥 הזנה חודשית'!$A$24="",'📥 הזנה חודשית'!$H$24=""),"",'📥 הזנה חודשית'!$H$24) | I63: =IF(OR('📥 הזנה חודשית'!$A$24="",'📥 הזנה חודשית'!$I$24=""),"",'📥 הזנה חודשית'!$I$24) | J63: =IF(OR('📥 הזנה חודשית'!$A$24="",'📥 הזנה חודשית'!$J$24=""),"",'📥 הזנה חודשית'!$J$24) | K63: =IF(OR('📥 הזנה חודשית'!$A$24="",'📥 הזנה חודשית'!$K$24=""),"",'📥 הזנה חודשית'!$K$24) | L63: =IF(OR('📥 הזנה חודשית'!$A$24="",'📥 הזנה חודשית'!$L$24=""),"",'📥 הזנה חודשית'!$L$24) | M63: =IF(OR('📥 הזנה חודשית'!$A$24="",'📥 הזנה חודשית'!$M$24=""),"",'📥 הזנה חודשית'!$M$24) | N63: =IF(OR('📥 הזנה חודשית'!$A$24="",'📥 הזנה חודשית'!$N$24=""),"",'📥 הזנה חודשית'!$N$24) | O63: =IF(B63="","",'📥 הזנה חודשית'!$O$24)
B64: =IF('📥 הזנה חודשית'!$A$25="","",'📥 הזנה חודשית'!$A$25) | C64: =IF(OR('📥 הזנה חודשית'!$A$25="",'📥 הזנה חודשית'!$C$25=""),"",'📥 הזנה חודשית'!$C$25) | D64: =IF(OR('📥 הזנה חודשית'!$A$25="",'📥 הזנה חודשית'!$D$25=""),"",'📥 הזנה חודשית'!$D$25) | E64: =IF(OR('📥 הזנה חודשית'!$A$25="",'📥 הזנה חודשית'!$E$25=""),"",'📥 הזנה חודשית'!$E$25) | F64: =IF(OR('📥 הזנה חודשית'!$A$25="",'📥 הזנה חודשית'!$F$25=""),"",'📥 הזנה חודשית'!$F$25) | G64: =IF(OR('📥 הזנה חודשית'!$A$25="",'📥 הזנה חודשית'!$G$25=""),"",'📥 הזנה חודשית'!$G$25) | H64: =IF(OR('📥 הזנה חודשית'!$A$25="",'📥 הזנה חודשית'!$H$25=""),"",'📥 הזנה חודשית'!$H$25) | I64: =IF(OR('📥 הזנה חודשית'!$A$25="",'📥 הזנה חודשית'!$I$25=""),"",'📥 הזנה חודשית'!$I$25) | J64: =IF(OR('📥 הזנה חודשית'!$A$25="",'📥 הזנה חודשית'!$J$25=""),"",'📥 הזנה חודשית'!$J$25) | K64: =IF(OR('📥 הזנה חודשית'!$A$25="",'📥 הזנה חודשית'!$K$25=""),"",'📥 הזנה חודשית'!$K$25) | L64: =IF(OR('📥 הזנה חודשית'!$A$25="",'📥 הזנה חודשית'!$L$25=""),"",'📥 הזנה חודשית'!$L$25) | M64: =IF(OR('📥 הזנה חודשית'!$A$25="",'📥 הזנה חודשית'!$M$25=""),"",'📥 הזנה חודשית'!$M$25) | N64: =IF(OR('📥 הזנה חודשית'!$A$25="",'📥 הזנה חודשית'!$N$25=""),"",'📥 הזנה חודשית'!$N$25) | O64: =IF(B64="","",'📥 הזנה חודשית'!$O$25)
B65: =IF('📥 הזנה חודשית'!$A$26="","",'📥 הזנה חודשית'!$A$26) | C65: =IF(OR('📥 הזנה חודשית'!$A$26="",'📥 הזנה חודשית'!$C$26=""),"",'📥 הזנה חודשית'!$C$26) | D65: =IF(OR('📥 הזנה חודשית'!$A$26="",'📥 הזנה חודשית'!$D$26=""),"",'📥 הזנה חודשית'!$D$26) | E65: =IF(OR('📥 הזנה חודשית'!$A$26="",'📥 הזנה חודשית'!$E$26=""),"",'📥 הזנה חודשית'!$E$26) | F65: =IF(OR('📥 הזנה חודשית'!$A$26="",'📥 הזנה חודשית'!$F$26=""),"",'📥 הזנה חודשית'!$F$26) | G65: =IF(OR('📥 הזנה חודשית'!$A$26="",'📥 הזנה חודשית'!$G$26=""),"",'📥 הזנה חודשית'!$G$26) | H65: =IF(OR('📥 הזנה חודשית'!$A$26="",'📥 הזנה חודשית'!$H$26=""),"",'📥 הזנה חודשית'!$H$26) | I65: =IF(OR('📥 הזנה חודשית'!$A$26="",'📥 הזנה חודשית'!$I$26=""),"",'📥 הזנה חודשית'!$I$26) | J65: =IF(OR('📥 הזנה חודשית'!$A$26="",'📥 הזנה חודשית'!$J$26=""),"",'📥 הזנה חודשית'!$J$26) | K65: =IF(OR('📥 הזנה חודשית'!$A$26="",'📥 הזנה חודשית'!$K$26=""),"",'📥 הזנה חודשית'!$K$26) | L65: =IF(OR('📥 הזנה חודשית'!$A$26="",'📥 הזנה חודשית'!$L$26=""),"",'📥 הזנה חודשית'!$L$26) | M65: =IF(OR('📥 הזנה חודשית'!$A$26="",'📥 הזנה חודשית'!$M$26=""),"",'📥 הזנה חודשית'!$M$26) | N65: =IF(OR('📥 הזנה חודשית'!$A$26="",'📥 הזנה חודשית'!$N$26=""),"",'📥 הזנה חודשית'!$N$26) | O65: =IF(B65="","",'📥 הזנה חודשית'!$O$26)
B66: =IF('📥 הזנה חודשית'!$A$27="","",'📥 הזנה חודשית'!$A$27) | C66: =IF(OR('📥 הזנה חודשית'!$A$27="",'📥 הזנה חודשית'!$C$27=""),"",'📥 הזנה חודשית'!$C$27) | D66: =IF(OR('📥 הזנה חודשית'!$A$27="",'📥 הזנה חודשית'!$D$27=""),"",'📥 הזנה חודשית'!$D$27) | E66: =IF(OR('📥 הזנה חודשית'!$A$27="",'📥 הזנה חודשית'!$E$27=""),"",'📥 הזנה חודשית'!$E$27) | F66: =IF(OR('📥 הזנה חודשית'!$A$27="",'📥 הזנה חודשית'!$F$27=""),"",'📥 הזנה חודשית'!$F$27) | G66: =IF(OR('📥 הזנה חודשית'!$A$27="",'📥 הזנה חודשית'!$G$27=""),"",'📥 הזנה חודשית'!$G$27) | H66: =IF(OR('📥 הזנה חודשית'!$A$27="",'📥 הזנה חודשית'!$H$27=""),"",'📥 הזנה חודשית'!$H$27) | I66: =IF(OR('📥 הזנה חודשית'!$A$27="",'📥 הזנה חודשית'!$I$27=""),"",'📥 הזנה חודשית'!$I$27) | J66: =IF(OR('📥 הזנה חודשית'!$A$27="",'📥 הזנה חודשית'!$J$27=""),"",'📥 הזנה חודשית'!$J$27) | K66: =IF(OR('📥 הזנה חודשית'!$A$27="",'📥 הזנה חודשית'!$K$27=""),"",'📥 הזנה חודשית'!$K$27) | L66: =IF(OR('📥 הזנה חודשית'!$A$27="",'📥 הזנה חודשית'!$L$27=""),"",'📥 הזנה חודשית'!$L$27) | M66: =IF(OR('📥 הזנה חודשית'!$A$27="",'📥 הזנה חודשית'!$M$27=""),"",'📥 הזנה חודשית'!$M$27) | N66: =IF(OR('📥 הזנה חודשית'!$A$27="",'📥 הזנה חודשית'!$N$27=""),"",'📥 הזנה חודשית'!$N$27) | O66: =IF(B66="","",'📥 הזנה חודשית'!$O$27)
B67: =IF('📥 הזנה חודשית'!$A$28="","",'📥 הזנה חודשית'!$A$28) | C67: =IF(OR('📥 הזנה חודשית'!$A$28="",'📥 הזנה חודשית'!$C$28=""),"",'📥 הזנה חודשית'!$C$28) | D67: =IF(OR('📥 הזנה חודשית'!$A$28="",'📥 הזנה חודשית'!$D$28=""),"",'📥 הזנה חודשית'!$D$28) | E67: =IF(OR('📥 הזנה חודשית'!$A$28="",'📥 הזנה חודשית'!$E$28=""),"",'📥 הזנה חודשית'!$E$28) | F67: =IF(OR('📥 הזנה חודשית'!$A$28="",'📥 הזנה חודשית'!$F$28=""),"",'📥 הזנה חודשית'!$F$28) | G67: =IF(OR('📥 הזנה חודשית'!$A$28="",'📥 הזנה חודשית'!$G$28=""),"",'📥 הזנה חודשית'!$G$28) | H67: =IF(OR('📥 הזנה חודשית'!$A$28="",'📥 הזנה חודשית'!$H$28=""),"",'📥 הזנה חודשית'!$H$28) | I67: =IF(OR('📥 הזנה חודשית'!$A$28="",'📥 הזנה חודשית'!$I$28=""),"",'📥 הזנה חודשית'!$I$28) | J67: =IF(OR('📥 הזנה חודשית'!$A$28="",'📥 הזנה חודשית'!$J$28=""),"",'📥 הזנה חודשית'!$J$28) | K67: =IF(OR('📥 הזנה חודשית'!$A$28="",'📥 הזנה חודשית'!$K$28=""),"",'📥 הזנה חודשית'!$K$28) | L67: =IF(OR('📥 הזנה חודשית'!$A$28="",'📥 הזנה חודשית'!$L$28=""),"",'📥 הזנה חודשית'!$L$28) | M67: =IF(OR('📥 הזנה חודשית'!$A$28="",'📥 הזנה חודשית'!$M$28=""),"",'📥 הזנה חודשית'!$M$28) | N67: =IF(OR('📥 הזנה חודשית'!$A$28="",'📥 הזנה חודשית'!$N$28=""),"",'📥 הזנה חודשית'!$N$28) | O67: =IF(B67="","",'📥 הזנה חודשית'!$O$28)
B68: =IF('📥 הזנה חודשית'!$A$29="","",'📥 הזנה חודשית'!$A$29) | C68: =IF(OR('📥 הזנה חודשית'!$A$29="",'📥 הזנה חודשית'!$C$29=""),"",'📥 הזנה חודשית'!$C$29) | D68: =IF(OR('📥 הזנה חודשית'!$A$29="",'📥 הזנה חודשית'!$D$29=""),"",'📥 הזנה חודשית'!$D$29) | E68: =IF(OR('📥 הזנה חודשית'!$A$29="",'📥 הזנה חודשית'!$E$29=""),"",'📥 הזנה חודשית'!$E$29) | F68: =IF(OR('📥 הזנה חודשית'!$A$29="",'📥 הזנה חודשית'!$F$29=""),"",'📥 הזנה חודשית'!$F$29) | G68: =IF(OR('📥 הזנה חודשית'!$A$29="",'📥 הזנה חודשית'!$G$29=""),"",'📥 הזנה חודשית'!$G$29) | H68: =IF(OR('📥 הזנה חודשית'!$A$29="",'📥 הזנה חודשית'!$H$29=""),"",'📥 הזנה חודשית'!$H$29) | I68: =IF(OR('📥 הזנה חודשית'!$A$29="",'📥 הזנה חודשית'!$I$29=""),"",'📥 הזנה חודשית'!$I$29) | J68: =IF(OR('📥 הזנה חודשית'!$A$29="",'📥 הזנה חודשית'!$J$29=""),"",'📥 הזנה חודשית'!$J$29) | K68: =IF(OR('📥 הזנה חודשית'!$A$29="",'📥 הזנה חודשית'!$K$29=""),"",'📥 הזנה חודשית'!$K$29) | L68: =IF(OR('📥 הזנה חודשית'!$A$29="",'📥 הזנה חודשית'!$L$29=""),"",'📥 הזנה חודשית'!$L$29) | M68: =IF(OR('📥 הזנה חודשית'!$A$29="",'📥 הזנה חודשית'!$M$29=""),"",'📥 הזנה חודשית'!$M$29) | N68: =IF(OR('📥 הזנה חודשית'!$A$29="",'📥 הזנה חודשית'!$N$29=""),"",'📥 הזנה חודשית'!$N$29) | O68: =IF(B68="","",'📥 הזנה חודשית'!$O$29)
B69: =IF('📥 הזנה חודשית'!$A$30="","",'📥 הזנה חודשית'!$A$30) | C69: =IF(OR('📥 הזנה חודשית'!$A$30="",'📥 הזנה חודשית'!$C$30=""),"",'📥 הזנה חודשית'!$C$30) | D69: =IF(OR('📥 הזנה חודשית'!$A$30="",'📥 הזנה חודשית'!$D$30=""),"",'📥 הזנה חודשית'!$D$30) | E69: =IF(OR('📥 הזנה חודשית'!$A$30="",'📥 הזנה חודשית'!$E$30=""),"",'📥 הזנה חודשית'!$E$30) | F69: =IF(OR('📥 הזנה חודשית'!$A$30="",'📥 הזנה חודשית'!$F$30=""),"",'📥 הזנה חודשית'!$F$30) | G69: =IF(OR('📥 הזנה חודשית'!$A$30="",'📥 הזנה חודשית'!$G$30=""),"",'📥 הזנה חודשית'!$G$30) | H69: =IF(OR('📥 הזנה חודשית'!$A$30="",'📥 הזנה חודשית'!$H$30=""),"",'📥 הזנה חודשית'!$H$30) | I69: =IF(OR('📥 הזנה חודשית'!$A$30="",'📥 הזנה חודשית'!$I$30=""),"",'📥 הזנה חודשית'!$I$30) | J69: =IF(OR('📥 הזנה חודשית'!$A$30="",'📥 הזנה חודשית'!$J$30=""),"",'📥 הזנה חודשית'!$J$30) | K69: =IF(OR('📥 הזנה חודשית'!$A$30="",'📥 הזנה חודשית'!$K$30=""),"",'📥 הזנה חודשית'!$K$30) | L69: =IF(OR('📥 הזנה חודשית'!$A$30="",'📥 הזנה חודשית'!$L$30=""),"",'📥 הזנה חודשית'!$L$30) | M69: =IF(OR('📥 הזנה חודשית'!$A$30="",'📥 הזנה חודשית'!$M$30=""),"",'📥 הזנה חודשית'!$M$30) | N69: =IF(OR('📥 הזנה חודשית'!$A$30="",'📥 הזנה חודשית'!$N$30=""),"",'📥 הזנה חודשית'!$N$30) | O69: =IF(B69="","",'📥 הזנה חודשית'!$O$30)
B70: =IF('📥 הזנה חודשית'!$A$31="","",'📥 הזנה חודשית'!$A$31) | C70: =IF(OR('📥 הזנה חודשית'!$A$31="",'📥 הזנה חודשית'!$C$31=""),"",'📥 הזנה חודשית'!$C$31) | D70: =IF(OR('📥 הזנה חודשית'!$A$31="",'📥 הזנה חודשית'!$D$31=""),"",'📥 הזנה חודשית'!$D$31) | E70: =IF(OR('📥 הזנה חודשית'!$A$31="",'📥 הזנה חודשית'!$E$31=""),"",'📥 הזנה חודשית'!$E$31) | F70: =IF(OR('📥 הזנה חודשית'!$A$31="",'📥 הזנה חודשית'!$F$31=""),"",'📥 הזנה חודשית'!$F$31) | G70: =IF(OR('📥 הזנה חודשית'!$A$31="",'📥 הזנה חודשית'!$G$31=""),"",'📥 הזנה חודשית'!$G$31) | H70: =IF(OR('📥 הזנה חודשית'!$A$31="",'📥 הזנה חודשית'!$H$31=""),"",'📥 הזנה חודשית'!$H$31) | I70: =IF(OR('📥 הזנה חודשית'!$A$31="",'📥 הזנה חודשית'!$I$31=""),"",'📥 הזנה חודשית'!$I$31) | J70: =IF(OR('📥 הזנה חודשית'!$A$31="",'📥 הזנה חודשית'!$J$31=""),"",'📥 הזנה חודשית'!$J$31) | K70: =IF(OR('📥 הזנה חודשית'!$A$31="",'📥 הזנה חודשית'!$K$31=""),"",'📥 הזנה חודשית'!$K$31) | L70: =IF(OR('📥 הזנה חודשית'!$A$31="",'📥 הזנה חודשית'!$L$31=""),"",'📥 הזנה חודשית'!$L$31) | M70: =IF(OR('📥 הזנה חודשית'!$A$31="",'📥 הזנה חודשית'!$M$31=""),"",'📥 הזנה חודשית'!$M$31) | N70: =IF(OR('📥 הזנה חודשית'!$A$31="",'📥 הזנה חודשית'!$N$31=""),"",'📥 הזנה חודשית'!$N$31) | O70: =IF(B70="","",'📥 הזנה חודשית'!$O$31)
B71: 🛒 הוצאות משתנות
B72: =IF('📥 הזנה חודשית'!$A$34="","",'📥 הזנה חודשית'!$A$34) | C72: =IF(OR('📥 הזנה חודשית'!$A$34="",'📥 הזנה חודשית'!$C$34=""),"",'📥 הזנה חודשית'!$C$34) | D72: =IF(OR('📥 הזנה חודשית'!$A$34="",'📥 הזנה חודשית'!$D$34=""),"",'📥 הזנה חודשית'!$D$34) | E72: =IF(OR('📥 הזנה חודשית'!$A$34="",'📥 הזנה חודשית'!$E$34=""),"",'📥 הזנה חודשית'!$E$34) | F72: =IF(OR('📥 הזנה חודשית'!$A$34="",'📥 הזנה חודשית'!$F$34=""),"",'📥 הזנה חודשית'!$F$34) | G72: =IF(OR('📥 הזנה חודשית'!$A$34="",'📥 הזנה חודשית'!$G$34=""),"",'📥 הזנה חודשית'!$G$34) | H72: =IF(OR('📥 הזנה חודשית'!$A$34="",'📥 הזנה חודשית'!$H$34=""),"",'📥 הזנה חודשית'!$H$34) | I72: =IF(OR('📥 הזנה חודשית'!$A$34="",'📥 הזנה חודשית'!$I$34=""),"",'📥 הזנה חודשית'!$I$34) | J72: =IF(OR('📥 הזנה חודשית'!$A$34="",'📥 הזנה חודשית'!$J$34=""),"",'📥 הזנה חודשית'!$J$34) | K72: =IF(OR('📥 הזנה חודשית'!$A$34="",'📥 הזנה חודשית'!$K$34=""),"",'📥 הזנה חודשית'!$K$34) | L72: =IF(OR('📥 הזנה חודשית'!$A$34="",'📥 הזנה חודשית'!$L$34=""),"",'📥 הזנה חודשית'!$L$34) | M72: =IF(OR('📥 הזנה חודשית'!$A$34="",'📥 הזנה חודשית'!$M$34=""),"",'📥 הזנה חודשית'!$M$34) | N72: =IF(OR('📥 הזנה חודשית'!$A$34="",'📥 הזנה חודשית'!$N$34=""),"",'📥 הזנה חודשית'!$N$34) | O72: =IF(B72="","",'📥 הזנה חודשית'!$O$34)
B73: =IF('📥 הזנה חודשית'!$A$35="","",'📥 הזנה חודשית'!$A$35) | C73: =IF(OR('📥 הזנה חודשית'!$A$35="",'📥 הזנה חודשית'!$C$35=""),"",'📥 הזנה חודשית'!$C$35) | D73: =IF(OR('📥 הזנה חודשית'!$A$35="",'📥 הזנה חודשית'!$D$35=""),"",'📥 הזנה חודשית'!$D$35) | E73: =IF(OR('📥 הזנה חודשית'!$A$35="",'📥 הזנה חודשית'!$E$35=""),"",'📥 הזנה חודשית'!$E$35) | F73: =IF(OR('📥 הזנה חודשית'!$A$35="",'📥 הזנה חודשית'!$F$35=""),"",'📥 הזנה חודשית'!$F$35) | G73: =IF(OR('📥 הזנה חודשית'!$A$35="",'📥 הזנה חודשית'!$G$35=""),"",'📥 הזנה חודשית'!$G$35) | H73: =IF(OR('📥 הזנה חודשית'!$A$35="",'📥 הזנה חודשית'!$H$35=""),"",'📥 הזנה חודשית'!$H$35) | I73: =IF(OR('📥 הזנה חודשית'!$A$35="",'📥 הזנה חודשית'!$I$35=""),"",'📥 הזנה חודשית'!$I$35) | J73: =IF(OR('📥 הזנה חודשית'!$A$35="",'📥 הזנה חודשית'!$J$35=""),"",'📥 הזנה חודשית'!$J$35) | K73: =IF(OR('📥 הזנה חודשית'!$A$35="",'📥 הזנה חודשית'!$K$35=""),"",'📥 הזנה חודשית'!$K$35) | L73: =IF(OR('📥 הזנה חודשית'!$A$35="",'📥 הזנה חודשית'!$L$35=""),"",'📥 הזנה חודשית'!$L$35) | M73: =IF(OR('📥 הזנה חודשית'!$A$35="",'📥 הזנה חודשית'!$M$35=""),"",'📥 הזנה חודשית'!$M$35) | N73: =IF(OR('📥 הזנה חודשית'!$A$35="",'📥 הזנה חודשית'!$N$35=""),"",'📥 הזנה חודשית'!$N$35) | O73: =IF(B73="","",'📥 הזנה חודשית'!$O$35)
B74: =IF('📥 הזנה חודשית'!$A$36="","",'📥 הזנה חודשית'!$A$36) | C74: =IF(OR('📥 הזנה חודשית'!$A$36="",'📥 הזנה חודשית'!$C$36=""),"",'📥 הזנה חודשית'!$C$36) | D74: =IF(OR('📥 הזנה חודשית'!$A$36="",'📥 הזנה חודשית'!$D$36=""),"",'📥 הזנה חודשית'!$D$36) | E74: =IF(OR('📥 הזנה חודשית'!$A$36="",'📥 הזנה חודשית'!$E$36=""),"",'📥 הזנה חודשית'!$E$36) | F74: =IF(OR('📥 הזנה חודשית'!$A$36="",'📥 הזנה חודשית'!$F$36=""),"",'📥 הזנה חודשית'!$F$36) | G74: =IF(OR('📥 הזנה חודשית'!$A$36="",'📥 הזנה חודשית'!$G$36=""),"",'📥 הזנה חודשית'!$G$36) | H74: =IF(OR('📥 הזנה חודשית'!$A$36="",'📥 הזנה חודשית'!$H$36=""),"",'📥 הזנה חודשית'!$H$36) | I74: =IF(OR('📥 הזנה חודשית'!$A$36="",'📥 הזנה חודשית'!$I$36=""),"",'📥 הזנה חודשית'!$I$36) | J74: =IF(OR('📥 הזנה חודשית'!$A$36="",'📥 הזנה חודשית'!$J$36=""),"",'📥 הזנה חודשית'!$J$36) | K74: =IF(OR('📥 הזנה חודשית'!$A$36="",'📥 הזנה חודשית'!$K$36=""),"",'📥 הזנה חודשית'!$K$36) | L74: =IF(OR('📥 הזנה חודשית'!$A$36="",'📥 הזנה חודשית'!$L$36=""),"",'📥 הזנה חודשית'!$L$36) | M74: =IF(OR('📥 הזנה חודשית'!$A$36="",'📥 הזנה חודשית'!$M$36=""),"",'📥 הזנה חודשית'!$M$36) | N74: =IF(OR('📥 הזנה חודשית'!$A$36="",'📥 הזנה חודשית'!$N$36=""),"",'📥 הזנה חודשית'!$N$36) | O74: =IF(B74="","",'📥 הזנה חודשית'!$O$36)
B75: =IF('📥 הזנה חודשית'!$A$37="","",'📥 הזנה חודשית'!$A$37) | C75: =IF(OR('📥 הזנה חודשית'!$A$37="",'📥 הזנה חודשית'!$C$37=""),"",'📥 הזנה חודשית'!$C$37) | D75: =IF(OR('📥 הזנה חודשית'!$A$37="",'📥 הזנה חודשית'!$D$37=""),"",'📥 הזנה חודשית'!$D$37) | E75: =IF(OR('📥 הזנה חודשית'!$A$37="",'📥 הזנה חודשית'!$E$37=""),"",'📥 הזנה חודשית'!$E$37) | F75: =IF(OR('📥 הזנה חודשית'!$A$37="",'📥 הזנה חודשית'!$F$37=""),"",'📥 הזנה חודשית'!$F$37) | G75: =IF(OR('📥 הזנה חודשית'!$A$37="",'📥 הזנה חודשית'!$G$37=""),"",'📥 הזנה חודשית'!$G$37) | H75: =IF(OR('📥 הזנה חודשית'!$A$37="",'📥 הזנה חודשית'!$H$37=""),"",'📥 הזנה חודשית'!$H$37) | I75: =IF(OR('📥 הזנה חודשית'!$A$37="",'📥 הזנה חודשית'!$I$37=""),"",'📥 הזנה חודשית'!$I$37) | J75: =IF(OR('📥 הזנה חודשית'!$A$37="",'📥 הזנה חודשית'!$J$37=""),"",'📥 הזנה חודשית'!$J$37) | K75: =IF(OR('📥 הזנה חודשית'!$A$37="",'📥 הזנה חודשית'!$K$37=""),"",'📥 הזנה חודשית'!$K$37) | L75: =IF(OR('📥 הזנה חודשית'!$A$37="",'📥 הזנה חודשית'!$L$37=""),"",'📥 הזנה חודשית'!$L$37) | M75: =IF(OR('📥 הזנה חודשית'!$A$37="",'📥 הזנה חודשית'!$M$37=""),"",'📥 הזנה חודשית'!$M$37) | N75: =IF(OR('📥 הזנה חודשית'!$A$37="",'📥 הזנה חודשית'!$N$37=""),"",'📥 הזנה חודשית'!$N$37) | O75: =IF(B75="","",'📥 הזנה חודשית'!$O$37)
B76: =IF('📥 הזנה חודשית'!$A$38="","",'📥 הזנה חודשית'!$A$38) | C76: =IF(OR('📥 הזנה חודשית'!$A$38="",'📥 הזנה חודשית'!$C$38=""),"",'📥 הזנה חודשית'!$C$38) | D76: =IF(OR('📥 הזנה חודשית'!$A$38="",'📥 הזנה חודשית'!$D$38=""),"",'📥 הזנה חודשית'!$D$38) | E76: =IF(OR('📥 הזנה חודשית'!$A$38="",'📥 הזנה חודשית'!$E$38=""),"",'📥 הזנה חודשית'!$E$38) | F76: =IF(OR('📥 הזנה חודשית'!$A$38="",'📥 הזנה חודשית'!$F$38=""),"",'📥 הזנה חודשית'!$F$38) | G76: =IF(OR('📥 הזנה חודשית'!$A$38="",'📥 הזנה חודשית'!$G$38=""),"",'📥 הזנה חודשית'!$G$38) | H76: =IF(OR('📥 הזנה חודשית'!$A$38="",'📥 הזנה חודשית'!$H$38=""),"",'📥 הזנה חודשית'!$H$38) | I76: =IF(OR('📥 הזנה חודשית'!$A$38="",'📥 הזנה חודשית'!$I$38=""),"",'📥 הזנה חודשית'!$I$38) | J76: =IF(OR('📥 הזנה חודשית'!$A$38="",'📥 הזנה חודשית'!$J$38=""),"",'📥 הזנה חודשית'!$J$38) | K76: =IF(OR('📥 הזנה חודשית'!$A$38="",'📥 הזנה חודשית'!$K$38=""),"",'📥 הזנה חודשית'!$K$38) | L76: =IF(OR('📥 הזנה חודשית'!$A$38="",'📥 הזנה חודשית'!$L$38=""),"",'📥 הזנה חודשית'!$L$38) | M76: =IF(OR('📥 הזנה חודשית'!$A$38="",'📥 הזנה חודשית'!$M$38=""),"",'📥 הזנה חודשית'!$M$38) | N76: =IF(OR('📥 הזנה חודשית'!$A$38="",'📥 הזנה חודשית'!$N$38=""),"",'📥 הזנה חודשית'!$N$38) | O76: =IF(B76="","",'📥 הזנה חודשית'!$O$38)
B77: =IF('📥 הזנה חודשית'!$A$39="","",'📥 הזנה חודשית'!$A$39) | C77: =IF(OR('📥 הזנה חודשית'!$A$39="",'📥 הזנה חודשית'!$C$39=""),"",'📥 הזנה חודשית'!$C$39) | D77: =IF(OR('📥 הזנה חודשית'!$A$39="",'📥 הזנה חודשית'!$D$39=""),"",'📥 הזנה חודשית'!$D$39) | E77: =IF(OR('📥 הזנה חודשית'!$A$39="",'📥 הזנה חודשית'!$E$39=""),"",'📥 הזנה חודשית'!$E$39) | F77: =IF(OR('📥 הזנה חודשית'!$A$39="",'📥 הזנה חודשית'!$F$39=""),"",'📥 הזנה חודשית'!$F$39) | G77: =IF(OR('📥 הזנה חודשית'!$A$39="",'📥 הזנה חודשית'!$G$39=""),"",'📥 הזנה חודשית'!$G$39) | H77: =IF(OR('📥 הזנה חודשית'!$A$39="",'📥 הזנה חודשית'!$H$39=""),"",'📥 הזנה חודשית'!$H$39) | I77: =IF(OR('📥 הזנה חודשית'!$A$39="",'📥 הזנה חודשית'!$I$39=""),"",'📥 הזנה חודשית'!$I$39) | J77: =IF(OR('📥 הזנה חודשית'!$A$39="",'📥 הזנה חודשית'!$J$39=""),"",'📥 הזנה חודשית'!$J$39) | K77: =IF(OR('📥 הזנה חודשית'!$A$39="",'📥 הזנה חודשית'!$K$39=""),"",'📥 הזנה חודשית'!$K$39) | L77: =IF(OR('📥 הזנה חודשית'!$A$39="",'📥 הזנה חודשית'!$L$39=""),"",'📥 הזנה חודשית'!$L$39) | M77: =IF(OR('📥 הזנה חודשית'!$A$39="",'📥 הזנה חודשית'!$M$39=""),"",'📥 הזנה חודשית'!$M$39) | N77: =IF(OR('📥 הזנה חודשית'!$A$39="",'📥 הזנה חודשית'!$N$39=""),"",'📥 הזנה חודשית'!$N$39) | O77: =IF(B77="","",'📥 הזנה חודשית'!$O$39)
B78: =IF('📥 הזנה חודשית'!$A$40="","",'📥 הזנה חודשית'!$A$40) | C78: =IF(OR('📥 הזנה חודשית'!$A$40="",'📥 הזנה חודשית'!$C$40=""),"",'📥 הזנה חודשית'!$C$40) | D78: =IF(OR('📥 הזנה חודשית'!$A$40="",'📥 הזנה חודשית'!$D$40=""),"",'📥 הזנה חודשית'!$D$40) | E78: =IF(OR('📥 הזנה חודשית'!$A$40="",'📥 הזנה חודשית'!$E$40=""),"",'📥 הזנה חודשית'!$E$40) | F78: =IF(OR('📥 הזנה חודשית'!$A$40="",'📥 הזנה חודשית'!$F$40=""),"",'📥 הזנה חודשית'!$F$40) | G78: =IF(OR('📥 הזנה חודשית'!$A$40="",'📥 הזנה חודשית'!$G$40=""),"",'📥 הזנה חודשית'!$G$40) | H78: =IF(OR('📥 הזנה חודשית'!$A$40="",'📥 הזנה חודשית'!$H$40=""),"",'📥 הזנה חודשית'!$H$40) | I78: =IF(OR('📥 הזנה חודשית'!$A$40="",'📥 הזנה חודשית'!$I$40=""),"",'📥 הזנה חודשית'!$I$40) | J78: =IF(OR('📥 הזנה חודשית'!$A$40="",'📥 הזנה חודשית'!$J$40=""),"",'📥 הזנה חודשית'!$J$40) | K78: =IF(OR('📥 הזנה חודשית'!$A$40="",'📥 הזנה חודשית'!$K$40=""),"",'📥 הזנה חודשית'!$K$40) | L78: =IF(OR('📥 הזנה חודשית'!$A$40="",'📥 הזנה חודשית'!$L$40=""),"",'📥 הזנה חודשית'!$L$40) | M78: =IF(OR('📥 הזנה חודשית'!$A$40="",'📥 הזנה חודשית'!$M$40=""),"",'📥 הזנה חודשית'!$M$40) | N78: =IF(OR('📥 הזנה חודשית'!$A$40="",'📥 הזנה חודשית'!$N$40=""),"",'📥 הזנה חודשית'!$N$40) | O78: =IF(B78="","",'📥 הזנה חודשית'!$O$40)
B79: =IF('📥 הזנה חודשית'!$A$41="","",'📥 הזנה חודשית'!$A$41) | C79: =IF(OR('📥 הזנה חודשית'!$A$41="",'📥 הזנה חודשית'!$C$41=""),"",'📥 הזנה חודשית'!$C$41) | D79: =IF(OR('📥 הזנה חודשית'!$A$41="",'📥 הזנה חודשית'!$D$41=""),"",'📥 הזנה חודשית'!$D$41) | E79: =IF(OR('📥 הזנה חודשית'!$A$41="",'📥 הזנה חודשית'!$E$41=""),"",'📥 הזנה חודשית'!$E$41) | F79: =IF(OR('📥 הזנה חודשית'!$A$41="",'📥 הזנה חודשית'!$F$41=""),"",'📥 הזנה חודשית'!$F$41) | G79: =IF(OR('📥 הזנה חודשית'!$A$41="",'📥 הזנה חודשית'!$G$41=""),"",'📥 הזנה חודשית'!$G$41) | H79: =IF(OR('📥 הזנה חודשית'!$A$41="",'📥 הזנה חודשית'!$H$41=""),"",'📥 הזנה חודשית'!$H$41) | I79: =IF(OR('📥 הזנה חודשית'!$A$41="",'📥 הזנה חודשית'!$I$41=""),"",'📥 הזנה חודשית'!$I$41) | J79: =IF(OR('📥 הזנה חודשית'!$A$41="",'📥 הזנה חודשית'!$J$41=""),"",'📥 הזנה חודשית'!$J$41) | K79: =IF(OR('📥 הזנה חודשית'!$A$41="",'📥 הזנה חודשית'!$K$41=""),"",'📥 הזנה חודשית'!$K$41) | L79: =IF(OR('📥 הזנה חודשית'!$A$41="",'📥 הזנה חודשית'!$L$41=""),"",'📥 הזנה חודשית'!$L$41) | M79: =IF(OR('📥 הזנה חודשית'!$A$41="",'📥 הזנה חודשית'!$M$41=""),"",'📥 הזנה חודשית'!$M$41) | N79: =IF(OR('📥 הזנה חודשית'!$A$41="",'📥 הזנה חודשית'!$N$41=""),"",'📥 הזנה חודשית'!$N$41) | O79: =IF(B79="","",'📥 הזנה חודשית'!$O$41)
...

Sheet 🎯 יעדים
B2: 🎯 יעדי חיסכון וסילוק חובות
B3: ממלאים פעם אחת את התאים בצבע שמנת – ההתקדמות מחושבת לבד מתוך ההזנה החודשית
B5: 🐷 תוכניות חיסכון
B6: תוכנית | C6: יעד | D6: היה בצד בתחילת השנה | E6: תאריך יעד | F6: הופקד השנה | G6: סה"כ נחסך | H6: נותר | I6: התקדמות | K6: כמה להפקיד בחודש
B7: =IF('📥 הזנה חודשית'!$A$15="","",'📥 הזנה חודשית'!$A$15) | C7: 30000 | D7: 18000 | E7: =DATE(2027,6,30) | F7: ='📥 הזנה חודשית'!$O$15 | G7: =N(D7)+F7 | H7: =MAX(0,N(C7)-G7) | I7: =IF(N(C7)=0,"",MIN(1,G7/C7)) | J7: =IF(I7="","",REPT("█",ROUND(MAX(0,MIN(1,I7))*10,0))&REPT("░",10-ROUND(MAX(0,MIN(1,I7))*10,0))) | K7: =IF(OR(N(C7)=0,E7=""),"",IF(H7=0,"✅ הושג",H7/MAX(1,(YEAR(E7)-YEAR(TODAY()))*12+MONTH(E7)-MONTH(TODAY()))))
B8: =IF('📥 הזנה חודשית'!$A$16="","",'📥 הזנה חודשית'!$A$16) | C8: 12000 | D8: 2500 | E8: =DATE(2027,7,31) | F8: ='📥 הזנה חודשית'!$O$16 | G8: =N(D8)+F8 | H8: =MAX(0,N(C8)-G8) | I8: =IF(N(C8)=0,"",MIN(1,G8/C8)) | J8: =IF(I8="","",REPT("█",ROUND(MAX(0,MIN(1,I8))*10,0))&REPT("░",10-ROUND(MAX(0,MIN(1,I8))*10,0))) | K8: =IF(OR(N(C8)=0,E8=""),"",IF(H8=0,"✅ הושג",H8/MAX(1,(YEAR(E8)-YEAR(TODAY()))*12+MONTH(E8)-MONTH(TODAY()))))
B9: =IF('📥 הזנה חודשית'!$A$17="","",'📥 הזנה חודשית'!$A$17) | C9: 40000 | D9: 15000 | E9: =DATE(2028,12,31) | F9: ='📥 הזנה חודשית'!$O$17 | G9: =N(D9)+F9 | H9: =MAX(0,N(C9)-G9) | I9: =IF(N(C9)=0,"",MIN(1,G9/C9)) | J9: =IF(I9="","",REPT("█",ROUND(MAX(0,MIN(1,I9))*10,0))&REPT("░",10-ROUND(MAX(0,MIN(1,I9))*10,0))) | K9: =IF(OR(N(C9)=0,E9=""),"",IF(H9=0,"✅ הושג",H9/MAX(1,(YEAR(E9)-YEAR(TODAY()))*12+MONTH(E9)-MONTH(TODAY()))))
B10: =IF('📥 הזנה חודשית'!$A$18="","",'📥 הזנה חודשית'!$A$18) | C10: 150000 | D10: 62000 | E10: =DATE(2030,12,31) | F10: ='📥 הזנה חודשית'!$O$18 | G10: =N(D10)+F10 | H10: =MAX(0,N(C10)-G10) | I10: =IF(N(C10)=0,"",MIN(1,G10/C10)) | J10: =IF(I10="","",REPT("█",ROUND(MAX(0,MIN(1,I10))*10,0))&REPT("░",10-ROUND(MAX(0,MIN(1,I10))*10,0))) | K10: =IF(OR(N(C10)=0,E10=""),"",IF(H10=0,"✅ הושג",H10/MAX(1,(YEAR(E10)-YEAR(TODAY()))*12+MONTH(E10)-MONTH(TODAY()))))
B11: =IF('📥 הזנה חודשית'!$A$19="","",'📥 הזנה חודשית'!$A$19) | C11: 50000 | D11: 21000 | E11: =DATE(2028,12,31) | F11: ='📥 הזנה חודשית'!$O$19 | G11: =N(D11)+F11 | H11: =MAX(0,N(C11)-G11) | I11: =IF(N(C11)=0,"",MIN(1,G11/C11)) | J11: =IF(I11="","",REPT("█",ROUND(MAX(0,MIN(1,I11))*10,0))&REPT("░",10-ROUND(MAX(0,MIN(1,I11))*10,0))) | K11: =IF(OR(N(C11)=0,E11=""),"",IF(H11=0,"✅ הושג",H11/MAX(1,(YEAR(E11)-YEAR(TODAY()))*12+MONTH(E11)-MONTH(TODAY()))))
B12: סה"כ | C12: =SUM(C7:C11) | D12: =SUM(D7:D11) | F12: =SUM(F7:F11) | G12: =SUM(G7:G11) | H12: =SUM(H7:H11) | I12: =IF(C12=0,"",MIN(1,G12/C12)) | J12: =IF(I12="","",REPT("█",ROUND(MAX(0,MIN(1,I12))*10,0))&REPT("░",10-ROUND(MAX(0,MIN(1,I12))*10,0))) | K12: =SUM(K7:K11)
B15: 💳 סילוק חובות
B16: חוב | C16: יתרה בתחילת השנה | D16: ריבית שנתית | E16: שולם השנה | F16: יתרה משוערת | G16: נפרע | I16: החזר חודשי ממוצע | J16: חודשים לסיום | K16: סיום משוער
B17: =IF('📥 הזנה חודשית'!$A$47="","",'📥 הזנה חודשית'!$A$47) | C17: 38000 | D17: 0.055 | E17: ='📥 הזנה חודשית'!$O$47 | F17: =MAX(0,N(C17)-E17) | G17: =IF(N(C17)=0,"",MIN(1,E17/C17)) | H17: =IF(G17="","",REPT("█",ROUND(MAX(0,MIN(1,G17))*10,0))&REPT("░",10-ROUND(MAX(0,MIN(1,G17))*10,0))) | I17: ='📥 הזנה חודשית'!$P$47 | J17: =IF(OR(N(C17)=0,N(I17)=0),"",IF(F17=0,0,IFERROR(ROUNDUP(NPER(N(D17)/12,-I17,F17),0),"ההחזר נמוך מהריבית"))) | K17: =IF(ISNUMBER(J17),IF(J17=0,"🎉 נסגר",EDATE(TODAY(),J17)),"")
B18: =IF('📥 הזנה חודשית'!$A$48="","",'📥 הזנה חודשית'!$A$48) | C18: 22000 | D18: 0.07 | E18: ='📥 הזנה חודשית'!$O$48 | F18: =MAX(0,N(C18)-E18) | G18: =IF(N(C18)=0,"",MIN(1,E18/C18)) | H18: =IF(G18="","",REPT("█",ROUND(MAX(0,MIN(1,G18))*10,0))&REPT("░",10-ROUND(MAX(0,MIN(1,G18))*10,0))) | I18: ='📥 הזנה חודשית'!$P$48 | J18: =IF(OR(N(C18)=0,N(I18)=0),"",IF(F18=0,0,IFERROR(ROUNDUP(NPER(N(D18)/12,-I18,F18),0),"ההחזר נמוך מהריבית"))) | K18: =IF(ISNUMBER(J18),IF(J18=0,"🎉 נסגר",EDATE(TODAY(),J18)),"")
B19: =IF('📥 הזנה חודשית'!$A$49="","",'📥 הזנה חודשית'!$A$49) | C19: 4800 | D19: 0.12 | E19: ='📥 הזנה חודשית'!$O$49 | F19: =MAX(0,N(C19)-E19) | G19: =IF(N(C19)=0,"",MIN(1,E19/C19)) | H19: =IF(G19="","",REPT("█",ROUND(MAX(0,MIN(1,G19))*10,0))&REPT("░",10-ROUND(MAX(0,MIN(1,G19))*10,0))) | I19: ='📥 הזנה חודשית'!$P$49 | J19: =IF(OR(N(C19)=0,N(I19)=0),"",IF(F19=0,0,IFERROR(ROUNDUP(NPER(N(D19)/12,-I19,F19),0),"ההחזר נמוך מהריבית"))) | K19: =IF(ISNUMBER(J19),IF(J19=0,"🎉 נסגר",EDATE(TODAY(),J19)),"")
B20: =IF('📥 הזנה חודשית'!$A$50="","",'📥 הזנה חודשית'!$A$50) | E20: ='📥 הזנה חודשית'!$O$50 | F20: =MAX(0,N(C20)-E20) | G20: =IF(N(C20)=0,"",MIN(1,E20/C20)) | H20: =IF(G20="","",REPT("█",ROUND(MAX(0,MIN(1,G20))*10,0))&REPT("░",10-ROUND(MAX(0,MIN(1,G20))*10,0))) | I20: ='📥 הזנה חודשית'!$P$50 | J20: =IF(OR(N(C20)=0,N(I20)=0),"",IF(F20=0,0,IFERROR(ROUNDUP(NPER(N(D20)/12,-I20,F20),0),"ההחזר נמוך מהריבית"))) | K20: =IF(ISNUMBER(J20),IF(J20=0,"🎉 נסגר",EDATE(TODAY(),J20)),"")
B21: סה"כ | C21: =SUM(C17:C20) | E21: =SUM(E17:E20) | F21: =SUM(F17:F20) | G21: =IF(C21=0,"",MIN(1,E21/C21)) | H21: =IF(G21="","",REPT("█",ROUND(MAX(0,MIN(1,G21))*10,0))&REPT("░",10-ROUND(MAX(0,MIN(1,G21))*10,0))) | I21: =SUM(I17:I20) | J21: =IF(COUNT(J17:J20)=0,"",MAX(J17:J20)) | K21: =IF(ISNUMBER(J21),IF(J21=0,"🎉",EDATE(TODAY(),J21)),"")
B22: 💡 'יתרה משוערת' = יתרת תחילת השנה פחות ההחזרים (בלי ריבית). 'חודשים לסיום' כן מחשב ריבית לפי ההחזר החודשי הממוצע.

Sheet 📖 מדריך
B2: 📖 איך משתמשים – 3 צעדים
B3: פעם אחת מגדירים, פעם בחודש ממלאים, וכל השאר קורה לבד
B5: 1 | C5: הגדרה חד-פעמית (10 דקות)
C6: בלשונית '📥 הזנה חודשית': עדכנו את שמות הקטגוריות ואת התקציב החודשי לכל אחת (עמודה B). בלשונית '🎯 יעדים': רשמו יעד לכל תוכנית חיסכון ואת יתרת החובות בתחילת השנה.
B7: 2 | C7: פעם בחודש (5 דקות)
C8: פותחים את דף הבנק ואת פירוט כרטיס האשראי, ובלשונית '📥 הזנה חודשית' ממלאים את העמודה של החודש: כמה נכנס, כמה הופקד לחיסכון, כמה יצא על כל קטגוריה. מספרים בלבד, בלי ₪.
B9: 3 | C9: מסתכלים על התמונה
C10: '📊 תמונת מצב' מציג אוטומטית את החודש האחרון שמילאתם: כרטיסי סיכום, תקציב מול בפועל, 5 ההוצאות הגדולות ותובנות. אפשר לבחור כל חודש אחר מהרשימה. ב-'📈 מגמות' רואים את כל השנה, וב-'🎯 יעדים' את ההתקדמות ליעדים.
C12: 🎨 מקרא
C13: תא להזנה – רק כאן מקלידים. כל השאר מחושב אוטומטית.
C14: 💰 הכנסות
C15: 🐷 חיסכון
C16: 🧾 חשבונות ומנויים
C17: 🛒 הוצאות משתנות
C18: 💳 חובות
C19: רקע אדום בלשונית ההזנה = חריגה מהתקציב של הקטגוריה
C21: 💡 אין צורך למלא את כל הקטגוריות – קטגוריה ריקה פשוט לא נספרת.
C22: 💡 רוצים קטגוריה חדשה? רשמו שם בשורה ריקה בסעיף המתאים – היא תופיע בכל הלשוניות.
C23: 💡 לשנה חדשה: שכפלו את הקובץ, שנו את השנה בתא B3 בלשונית ההזנה ומחקו את המספרים של החודשים.
